<?xml version="1.0" ?>
<!-- =================================================================================== -->
<!-- |    This document was autogenerated by xacro from ../urdf/d_0002_0.urdf.xacro    | -->
<!-- |    EDITING THIS FILE BY HAND IS NOT RECOMMENDED                                 | -->
<!-- =================================================================================== -->
<robot name="multi_degree" xmlns:xacro="http://ros.org/wiki/xacro">
  <material name="blue">
    <color rgba="0 0 0.8 1"/>
  </material>
  <material name="black">
    <color rgba="0 0 0 1"/>
  </material>
  <material name="white">
    <color rgba="1 1 1 1"/>
  </material>
  <link name="branch_0">
    <visual>
      <geometry>
        <cylinder length="3.236" radius="0.1"/>
      </geometry>
      <material name="blue"/>
    </visual>
    <collision>
      <geometry>
        <cylinder length="3.236" radius="0.1"/>
      </geometry>
    </collision>
    <inertial>
      <mass value="10"/>
      <inertia ixx="1.0" ixy="0.0" ixz="0.0" iyy="1.0" iyz="0.0" izz="1.0"/>
    </inertial>
  </link>
  <link name="branch_1">
    <visual>
      <geometry>
        <box size="0.1 0.1 1.618"/>
      </geometry>
      <origin rpy="0.04 0.05 0.06" xyz="0.01 0.02 0.03"/>
      <material name="white"/>
    </visual>
    <collision>
      <geometry>
        <box size="0.1 0.1 1.618"/>
      </geometry>
      <origin rpy="0.04 0.05 0.06" xyz="0.01 0.02 0.03"/>
    </collision>
    <inertial>
      <mass value="10"/>
      <inertia ixx="1.0" ixy="0.0" ixz="0.0" iyy="1.0" iyz="0.0" izz="1.0"/>
    </inertial>
  </link>
  <joint name="revolute_1" type="prismatic">
    <parent link="branch_0"/>
    <child link="branch_1"/>
    <origin rpy="0.11 0.12 0.13" xyz="0.07 0.08 0.09"/>
    <axis xyz="1 0 0"/>
    <limit effort="1000.0" lower="-1" upper="1" velocity="0.5"/>
  </joint>
  <link name="branch_2">
    <visual>
      <geometry>
        <box size="0.1 0.1 1.618"/>
      </geometry>
      <origin rpy="0.04 0.05 0.06" xyz="0.01 0.02 0.03"/>
      <material name="white"/>
    </visual>
    <collision>
      <geometry>
        <box size="0.1 0.1 1.618"/>
      </geometry>
      <origin rpy="0.04 0.05 0.06" xyz="0.01 0.02 0.03"/>
    </collision>
    <inertial>
      <mass value="10"/>
      <inertia ixx="1.0" ixy="0.0" ixz="0.0" iyy="1.0" iyz="0.0" izz="1.0"/>
    </inertial>
  </link>
  <joint name="revolute_2" type="revolute">
    <parent link="branch_1"/>
    <child link="branch_2"/>
    <origin rpy="0 0 0" xyz="0.07 0.08 0.09"/>
    <axis xyz="0 1 0"/>
    <limit effort="1000.0" lower="-1" upper="1" velocity="0.5"/>
  </joint>
  <!--   <xacro:branch2 suffix='3' type='revolute'>
    <origin xyz='0.07 0.08 0.09' rpy='0.11 0.12 0.13'/>
    <axis xyz='1 0 0'/>
  </xacro:branch2>
  <xacro:branch2 suffix='4' type='prismatic'>
    <origin xyz='0.07 0.08 0.09' rpy='0 0 0'/>
    <axis xyz='0 1 0'/>
  </xacro:branch2> -->
  <link name="head">
    <visual>
      <geometry>
        <sphere radius="0.1"/>
      </geometry>
      <material name="black"/>
    </visual>
    <collision>
      <geometry>
        <sphere radius="0.1"/>
      </geometry>
    </collision>
    <inertial>
      <mass value="2"/>
      <inertia ixx="1.0" ixy="0.0" ixz="0.0" iyy="1.0" iyz="0.0" izz="1.0"/>
    </inertial>
  </link>
  <joint name="head_swivel" type="continuous">
    <parent link="branch_2"/>
    <child link="head"/>
    <origin xyz="0 0 1.618"/>
    <axis xyz="0 0 1"/>
  </joint>
</robot>

