<?xml version="1.0" ?>
<!-- =================================================================================== -->
<!-- |    This document was autogenerated by xacro from ../urdf/d_0003_2.urdf.xacro    | -->
<!-- |    EDITING THIS FILE BY HAND IS NOT RECOMMENDED                                 | -->
<!-- =================================================================================== -->
<robot name="multi_degree" xmlns:xacro="http://ros.org/wiki/xacro">
  <material name="blue">
    <color rgba="0 0 0.8 1"/>
  </material>
  <material name="black">
    <color rgba="0 0 0 1"/>
  </material>
  <material name="white">
    <color rgba="1 1 1 1"/>
  </material>
  <link name="branch_0">
    <visual>
      <geometry>
        <cylinder length="0.4" radius="0.1"/>
      </geometry>
      <material name="blue"/>
    </visual>
    <collision>
      <geometry>
        <cylinder length="0.4" radius="0.1"/>
      </geometry>
    </collision>
    <inertial>
      <mass value="10"/>
      <inertia ixx="1.0" ixy="0.0" ixz="0.0" iyy="1.0" iyz="0.0" izz="1.0"/>
    </inertial>
  </link>
  <link name="branch_1">
    <visual>
      <geometry>
        <box size="0.1 0.1 0.2"/>
      </geometry>
      <origin rpy="0 0 0" xyz="0 0 0.1"/>
      <material name="white"/>
    </visual>
    <collision>
      <geometry>
        <box size="0.1 0.1 0.2"/>
      </geometry>
      <origin rpy="0 0 0" xyz="0 0 0.1"/>
    </collision>
    <inertial>
      <mass value="10"/>
      <inertia ixx="1.0" ixy="0.0" ixz="0.0" iyy="1.0" iyz="0.0" izz="1.0"/>
    </inertial>
  </link>
  <joint name="revolute_1" type="prismatic">
    <parent link="branch_0"/>
    <child link="branch_1"/>
    <origin rpy="0.907180 0.503388 -0.359069" xyz="0.006243 0.003664 0.548786"/>
    <axis xyz="0.695994 -0.425876 -0.088065"/>
    <limit effort="1000.0" lower="-0.548" upper="0.548" velocity="0.5"/>
  </joint>
  <link name="branch_2">
    <visual>
      <geometry>
        <box size="0.1 0.1 0.2"/>
      </geometry>
      <origin rpy="0 0 0" xyz="0 0 0.1"/>
      <material name="white"/>
    </visual>
    <collision>
      <geometry>
        <box size="0.1 0.1 0.2"/>
      </geometry>
      <origin rpy="0 0 0" xyz="0 0 0.1"/>
    </collision>
    <inertial>
      <mass value="10"/>
      <inertia ixx="1.0" ixy="0.0" ixz="0.0" iyy="1.0" iyz="0.0" izz="1.0"/>
    </inertial>
  </link>
  <joint name="revolute_2" type="prismatic">
    <parent link="branch_1"/>
    <child link="branch_2"/>
    <origin rpy="-0.551291 0.766358 -0.117398" xyz="0.074897 0.074505 0.511253"/>
    <axis xyz="0.285149 -0.771380 0.273469"/>
    <limit effort="1000.0" lower="-0.548" upper="0.548" velocity="0.5"/>
  </joint>
  <link name="branch_3">
    <visual>
      <geometry>
        <box size="0.1 0.1 0.2"/>
      </geometry>
      <origin rpy="0 0 0" xyz="0 0 0.1"/>
      <material name="white"/>
    </visual>
    <collision>
      <geometry>
        <box size="0.1 0.1 0.2"/>
      </geometry>
      <origin rpy="0 0 0" xyz="0 0 0.1"/>
    </collision>
    <inertial>
      <mass value="10"/>
      <inertia ixx="1.0" ixy="0.0" ixz="0.0" iyy="1.0" iyz="0.0" izz="1.0"/>
    </inertial>
  </link>
  <joint name="revolute_3" type="prismatic">
    <parent link="branch_2"/>
    <child link="branch_3"/>
    <origin rpy="0.137828 0.463183 0.892777" xyz="0.019333 0.023446 0.515947"/>
    <axis xyz="-0.503259 -0.002879 0.724157"/>
    <limit effort="1000.0" lower="-0.548" upper="0.548" velocity="0.5"/>
  </joint>
  <link name="head">
    <visual>
      <geometry>
        <sphere radius="0.1"/>
      </geometry>
      <material name="black"/>
    </visual>
    <collision>
      <geometry>
        <sphere radius="0.1"/>
      </geometry>
    </collision>
    <inertial>
      <mass value="2"/>
      <inertia ixx="1.0" ixy="0.0" ixz="0.0" iyy="1.0" iyz="0.0" izz="1.0"/>
    </inertial>
  </link>
  <joint name="head_swivel" type="continuous">
    <parent link="branch_3"/>
    <child link="head"/>
    <origin xyz="0 0 0.2"/>
    <axis xyz="0 0 1"/>
  </joint>
</robot>

