<?xml version="1.0" ?>
<!-- =================================================================================== -->
<!-- |    This document was autogenerated by xacro from ../urdf/d_0006_1.urdf.xacro    | -->
<!-- |    EDITING THIS FILE BY HAND IS NOT RECOMMENDED                                 | -->
<!-- =================================================================================== -->
<robot name="multi_degree" xmlns:xacro="http://ros.org/wiki/xacro">
  <material name="blue">
    <color rgba="0 0 0.8 1"/>
  </material>
  <material name="black">
    <color rgba="0 0 0 1"/>
  </material>
  <material name="white">
    <color rgba="1 1 1 1"/>
  </material>
  <link name="branch_0">
    <visual>
      <geometry>
        <cylinder length="0.4" radius="0.1"/>
      </geometry>
      <material name="blue"/>
    </visual>
    <collision>
      <geometry>
        <cylinder length="0.4" radius="0.1"/>
      </geometry>
    </collision>
    <inertial>
      <mass value="10"/>
      <inertia ixx="1.0" ixy="0.0" ixz="0.0" iyy="1.0" iyz="0.0" izz="1.0"/>
    </inertial>
  </link>
  <link name="branch_1">
    <visual>
      <geometry>
        <box size="0.1 0.1 0.2"/>
      </geometry>
      <origin rpy="0 0 0" xyz="0 0 0.1"/>
      <material name="white"/>
    </visual>
    <collision>
      <geometry>
        <box size="0.1 0.1 0.2"/>
      </geometry>
      <origin rpy="0 0 0" xyz="0 0 0.1"/>
    </collision>
    <inertial>
      <mass value="10"/>
      <inertia ixx="1.0" ixy="0.0" ixz="0.0" iyy="1.0" iyz="0.0" izz="1.0"/>
    </inertial>
  </link>
  <joint name="revolute_1" type="revolute">
    <parent link="branch_0"/>
    <child link="branch_1"/>
    <origin rpy="-0.021919 0.188077 -0.086778" xyz="0.091508 0.073299 0.441718"/>
    <axis xyz="-0.032973 -0.727414 0.744981"/>
    <limit effort="1000.0" lower="-0.548" upper="0.548" velocity="0.5"/>
  </joint>
  <link name="branch_2">
    <visual>
      <geometry>
        <box size="0.1 0.1 0.2"/>
      </geometry>
      <origin rpy="0 0 0" xyz="0 0 0.1"/>
      <material name="white"/>
    </visual>
    <collision>
      <geometry>
        <box size="0.1 0.1 0.2"/>
      </geometry>
      <origin rpy="0 0 0" xyz="0 0 0.1"/>
    </collision>
    <inertial>
      <mass value="10"/>
      <inertia ixx="1.0" ixy="0.0" ixz="0.0" iyy="1.0" iyz="0.0" izz="1.0"/>
    </inertial>
  </link>
  <joint name="revolute_2" type="revolute">
    <parent link="branch_1"/>
    <child link="branch_2"/>
    <origin rpy="0.001833 -0.355341 0.246387" xyz="0.029890 0.033865 0.479344"/>
    <axis xyz="0.825777 0.473465 0.460917"/>
    <limit effort="1000.0" lower="-0.548" upper="0.548" velocity="0.5"/>
  </joint>
  <link name="branch_3">
    <visual>
      <geometry>
        <box size="0.1 0.1 0.2"/>
      </geometry>
      <origin rpy="0 0 0" xyz="0 0 0.1"/>
      <material name="white"/>
    </visual>
    <collision>
      <geometry>
        <box size="0.1 0.1 0.2"/>
      </geometry>
      <origin rpy="0 0 0" xyz="0 0 0.1"/>
    </collision>
    <inertial>
      <mass value="10"/>
      <inertia ixx="1.0" ixy="0.0" ixz="0.0" iyy="1.0" iyz="0.0" izz="1.0"/>
    </inertial>
  </link>
  <joint name="revolute_3" type="revolute">
    <parent link="branch_2"/>
    <child link="branch_3"/>
    <origin rpy="-0.878534 0.995115 -0.919518" xyz="0.042641 0.007721 0.577868"/>
    <axis xyz="0.316374 0.496062 0.211134"/>
    <limit effort="1000.0" lower="-0.548" upper="0.548" velocity="0.5"/>
  </joint>
  <link name="branch_4">
    <visual>
      <geometry>
        <box size="0.1 0.1 0.2"/>
      </geometry>
      <origin rpy="0 0 0" xyz="0 0 0.1"/>
      <material name="white"/>
    </visual>
    <collision>
      <geometry>
        <box size="0.1 0.1 0.2"/>
      </geometry>
      <origin rpy="0 0 0" xyz="0 0 0.1"/>
    </collision>
    <inertial>
      <mass value="10"/>
      <inertia ixx="1.0" ixy="0.0" ixz="0.0" iyy="1.0" iyz="0.0" izz="1.0"/>
    </inertial>
  </link>
  <joint name="revolute_4" type="revolute">
    <parent link="branch_3"/>
    <child link="branch_4"/>
    <origin rpy="0.776829 -0.770404 -0.246982" xyz="0.062141 0.032339 0.573110"/>
    <axis xyz="0.515401 -0.608244 0.561255"/>
    <limit effort="1000.0" lower="-0.548" upper="0.548" velocity="0.5"/>
  </joint>
  <link name="branch_5">
    <visual>
      <geometry>
        <box size="0.1 0.1 0.2"/>
      </geometry>
      <origin rpy="0 0 0" xyz="0 0 0.1"/>
      <material name="white"/>
    </visual>
    <collision>
      <geometry>
        <box size="0.1 0.1 0.2"/>
      </geometry>
      <origin rpy="0 0 0" xyz="0 0 0.1"/>
    </collision>
    <inertial>
      <mass value="10"/>
      <inertia ixx="1.0" ixy="0.0" ixz="0.0" iyy="1.0" iyz="0.0" izz="1.0"/>
    </inertial>
  </link>
  <joint name="revolute_5" type="prismatic">
    <parent link="branch_4"/>
    <child link="branch_5"/>
    <origin rpy="0.172940 -0.238212 0.809268" xyz="0.092512 0.077762 0.481110"/>
    <axis xyz="0.323700 0.016150 0.408903"/>
    <limit effort="1000.0" lower="-0.548" upper="0.548" velocity="0.5"/>
  </joint>
  <link name="branch_6">
    <visual>
      <geometry>
        <box size="0.1 0.1 0.2"/>
      </geometry>
      <origin rpy="0 0 0" xyz="0 0 0.1"/>
      <material name="white"/>
    </visual>
    <collision>
      <geometry>
        <box size="0.1 0.1 0.2"/>
      </geometry>
      <origin rpy="0 0 0" xyz="0 0 0.1"/>
    </collision>
    <inertial>
      <mass value="10"/>
      <inertia ixx="1.0" ixy="0.0" ixz="0.0" iyy="1.0" iyz="0.0" izz="1.0"/>
    </inertial>
  </link>
  <joint name="revolute_6" type="revolute">
    <parent link="branch_5"/>
    <child link="branch_6"/>
    <origin rpy="0.229796 0.404182 0.731688" xyz="0.069211 0.059143 0.585315"/>
    <axis xyz="-0.119718 -0.606009 -0.294027"/>
    <limit effort="1000.0" lower="-0.548" upper="0.548" velocity="0.5"/>
  </joint>
  <link name="head">
    <visual>
      <geometry>
        <sphere radius="0.1"/>
      </geometry>
      <material name="black"/>
    </visual>
    <collision>
      <geometry>
        <sphere radius="0.1"/>
      </geometry>
    </collision>
    <inertial>
      <mass value="2"/>
      <inertia ixx="1.0" ixy="0.0" ixz="0.0" iyy="1.0" iyz="0.0" izz="1.0"/>
    </inertial>
  </link>
  <joint name="head_swivel" type="continuous">
    <parent link="branch_6"/>
    <child link="head"/>
    <origin xyz="0 0 0.2"/>
    <axis xyz="0 0 1"/>
  </joint>
</robot>

