<?xml version="1.0" ?>
<!-- =================================================================================== -->
<!-- |    This document was autogenerated by xacro from ../urdf/d_0025_0.urdf.xacro    | -->
<!-- |    EDITING THIS FILE BY HAND IS NOT RECOMMENDED                                 | -->
<!-- =================================================================================== -->
<robot name="multi_degree" xmlns:xacro="http://ros.org/wiki/xacro">
  <material name="blue">
    <color rgba="0 0 0.8 1"/>
  </material>
  <material name="black">
    <color rgba="0 0 0 1"/>
  </material>
  <material name="white">
    <color rgba="1 1 1 1"/>
  </material>
  <link name="branch_0">
    <visual>
      <geometry>
        <cylinder length="0.4" radius="0.1"/>
      </geometry>
      <material name="blue"/>
    </visual>
    <collision>
      <geometry>
        <cylinder length="0.4" radius="0.1"/>
      </geometry>
    </collision>
    <inertial>
      <mass value="10"/>
      <inertia ixx="1.0" ixy="0.0" ixz="0.0" iyy="1.0" iyz="0.0" izz="1.0"/>
    </inertial>
  </link>
  <link name="branch_1">
    <visual>
      <geometry>
        <box size="0.1 0.1 0.2"/>
      </geometry>
      <origin rpy="0 0 0" xyz="0 0 0.1"/>
      <material name="white"/>
    </visual>
    <collision>
      <geometry>
        <box size="0.1 0.1 0.2"/>
      </geometry>
      <origin rpy="0 0 0" xyz="0 0 0.1"/>
    </collision>
    <inertial>
      <mass value="10"/>
      <inertia ixx="1.0" ixy="0.0" ixz="0.0" iyy="1.0" iyz="0.0" izz="1.0"/>
    </inertial>
  </link>
  <joint name="revolute_1" type="revolute">
    <parent link="branch_0"/>
    <child link="branch_1"/>
    <origin rpy="0.072529 0.091843 -0.854458" xyz="0 0 0.2"/>
    <axis xyz="0 0 1"/>
    <limit effort="1000.0" lower="-0.548" upper="0.548" velocity="0.5"/>
  </joint>
  <link name="branch_2">
    <visual>
      <geometry>
        <box size="0.1 0.1 0.2"/>
      </geometry>
      <origin rpy="0 0 0" xyz="0 0 0.1"/>
      <material name="white"/>
    </visual>
    <collision>
      <geometry>
        <box size="0.1 0.1 0.2"/>
      </geometry>
      <origin rpy="0 0 0" xyz="0 0 0.1"/>
    </collision>
    <inertial>
      <mass value="10"/>
      <inertia ixx="1.0" ixy="0.0" ixz="0.0" iyy="1.0" iyz="0.0" izz="1.0"/>
    </inertial>
  </link>
  <joint name="revolute_2" type="revolute">
    <parent link="branch_1"/>
    <child link="branch_2"/>
    <origin rpy="-0.003062 0.836552 0.275877" xyz="0 0 0.2"/>
    <axis xyz="1 0 0"/>
    <limit effort="1000.0" lower="-0.548" upper="0.548" velocity="0.5"/>
  </joint>
  <link name="branch_3">
    <visual>
      <geometry>
        <box size="0.1 0.1 0.2"/>
      </geometry>
      <origin rpy="0 0 0" xyz="0 0 0.1"/>
      <material name="white"/>
    </visual>
    <collision>
      <geometry>
        <box size="0.1 0.1 0.2"/>
      </geometry>
      <origin rpy="0 0 0" xyz="0 0 0.1"/>
    </collision>
    <inertial>
      <mass value="10"/>
      <inertia ixx="1.0" ixy="0.0" ixz="0.0" iyy="1.0" iyz="0.0" izz="1.0"/>
    </inertial>
  </link>
  <joint name="revolute_3" type="revolute">
    <parent link="branch_2"/>
    <child link="branch_3"/>
    <origin rpy="0.607239 0.167782 0.231931" xyz="0 0 0.2"/>
    <axis xyz="0 1 0"/>
    <limit effort="1000.0" lower="-0.548" upper="0.548" velocity="0.5"/>
  </joint>
  <link name="branch_4">
    <visual>
      <geometry>
        <box size="0.1 0.1 0.2"/>
      </geometry>
      <origin rpy="0 0 0" xyz="0 0 0.1"/>
      <material name="white"/>
    </visual>
    <collision>
      <geometry>
        <box size="0.1 0.1 0.2"/>
      </geometry>
      <origin rpy="0 0 0" xyz="0 0 0.1"/>
    </collision>
    <inertial>
      <mass value="10"/>
      <inertia ixx="1.0" ixy="0.0" ixz="0.0" iyy="1.0" iyz="0.0" izz="1.0"/>
    </inertial>
  </link>
  <joint name="revolute_4" type="revolute">
    <parent link="branch_3"/>
    <child link="branch_4"/>
    <origin rpy="0.499236 0.502774 -0.407072" xyz="0 0 0.2"/>
    <axis xyz="0 0 1"/>
    <limit effort="1000.0" lower="-0.548" upper="0.548" velocity="0.5"/>
  </joint>
  <link name="branch_5">
    <visual>
      <geometry>
        <box size="0.1 0.1 0.2"/>
      </geometry>
      <origin rpy="0 0 0" xyz="0 0 0.1"/>
      <material name="white"/>
    </visual>
    <collision>
      <geometry>
        <box size="0.1 0.1 0.2"/>
      </geometry>
      <origin rpy="0 0 0" xyz="0 0 0.1"/>
    </collision>
    <inertial>
      <mass value="10"/>
      <inertia ixx="1.0" ixy="0.0" ixz="0.0" iyy="1.0" iyz="0.0" izz="1.0"/>
    </inertial>
  </link>
  <joint name="revolute_5" type="revolute">
    <parent link="branch_4"/>
    <child link="branch_5"/>
    <origin rpy="-0.196798 -0.003727 0.017126" xyz="0 0 0.2"/>
    <axis xyz="1 0 0"/>
    <limit effort="1000.0" lower="-0.548" upper="0.548" velocity="0.5"/>
  </joint>
  <link name="branch_6">
    <visual>
      <geometry>
        <box size="0.1 0.1 0.2"/>
      </geometry>
      <origin rpy="0 0 0" xyz="0 0 0.1"/>
      <material name="white"/>
    </visual>
    <collision>
      <geometry>
        <box size="0.1 0.1 0.2"/>
      </geometry>
      <origin rpy="0 0 0" xyz="0 0 0.1"/>
    </collision>
    <inertial>
      <mass value="10"/>
      <inertia ixx="1.0" ixy="0.0" ixz="0.0" iyy="1.0" iyz="0.0" izz="1.0"/>
    </inertial>
  </link>
  <joint name="revolute_6" type="revolute">
    <parent link="branch_5"/>
    <child link="branch_6"/>
    <origin rpy="0.973772 -0.147486 0.029199" xyz="0 0 0.2"/>
    <axis xyz="0 1 0"/>
    <limit effort="1000.0" lower="-0.548" upper="0.548" velocity="0.5"/>
  </joint>
  <link name="branch_7">
    <visual>
      <geometry>
        <box size="0.1 0.1 0.2"/>
      </geometry>
      <origin rpy="0 0 0" xyz="0 0 0.1"/>
      <material name="white"/>
    </visual>
    <collision>
      <geometry>
        <box size="0.1 0.1 0.2"/>
      </geometry>
      <origin rpy="0 0 0" xyz="0 0 0.1"/>
    </collision>
    <inertial>
      <mass value="10"/>
      <inertia ixx="1.0" ixy="0.0" ixz="0.0" iyy="1.0" iyz="0.0" izz="1.0"/>
    </inertial>
  </link>
  <joint name="revolute_7" type="revolute">
    <parent link="branch_6"/>
    <child link="branch_7"/>
    <origin rpy="0.340096 -0.275902 0.023494" xyz="0 0 0.2"/>
    <axis xyz="0 0 1"/>
    <limit effort="1000.0" lower="-0.548" upper="0.548" velocity="0.5"/>
  </joint>
  <link name="branch_8">
    <visual>
      <geometry>
        <box size="0.1 0.1 0.2"/>
      </geometry>
      <origin rpy="0 0 0" xyz="0 0 0.1"/>
      <material name="white"/>
    </visual>
    <collision>
      <geometry>
        <box size="0.1 0.1 0.2"/>
      </geometry>
      <origin rpy="0 0 0" xyz="0 0 0.1"/>
    </collision>
    <inertial>
      <mass value="10"/>
      <inertia ixx="1.0" ixy="0.0" ixz="0.0" iyy="1.0" iyz="0.0" izz="1.0"/>
    </inertial>
  </link>
  <joint name="revolute_8" type="revolute">
    <parent link="branch_7"/>
    <child link="branch_8"/>
    <origin rpy="-0.704116 -0.470497 0.208567" xyz="0 0 0.2"/>
    <axis xyz="1 0 0"/>
    <limit effort="1000.0" lower="-0.548" upper="0.548" velocity="0.5"/>
  </joint>
  <link name="branch_9">
    <visual>
      <geometry>
        <box size="0.1 0.1 0.2"/>
      </geometry>
      <origin rpy="0 0 0" xyz="0 0 0.1"/>
      <material name="white"/>
    </visual>
    <collision>
      <geometry>
        <box size="0.1 0.1 0.2"/>
      </geometry>
      <origin rpy="0 0 0" xyz="0 0 0.1"/>
    </collision>
    <inertial>
      <mass value="10"/>
      <inertia ixx="1.0" ixy="0.0" ixz="0.0" iyy="1.0" iyz="0.0" izz="1.0"/>
    </inertial>
  </link>
  <joint name="revolute_9" type="revolute">
    <parent link="branch_8"/>
    <child link="branch_9"/>
    <origin rpy="0.444512 0.588721 0.675735" xyz="0 0 0.2"/>
    <axis xyz="0 1 0"/>
    <limit effort="1000.0" lower="-0.548" upper="0.548" velocity="0.5"/>
  </joint>
  <link name="branch_10">
    <visual>
      <geometry>
        <box size="0.1 0.1 0.2"/>
      </geometry>
      <origin rpy="0 0 0" xyz="0 0 0.1"/>
      <material name="white"/>
    </visual>
    <collision>
      <geometry>
        <box size="0.1 0.1 0.2"/>
      </geometry>
      <origin rpy="0 0 0" xyz="0 0 0.1"/>
    </collision>
    <inertial>
      <mass value="10"/>
      <inertia ixx="1.0" ixy="0.0" ixz="0.0" iyy="1.0" iyz="0.0" izz="1.0"/>
    </inertial>
  </link>
  <joint name="revolute_10" type="revolute">
    <parent link="branch_9"/>
    <child link="branch_10"/>
    <origin rpy="-0.533240 0.514142 0.949813" xyz="0 0 0.2"/>
    <axis xyz="0 0 1"/>
    <limit effort="1000.0" lower="-0.548" upper="0.548" velocity="0.5"/>
  </joint>
  <link name="branch_11">
    <visual>
      <geometry>
        <box size="0.1 0.1 0.2"/>
      </geometry>
      <origin rpy="0 0 0" xyz="0 0 0.1"/>
      <material name="white"/>
    </visual>
    <collision>
      <geometry>
        <box size="0.1 0.1 0.2"/>
      </geometry>
      <origin rpy="0 0 0" xyz="0 0 0.1"/>
    </collision>
    <inertial>
      <mass value="10"/>
      <inertia ixx="1.0" ixy="0.0" ixz="0.0" iyy="1.0" iyz="0.0" izz="1.0"/>
    </inertial>
  </link>
  <joint name="revolute_11" type="revolute">
    <parent link="branch_10"/>
    <child link="branch_11"/>
    <origin rpy="0.558603 0.659683 -0.732984" xyz="0 0 0.2"/>
    <axis xyz="1 0 0"/>
    <limit effort="1000.0" lower="-0.548" upper="0.548" velocity="0.5"/>
  </joint>
  <link name="branch_12">
    <visual>
      <geometry>
        <box size="0.1 0.1 0.2"/>
      </geometry>
      <origin rpy="0 0 0" xyz="0 0 0.1"/>
      <material name="white"/>
    </visual>
    <collision>
      <geometry>
        <box size="0.1 0.1 0.2"/>
      </geometry>
      <origin rpy="0 0 0" xyz="0 0 0.1"/>
    </collision>
    <inertial>
      <mass value="10"/>
      <inertia ixx="1.0" ixy="0.0" ixz="0.0" iyy="1.0" iyz="0.0" izz="1.0"/>
    </inertial>
  </link>
  <joint name="revolute_12" type="revolute">
    <parent link="branch_11"/>
    <child link="branch_12"/>
    <origin rpy="0.395155 -0.064439 0.339545" xyz="0 0 0.2"/>
    <axis xyz="0 1 0"/>
    <limit effort="1000.0" lower="-0.548" upper="0.548" velocity="0.5"/>
  </joint>
  <link name="branch_13">
    <visual>
      <geometry>
        <box size="0.1 0.1 0.2"/>
      </geometry>
      <origin rpy="0 0 0" xyz="0 0 0.1"/>
      <material name="white"/>
    </visual>
    <collision>
      <geometry>
        <box size="0.1 0.1 0.2"/>
      </geometry>
      <origin rpy="0 0 0" xyz="0 0 0.1"/>
    </collision>
    <inertial>
      <mass value="10"/>
      <inertia ixx="1.0" ixy="0.0" ixz="0.0" iyy="1.0" iyz="0.0" izz="1.0"/>
    </inertial>
  </link>
  <joint name="revolute_13" type="revolute">
    <parent link="branch_12"/>
    <child link="branch_13"/>
    <origin rpy="-0.437063 -0.832508 -0.663517" xyz="0 0 0.2"/>
    <axis xyz="0 0 1"/>
    <limit effort="1000.0" lower="-0.548" upper="0.548" velocity="0.5"/>
  </joint>
  <link name="branch_14">
    <visual>
      <geometry>
        <box size="0.1 0.1 0.2"/>
      </geometry>
      <origin rpy="0 0 0" xyz="0 0 0.1"/>
      <material name="white"/>
    </visual>
    <collision>
      <geometry>
        <box size="0.1 0.1 0.2"/>
      </geometry>
      <origin rpy="0 0 0" xyz="0 0 0.1"/>
    </collision>
    <inertial>
      <mass value="10"/>
      <inertia ixx="1.0" ixy="0.0" ixz="0.0" iyy="1.0" iyz="0.0" izz="1.0"/>
    </inertial>
  </link>
  <joint name="revolute_14" type="revolute">
    <parent link="branch_13"/>
    <child link="branch_14"/>
    <origin rpy="-0.934289 -0.239580 0.943721" xyz="0 0 0.2"/>
    <axis xyz="1 0 0"/>
    <limit effort="1000.0" lower="-0.548" upper="0.548" velocity="0.5"/>
  </joint>
  <link name="branch_15">
    <visual>
      <geometry>
        <box size="0.1 0.1 0.2"/>
      </geometry>
      <origin rpy="0 0 0" xyz="0 0 0.1"/>
      <material name="white"/>
    </visual>
    <collision>
      <geometry>
        <box size="0.1 0.1 0.2"/>
      </geometry>
      <origin rpy="0 0 0" xyz="0 0 0.1"/>
    </collision>
    <inertial>
      <mass value="10"/>
      <inertia ixx="1.0" ixy="0.0" ixz="0.0" iyy="1.0" iyz="0.0" izz="1.0"/>
    </inertial>
  </link>
  <joint name="revolute_15" type="revolute">
    <parent link="branch_14"/>
    <child link="branch_15"/>
    <origin rpy="0.061985 0.777546 0.442957" xyz="0 0 0.2"/>
    <axis xyz="0 1 0"/>
    <limit effort="1000.0" lower="-0.548" upper="0.548" velocity="0.5"/>
  </joint>
  <link name="branch_16">
    <visual>
      <geometry>
        <box size="0.1 0.1 0.2"/>
      </geometry>
      <origin rpy="0 0 0" xyz="0 0 0.1"/>
      <material name="white"/>
    </visual>
    <collision>
      <geometry>
        <box size="0.1 0.1 0.2"/>
      </geometry>
      <origin rpy="0 0 0" xyz="0 0 0.1"/>
    </collision>
    <inertial>
      <mass value="10"/>
      <inertia ixx="1.0" ixy="0.0" ixz="0.0" iyy="1.0" iyz="0.0" izz="1.0"/>
    </inertial>
  </link>
  <joint name="revolute_16" type="revolute">
    <parent link="branch_15"/>
    <child link="branch_16"/>
    <origin rpy="0.914498 -0.193255 -0.753840" xyz="0 0 0.2"/>
    <axis xyz="0 0 1"/>
    <limit effort="1000.0" lower="-0.548" upper="0.548" velocity="0.5"/>
  </joint>
  <link name="branch_17">
    <visual>
      <geometry>
        <box size="0.1 0.1 0.2"/>
      </geometry>
      <origin rpy="0 0 0" xyz="0 0 0.1"/>
      <material name="white"/>
    </visual>
    <collision>
      <geometry>
        <box size="0.1 0.1 0.2"/>
      </geometry>
      <origin rpy="0 0 0" xyz="0 0 0.1"/>
    </collision>
    <inertial>
      <mass value="10"/>
      <inertia ixx="1.0" ixy="0.0" ixz="0.0" iyy="1.0" iyz="0.0" izz="1.0"/>
    </inertial>
  </link>
  <joint name="revolute_17" type="revolute">
    <parent link="branch_16"/>
    <child link="branch_17"/>
    <origin rpy="-0.361404 0.830239 -0.780069" xyz="0 0 0.2"/>
    <axis xyz="1 0 0"/>
    <limit effort="1000.0" lower="-0.548" upper="0.548" velocity="0.5"/>
  </joint>
  <link name="branch_18">
    <visual>
      <geometry>
        <box size="0.1 0.1 0.2"/>
      </geometry>
      <origin rpy="0 0 0" xyz="0 0 0.1"/>
      <material name="white"/>
    </visual>
    <collision>
      <geometry>
        <box size="0.1 0.1 0.2"/>
      </geometry>
      <origin rpy="0 0 0" xyz="0 0 0.1"/>
    </collision>
    <inertial>
      <mass value="10"/>
      <inertia ixx="1.0" ixy="0.0" ixz="0.0" iyy="1.0" iyz="0.0" izz="1.0"/>
    </inertial>
  </link>
  <joint name="revolute_18" type="revolute">
    <parent link="branch_17"/>
    <child link="branch_18"/>
    <origin rpy="0.168099 0.038807 0.560028" xyz="0 0 0.2"/>
    <axis xyz="0 1 0"/>
    <limit effort="1000.0" lower="-0.548" upper="0.548" velocity="0.5"/>
  </joint>
  <link name="branch_19">
    <visual>
      <geometry>
        <box size="0.1 0.1 0.2"/>
      </geometry>
      <origin rpy="0 0 0" xyz="0 0 0.1"/>
      <material name="white"/>
    </visual>
    <collision>
      <geometry>
        <box size="0.1 0.1 0.2"/>
      </geometry>
      <origin rpy="0 0 0" xyz="0 0 0.1"/>
    </collision>
    <inertial>
      <mass value="10"/>
      <inertia ixx="1.0" ixy="0.0" ixz="0.0" iyy="1.0" iyz="0.0" izz="1.0"/>
    </inertial>
  </link>
  <joint name="revolute_19" type="revolute">
    <parent link="branch_18"/>
    <child link="branch_19"/>
    <origin rpy="-0.243181 -0.285458 0.855912" xyz="0 0 0.2"/>
    <axis xyz="0 0 1"/>
    <limit effort="1000.0" lower="-0.548" upper="0.548" velocity="0.5"/>
  </joint>
  <link name="branch_20">
    <visual>
      <geometry>
        <box size="0.1 0.1 0.2"/>
      </geometry>
      <origin rpy="0 0 0" xyz="0 0 0.1"/>
      <material name="white"/>
    </visual>
    <collision>
      <geometry>
        <box size="0.1 0.1 0.2"/>
      </geometry>
      <origin rpy="0 0 0" xyz="0 0 0.1"/>
    </collision>
    <inertial>
      <mass value="10"/>
      <inertia ixx="1.0" ixy="0.0" ixz="0.0" iyy="1.0" iyz="0.0" izz="1.0"/>
    </inertial>
  </link>
  <joint name="revolute_20" type="revolute">
    <parent link="branch_19"/>
    <child link="branch_20"/>
    <origin rpy="-0.729039 -0.335645 0.300424" xyz="0 0 0.2"/>
    <axis xyz="1 0 0"/>
    <limit effort="1000.0" lower="-0.548" upper="0.548" velocity="0.5"/>
  </joint>
  <link name="branch_21">
    <visual>
      <geometry>
        <box size="0.1 0.1 0.2"/>
      </geometry>
      <origin rpy="0 0 0" xyz="0 0 0.1"/>
      <material name="white"/>
    </visual>
    <collision>
      <geometry>
        <box size="0.1 0.1 0.2"/>
      </geometry>
      <origin rpy="0 0 0" xyz="0 0 0.1"/>
    </collision>
    <inertial>
      <mass value="10"/>
      <inertia ixx="1.0" ixy="0.0" ixz="0.0" iyy="1.0" iyz="0.0" izz="1.0"/>
    </inertial>
  </link>
  <joint name="revolute_21" type="revolute">
    <parent link="branch_20"/>
    <child link="branch_21"/>
    <origin rpy="0.930644 -0.068630 0.767184" xyz="0 0 0.2"/>
    <axis xyz="0 1 0"/>
    <limit effort="1000.0" lower="-0.548" upper="0.548" velocity="0.5"/>
  </joint>
  <link name="branch_22">
    <visual>
      <geometry>
        <box size="0.1 0.1 0.2"/>
      </geometry>
      <origin rpy="0 0 0" xyz="0 0 0.1"/>
      <material name="white"/>
    </visual>
    <collision>
      <geometry>
        <box size="0.1 0.1 0.2"/>
      </geometry>
      <origin rpy="0 0 0" xyz="0 0 0.1"/>
    </collision>
    <inertial>
      <mass value="10"/>
      <inertia ixx="1.0" ixy="0.0" ixz="0.0" iyy="1.0" iyz="0.0" izz="1.0"/>
    </inertial>
  </link>
  <joint name="revolute_22" type="revolute">
    <parent link="branch_21"/>
    <child link="branch_22"/>
    <origin rpy="-0.133795 -0.729085 0.325787" xyz="0 0 0.2"/>
    <axis xyz="0 0 1"/>
    <limit effort="1000.0" lower="-0.548" upper="0.548" velocity="0.5"/>
  </joint>
  <link name="branch_23">
    <visual>
      <geometry>
        <box size="0.1 0.1 0.2"/>
      </geometry>
      <origin rpy="0 0 0" xyz="0 0 0.1"/>
      <material name="white"/>
    </visual>
    <collision>
      <geometry>
        <box size="0.1 0.1 0.2"/>
      </geometry>
      <origin rpy="0 0 0" xyz="0 0 0.1"/>
    </collision>
    <inertial>
      <mass value="10"/>
      <inertia ixx="1.0" ixy="0.0" ixz="0.0" iyy="1.0" iyz="0.0" izz="1.0"/>
    </inertial>
  </link>
  <joint name="revolute_23" type="revolute">
    <parent link="branch_22"/>
    <child link="branch_23"/>
    <origin rpy="0.033697 -0.392602 -0.279058" xyz="0 0 0.2"/>
    <axis xyz="1 0 0"/>
    <limit effort="1000.0" lower="-0.548" upper="0.548" velocity="0.5"/>
  </joint>
  <link name="branch_24">
    <visual>
      <geometry>
        <box size="0.1 0.1 0.2"/>
      </geometry>
      <origin rpy="0 0 0" xyz="0 0 0.1"/>
      <material name="white"/>
    </visual>
    <collision>
      <geometry>
        <box size="0.1 0.1 0.2"/>
      </geometry>
      <origin rpy="0 0 0" xyz="0 0 0.1"/>
    </collision>
    <inertial>
      <mass value="10"/>
      <inertia ixx="1.0" ixy="0.0" ixz="0.0" iyy="1.0" iyz="0.0" izz="1.0"/>
    </inertial>
  </link>
  <joint name="revolute_24" type="revolute">
    <parent link="branch_23"/>
    <child link="branch_24"/>
    <origin rpy="0.794117 -0.448880 0.283879" xyz="0 0 0.2"/>
    <axis xyz="0 1 0"/>
    <limit effort="1000.0" lower="-0.548" upper="0.548" velocity="0.5"/>
  </joint>
  <link name="branch_25">
    <visual>
      <geometry>
        <box size="0.1 0.1 0.2"/>
      </geometry>
      <origin rpy="0 0 0" xyz="0 0 0.1"/>
      <material name="white"/>
    </visual>
    <collision>
      <geometry>
        <box size="0.1 0.1 0.2"/>
      </geometry>
      <origin rpy="0 0 0" xyz="0 0 0.1"/>
    </collision>
    <inertial>
      <mass value="10"/>
      <inertia ixx="1.0" ixy="0.0" ixz="0.0" iyy="1.0" iyz="0.0" izz="1.0"/>
    </inertial>
  </link>
  <joint name="revolute_25" type="revolute">
    <parent link="branch_24"/>
    <child link="branch_25"/>
    <origin rpy="0.571663 0.994077 0.349590" xyz="0 0 0.2"/>
    <axis xyz="0 0 1"/>
    <limit effort="1000.0" lower="-0.548" upper="0.548" velocity="0.5"/>
  </joint>
  <link name="head">
    <visual>
      <geometry>
        <sphere radius="0.1"/>
      </geometry>
      <material name="black"/>
    </visual>
    <collision>
      <geometry>
        <sphere radius="0.1"/>
      </geometry>
    </collision>
    <inertial>
      <mass value="2"/>
      <inertia ixx="1.0" ixy="0.0" ixz="0.0" iyy="1.0" iyz="0.0" izz="1.0"/>
    </inertial>
  </link>
  <joint name="head_swivel" type="continuous">
    <parent link="branch_25"/>
    <child link="head"/>
    <origin xyz="0 0 0.2"/>
    <axis xyz="0 0 1"/>
  </joint>
</robot>

