<?xml version="1.0" ?>
<!-- =================================================================================== -->
<!-- |    This document was autogenerated by xacro from ../urdf/d_0100_3.urdf.xacro    | -->
<!-- |    EDITING THIS FILE BY HAND IS NOT RECOMMENDED                                 | -->
<!-- =================================================================================== -->
<robot name="multi_degree" xmlns:xacro="http://ros.org/wiki/xacro">
  <material name="blue">
    <color rgba="0 0 0.8 1"/>
  </material>
  <material name="black">
    <color rgba="0 0 0 1"/>
  </material>
  <material name="white">
    <color rgba="1 1 1 1"/>
  </material>
  <link name="branch_0">
    <visual>
      <geometry>
        <cylinder length="0.4" radius="0.1"/>
      </geometry>
      <material name="blue"/>
    </visual>
    <collision>
      <geometry>
        <cylinder length="0.4" radius="0.1"/>
      </geometry>
    </collision>
    <inertial>
      <mass value="10"/>
      <inertia ixx="1.0" ixy="0.0" ixz="0.0" iyy="1.0" iyz="0.0" izz="1.0"/>
    </inertial>
  </link>
  <link name="branch_1">
    <visual>
      <geometry>
        <box size="0.1 0.1 0.2"/>
      </geometry>
      <origin rpy="0 0 0" xyz="0 0 0.1"/>
      <material name="white"/>
    </visual>
    <collision>
      <geometry>
        <box size="0.1 0.1 0.2"/>
      </geometry>
      <origin rpy="0 0 0" xyz="0 0 0.1"/>
    </collision>
    <inertial>
      <mass value="10"/>
      <inertia ixx="1.0" ixy="0.0" ixz="0.0" iyy="1.0" iyz="0.0" izz="1.0"/>
    </inertial>
  </link>
  <joint name="revolute_1" type="revolute">
    <parent link="branch_0"/>
    <child link="branch_1"/>
    <origin rpy="0.449092 0.596963 0.756263" xyz="0.010334 0.054450 0.534072"/>
    <axis xyz="0.459515 0.350131 0.822310"/>
    <limit effort="1000.0" lower="-0.548" upper="0.548" velocity="0.5"/>
  </joint>
  <link name="branch_2">
    <visual>
      <geometry>
        <box size="0.1 0.1 0.2"/>
      </geometry>
      <origin rpy="0 0 0" xyz="0 0 0.1"/>
      <material name="white"/>
    </visual>
    <collision>
      <geometry>
        <box size="0.1 0.1 0.2"/>
      </geometry>
      <origin rpy="0 0 0" xyz="0 0 0.1"/>
    </collision>
    <inertial>
      <mass value="10"/>
      <inertia ixx="1.0" ixy="0.0" ixz="0.0" iyy="1.0" iyz="0.0" izz="1.0"/>
    </inertial>
  </link>
  <joint name="revolute_2" type="revolute">
    <parent link="branch_1"/>
    <child link="branch_2"/>
    <origin rpy="-0.776407 -0.192676 0.398255" xyz="0.029390 0.024083 0.521881"/>
    <axis xyz="-0.225647 0.302123 -0.765741"/>
    <limit effort="1000.0" lower="-0.548" upper="0.548" velocity="0.5"/>
  </joint>
  <link name="branch_3">
    <visual>
      <geometry>
        <box size="0.1 0.1 0.2"/>
      </geometry>
      <origin rpy="0 0 0" xyz="0 0 0.1"/>
      <material name="white"/>
    </visual>
    <collision>
      <geometry>
        <box size="0.1 0.1 0.2"/>
      </geometry>
      <origin rpy="0 0 0" xyz="0 0 0.1"/>
    </collision>
    <inertial>
      <mass value="10"/>
      <inertia ixx="1.0" ixy="0.0" ixz="0.0" iyy="1.0" iyz="0.0" izz="1.0"/>
    </inertial>
  </link>
  <joint name="revolute_3" type="revolute">
    <parent link="branch_2"/>
    <child link="branch_3"/>
    <origin rpy="-0.233763 -0.426355 -0.417307" xyz="0.051181 0.053003 0.558445"/>
    <axis xyz="-0.826791 -0.733188 0.065680"/>
    <limit effort="1000.0" lower="-0.548" upper="0.548" velocity="0.5"/>
  </joint>
  <link name="branch_4">
    <visual>
      <geometry>
        <box size="0.1 0.1 0.2"/>
      </geometry>
      <origin rpy="0 0 0" xyz="0 0 0.1"/>
      <material name="white"/>
    </visual>
    <collision>
      <geometry>
        <box size="0.1 0.1 0.2"/>
      </geometry>
      <origin rpy="0 0 0" xyz="0 0 0.1"/>
    </collision>
    <inertial>
      <mass value="10"/>
      <inertia ixx="1.0" ixy="0.0" ixz="0.0" iyy="1.0" iyz="0.0" izz="1.0"/>
    </inertial>
  </link>
  <joint name="revolute_4" type="revolute">
    <parent link="branch_3"/>
    <child link="branch_4"/>
    <origin rpy="-0.007902 0.929472 0.953011" xyz="0.004055 0.063510 0.540210"/>
    <axis xyz="0.431234 0.092503 0.608787"/>
    <limit effort="1000.0" lower="-0.548" upper="0.548" velocity="0.5"/>
  </joint>
  <link name="branch_5">
    <visual>
      <geometry>
        <box size="0.1 0.1 0.2"/>
      </geometry>
      <origin rpy="0 0 0" xyz="0 0 0.1"/>
      <material name="white"/>
    </visual>
    <collision>
      <geometry>
        <box size="0.1 0.1 0.2"/>
      </geometry>
      <origin rpy="0 0 0" xyz="0 0 0.1"/>
    </collision>
    <inertial>
      <mass value="10"/>
      <inertia ixx="1.0" ixy="0.0" ixz="0.0" iyy="1.0" iyz="0.0" izz="1.0"/>
    </inertial>
  </link>
  <joint name="revolute_5" type="revolute">
    <parent link="branch_4"/>
    <child link="branch_5"/>
    <origin rpy="0.875626 -0.170512 0.200751" xyz="0.017864 0.002415 0.542434"/>
    <axis xyz="0.659409 -0.717442 -0.987851"/>
    <limit effort="1000.0" lower="-0.548" upper="0.548" velocity="0.5"/>
  </joint>
  <link name="branch_6">
    <visual>
      <geometry>
        <box size="0.1 0.1 0.2"/>
      </geometry>
      <origin rpy="0 0 0" xyz="0 0 0.1"/>
      <material name="white"/>
    </visual>
    <collision>
      <geometry>
        <box size="0.1 0.1 0.2"/>
      </geometry>
      <origin rpy="0 0 0" xyz="0 0 0.1"/>
    </collision>
    <inertial>
      <mass value="10"/>
      <inertia ixx="1.0" ixy="0.0" ixz="0.0" iyy="1.0" iyz="0.0" izz="1.0"/>
    </inertial>
  </link>
  <joint name="revolute_6" type="prismatic">
    <parent link="branch_5"/>
    <child link="branch_6"/>
    <origin rpy="0.360147 -0.757899 -0.514663" xyz="0.021010 0.091327 0.525157"/>
    <axis xyz="-0.312985 -0.107773 -0.724809"/>
    <limit effort="1000.0" lower="-0.548" upper="0.548" velocity="0.5"/>
  </joint>
  <link name="branch_7">
    <visual>
      <geometry>
        <box size="0.1 0.1 0.2"/>
      </geometry>
      <origin rpy="0 0 0" xyz="0 0 0.1"/>
      <material name="white"/>
    </visual>
    <collision>
      <geometry>
        <box size="0.1 0.1 0.2"/>
      </geometry>
      <origin rpy="0 0 0" xyz="0 0 0.1"/>
    </collision>
    <inertial>
      <mass value="10"/>
      <inertia ixx="1.0" ixy="0.0" ixz="0.0" iyy="1.0" iyz="0.0" izz="1.0"/>
    </inertial>
  </link>
  <joint name="revolute_7" type="prismatic">
    <parent link="branch_6"/>
    <child link="branch_7"/>
    <origin rpy="-0.622128 -0.359973 -0.712638" xyz="0.082403 0.002107 0.527946"/>
    <axis xyz="-0.259433 0.650917 0.360562"/>
    <limit effort="1000.0" lower="-0.548" upper="0.548" velocity="0.5"/>
  </joint>
  <link name="branch_8">
    <visual>
      <geometry>
        <box size="0.1 0.1 0.2"/>
      </geometry>
      <origin rpy="0 0 0" xyz="0 0 0.1"/>
      <material name="white"/>
    </visual>
    <collision>
      <geometry>
        <box size="0.1 0.1 0.2"/>
      </geometry>
      <origin rpy="0 0 0" xyz="0 0 0.1"/>
    </collision>
    <inertial>
      <mass value="10"/>
      <inertia ixx="1.0" ixy="0.0" ixz="0.0" iyy="1.0" iyz="0.0" izz="1.0"/>
    </inertial>
  </link>
  <joint name="revolute_8" type="revolute">
    <parent link="branch_7"/>
    <child link="branch_8"/>
    <origin rpy="0.621284 0.941318 -0.280781" xyz="0.083479 0.068283 0.459485"/>
    <axis xyz="0.952141 0.377811 -0.047869"/>
    <limit effort="1000.0" lower="-0.548" upper="0.548" velocity="0.5"/>
  </joint>
  <link name="branch_9">
    <visual>
      <geometry>
        <box size="0.1 0.1 0.2"/>
      </geometry>
      <origin rpy="0 0 0" xyz="0 0 0.1"/>
      <material name="white"/>
    </visual>
    <collision>
      <geometry>
        <box size="0.1 0.1 0.2"/>
      </geometry>
      <origin rpy="0 0 0" xyz="0 0 0.1"/>
    </collision>
    <inertial>
      <mass value="10"/>
      <inertia ixx="1.0" ixy="0.0" ixz="0.0" iyy="1.0" iyz="0.0" izz="1.0"/>
    </inertial>
  </link>
  <joint name="revolute_9" type="revolute">
    <parent link="branch_8"/>
    <child link="branch_9"/>
    <origin rpy="-0.146359 -0.562522 -0.835687" xyz="0.034009 0.084453 0.552446"/>
    <axis xyz="0.572415 0.964244 0.944663"/>
    <limit effort="1000.0" lower="-0.548" upper="0.548" velocity="0.5"/>
  </joint>
  <link name="branch_10">
    <visual>
      <geometry>
        <box size="0.1 0.1 0.2"/>
      </geometry>
      <origin rpy="0 0 0" xyz="0 0 0.1"/>
      <material name="white"/>
    </visual>
    <collision>
      <geometry>
        <box size="0.1 0.1 0.2"/>
      </geometry>
      <origin rpy="0 0 0" xyz="0 0 0.1"/>
    </collision>
    <inertial>
      <mass value="10"/>
      <inertia ixx="1.0" ixy="0.0" ixz="0.0" iyy="1.0" iyz="0.0" izz="1.0"/>
    </inertial>
  </link>
  <joint name="revolute_10" type="revolute">
    <parent link="branch_9"/>
    <child link="branch_10"/>
    <origin rpy="0.271705 0.859777 -0.587356" xyz="0.065692 0.056962 0.479052"/>
    <axis xyz="-0.035248 -0.500201 -0.561419"/>
    <limit effort="1000.0" lower="-0.548" upper="0.548" velocity="0.5"/>
  </joint>
  <link name="branch_11">
    <visual>
      <geometry>
        <box size="0.1 0.1 0.2"/>
      </geometry>
      <origin rpy="0 0 0" xyz="0 0 0.1"/>
      <material name="white"/>
    </visual>
    <collision>
      <geometry>
        <box size="0.1 0.1 0.2"/>
      </geometry>
      <origin rpy="0 0 0" xyz="0 0 0.1"/>
    </collision>
    <inertial>
      <mass value="10"/>
      <inertia ixx="1.0" ixy="0.0" ixz="0.0" iyy="1.0" iyz="0.0" izz="1.0"/>
    </inertial>
  </link>
  <joint name="revolute_11" type="prismatic">
    <parent link="branch_10"/>
    <child link="branch_11"/>
    <origin rpy="0.120466 0.683972 0.291594" xyz="0.024306 0.013941 0.491288"/>
    <axis xyz="0.863938 0.230948 -0.417539"/>
    <limit effort="1000.0" lower="-0.548" upper="0.548" velocity="0.5"/>
  </joint>
  <link name="branch_12">
    <visual>
      <geometry>
        <box size="0.1 0.1 0.2"/>
      </geometry>
      <origin rpy="0 0 0" xyz="0 0 0.1"/>
      <material name="white"/>
    </visual>
    <collision>
      <geometry>
        <box size="0.1 0.1 0.2"/>
      </geometry>
      <origin rpy="0 0 0" xyz="0 0 0.1"/>
    </collision>
    <inertial>
      <mass value="10"/>
      <inertia ixx="1.0" ixy="0.0" ixz="0.0" iyy="1.0" iyz="0.0" izz="1.0"/>
    </inertial>
  </link>
  <joint name="revolute_12" type="revolute">
    <parent link="branch_11"/>
    <child link="branch_12"/>
    <origin rpy="-0.027919 -0.971749 0.842487" xyz="0.033057 0.077636 0.469613"/>
    <axis xyz="-0.374623 0.497374 0.376315"/>
    <limit effort="1000.0" lower="-0.548" upper="0.548" velocity="0.5"/>
  </joint>
  <link name="branch_13">
    <visual>
      <geometry>
        <box size="0.1 0.1 0.2"/>
      </geometry>
      <origin rpy="0 0 0" xyz="0 0 0.1"/>
      <material name="white"/>
    </visual>
    <collision>
      <geometry>
        <box size="0.1 0.1 0.2"/>
      </geometry>
      <origin rpy="0 0 0" xyz="0 0 0.1"/>
    </collision>
    <inertial>
      <mass value="10"/>
      <inertia ixx="1.0" ixy="0.0" ixz="0.0" iyy="1.0" iyz="0.0" izz="1.0"/>
    </inertial>
  </link>
  <joint name="revolute_13" type="revolute">
    <parent link="branch_12"/>
    <child link="branch_13"/>
    <origin rpy="-0.191493 0.038021 -0.870948" xyz="0.097387 0.091427 0.540076"/>
    <axis xyz="-0.552458 -0.732882 -0.285409"/>
    <limit effort="1000.0" lower="-0.548" upper="0.548" velocity="0.5"/>
  </joint>
  <link name="branch_14">
    <visual>
      <geometry>
        <box size="0.1 0.1 0.2"/>
      </geometry>
      <origin rpy="0 0 0" xyz="0 0 0.1"/>
      <material name="white"/>
    </visual>
    <collision>
      <geometry>
        <box size="0.1 0.1 0.2"/>
      </geometry>
      <origin rpy="0 0 0" xyz="0 0 0.1"/>
    </collision>
    <inertial>
      <mass value="10"/>
      <inertia ixx="1.0" ixy="0.0" ixz="0.0" iyy="1.0" iyz="0.0" izz="1.0"/>
    </inertial>
  </link>
  <joint name="revolute_14" type="revolute">
    <parent link="branch_13"/>
    <child link="branch_14"/>
    <origin rpy="0.363315 0.739136 0.446266" xyz="0.082107 0.032601 0.456673"/>
    <axis xyz="-0.126920 0.234475 0.052860"/>
    <limit effort="1000.0" lower="-0.548" upper="0.548" velocity="0.5"/>
  </joint>
  <link name="branch_15">
    <visual>
      <geometry>
        <box size="0.1 0.1 0.2"/>
      </geometry>
      <origin rpy="0 0 0" xyz="0 0 0.1"/>
      <material name="white"/>
    </visual>
    <collision>
      <geometry>
        <box size="0.1 0.1 0.2"/>
      </geometry>
      <origin rpy="0 0 0" xyz="0 0 0.1"/>
    </collision>
    <inertial>
      <mass value="10"/>
      <inertia ixx="1.0" ixy="0.0" ixz="0.0" iyy="1.0" iyz="0.0" izz="1.0"/>
    </inertial>
  </link>
  <joint name="revolute_15" type="revolute">
    <parent link="branch_14"/>
    <child link="branch_15"/>
    <origin rpy="-0.054951 -0.284432 0.769077" xyz="0.024888 0.070585 0.474116"/>
    <axis xyz="0.995133 -0.211989 0.402291"/>
    <limit effort="1000.0" lower="-0.548" upper="0.548" velocity="0.5"/>
  </joint>
  <link name="branch_16">
    <visual>
      <geometry>
        <box size="0.1 0.1 0.2"/>
      </geometry>
      <origin rpy="0 0 0" xyz="0 0 0.1"/>
      <material name="white"/>
    </visual>
    <collision>
      <geometry>
        <box size="0.1 0.1 0.2"/>
      </geometry>
      <origin rpy="0 0 0" xyz="0 0 0.1"/>
    </collision>
    <inertial>
      <mass value="10"/>
      <inertia ixx="1.0" ixy="0.0" ixz="0.0" iyy="1.0" iyz="0.0" izz="1.0"/>
    </inertial>
  </link>
  <joint name="revolute_16" type="revolute">
    <parent link="branch_15"/>
    <child link="branch_16"/>
    <origin rpy="0.065689 -0.875815 0.736741" xyz="0.044711 0.076247 0.454525"/>
    <axis xyz="0.161344 -0.760467 -0.507009"/>
    <limit effort="1000.0" lower="-0.548" upper="0.548" velocity="0.5"/>
  </joint>
  <link name="branch_17">
    <visual>
      <geometry>
        <box size="0.1 0.1 0.2"/>
      </geometry>
      <origin rpy="0 0 0" xyz="0 0 0.1"/>
      <material name="white"/>
    </visual>
    <collision>
      <geometry>
        <box size="0.1 0.1 0.2"/>
      </geometry>
      <origin rpy="0 0 0" xyz="0 0 0.1"/>
    </collision>
    <inertial>
      <mass value="10"/>
      <inertia ixx="1.0" ixy="0.0" ixz="0.0" iyy="1.0" iyz="0.0" izz="1.0"/>
    </inertial>
  </link>
  <joint name="revolute_17" type="revolute">
    <parent link="branch_16"/>
    <child link="branch_17"/>
    <origin rpy="-0.320331 -0.392390 0.918876" xyz="0.066584 0.058717 0.528219"/>
    <axis xyz="-0.433842 -0.772798 -0.075676"/>
    <limit effort="1000.0" lower="-0.548" upper="0.548" velocity="0.5"/>
  </joint>
  <link name="branch_18">
    <visual>
      <geometry>
        <box size="0.1 0.1 0.2"/>
      </geometry>
      <origin rpy="0 0 0" xyz="0 0 0.1"/>
      <material name="white"/>
    </visual>
    <collision>
      <geometry>
        <box size="0.1 0.1 0.2"/>
      </geometry>
      <origin rpy="0 0 0" xyz="0 0 0.1"/>
    </collision>
    <inertial>
      <mass value="10"/>
      <inertia ixx="1.0" ixy="0.0" ixz="0.0" iyy="1.0" iyz="0.0" izz="1.0"/>
    </inertial>
  </link>
  <joint name="revolute_18" type="revolute">
    <parent link="branch_17"/>
    <child link="branch_18"/>
    <origin rpy="-0.487028 -0.664765 0.144000" xyz="0.096233 0.053820 0.408905"/>
    <axis xyz="-0.287322 -0.521317 -0.413191"/>
    <limit effort="1000.0" lower="-0.548" upper="0.548" velocity="0.5"/>
  </joint>
  <link name="branch_19">
    <visual>
      <geometry>
        <box size="0.1 0.1 0.2"/>
      </geometry>
      <origin rpy="0 0 0" xyz="0 0 0.1"/>
      <material name="white"/>
    </visual>
    <collision>
      <geometry>
        <box size="0.1 0.1 0.2"/>
      </geometry>
      <origin rpy="0 0 0" xyz="0 0 0.1"/>
    </collision>
    <inertial>
      <mass value="10"/>
      <inertia ixx="1.0" ixy="0.0" ixz="0.0" iyy="1.0" iyz="0.0" izz="1.0"/>
    </inertial>
  </link>
  <joint name="revolute_19" type="revolute">
    <parent link="branch_18"/>
    <child link="branch_19"/>
    <origin rpy="-0.293872 -0.550581 -0.493648" xyz="0.011553 0.049733 0.557204"/>
    <axis xyz="-0.529398 0.487659 -0.533733"/>
    <limit effort="1000.0" lower="-0.548" upper="0.548" velocity="0.5"/>
  </joint>
  <link name="branch_20">
    <visual>
      <geometry>
        <box size="0.1 0.1 0.2"/>
      </geometry>
      <origin rpy="0 0 0" xyz="0 0 0.1"/>
      <material name="white"/>
    </visual>
    <collision>
      <geometry>
        <box size="0.1 0.1 0.2"/>
      </geometry>
      <origin rpy="0 0 0" xyz="0 0 0.1"/>
    </collision>
    <inertial>
      <mass value="10"/>
      <inertia ixx="1.0" ixy="0.0" ixz="0.0" iyy="1.0" iyz="0.0" izz="1.0"/>
    </inertial>
  </link>
  <joint name="revolute_20" type="revolute">
    <parent link="branch_19"/>
    <child link="branch_20"/>
    <origin rpy="-0.764778 -0.610521 -0.571808" xyz="0.070478 0.083584 0.510786"/>
    <axis xyz="0.636766 -0.404006 -0.560456"/>
    <limit effort="1000.0" lower="-0.548" upper="0.548" velocity="0.5"/>
  </joint>
  <link name="branch_21">
    <visual>
      <geometry>
        <box size="0.1 0.1 0.2"/>
      </geometry>
      <origin rpy="0 0 0" xyz="0 0 0.1"/>
      <material name="white"/>
    </visual>
    <collision>
      <geometry>
        <box size="0.1 0.1 0.2"/>
      </geometry>
      <origin rpy="0 0 0" xyz="0 0 0.1"/>
    </collision>
    <inertial>
      <mass value="10"/>
      <inertia ixx="1.0" ixy="0.0" ixz="0.0" iyy="1.0" iyz="0.0" izz="1.0"/>
    </inertial>
  </link>
  <joint name="revolute_21" type="revolute">
    <parent link="branch_20"/>
    <child link="branch_21"/>
    <origin rpy="0.340937 -0.219233 -0.606602" xyz="0.020866 0.043491 0.490637"/>
    <axis xyz="-0.103987 0.456625 -0.168963"/>
    <limit effort="1000.0" lower="-0.548" upper="0.548" velocity="0.5"/>
  </joint>
  <link name="branch_22">
    <visual>
      <geometry>
        <box size="0.1 0.1 0.2"/>
      </geometry>
      <origin rpy="0 0 0" xyz="0 0 0.1"/>
      <material name="white"/>
    </visual>
    <collision>
      <geometry>
        <box size="0.1 0.1 0.2"/>
      </geometry>
      <origin rpy="0 0 0" xyz="0 0 0.1"/>
    </collision>
    <inertial>
      <mass value="10"/>
      <inertia ixx="1.0" ixy="0.0" ixz="0.0" iyy="1.0" iyz="0.0" izz="1.0"/>
    </inertial>
  </link>
  <joint name="revolute_22" type="revolute">
    <parent link="branch_21"/>
    <child link="branch_22"/>
    <origin rpy="0.993135 0.402364 -0.961432" xyz="0.049390 0.048720 0.474470"/>
    <axis xyz="-0.524539 0.440672 -0.024234"/>
    <limit effort="1000.0" lower="-0.548" upper="0.548" velocity="0.5"/>
  </joint>
  <link name="branch_23">
    <visual>
      <geometry>
        <box size="0.1 0.1 0.2"/>
      </geometry>
      <origin rpy="0 0 0" xyz="0 0 0.1"/>
      <material name="white"/>
    </visual>
    <collision>
      <geometry>
        <box size="0.1 0.1 0.2"/>
      </geometry>
      <origin rpy="0 0 0" xyz="0 0 0.1"/>
    </collision>
    <inertial>
      <mass value="10"/>
      <inertia ixx="1.0" ixy="0.0" ixz="0.0" iyy="1.0" iyz="0.0" izz="1.0"/>
    </inertial>
  </link>
  <joint name="revolute_23" type="revolute">
    <parent link="branch_22"/>
    <child link="branch_23"/>
    <origin rpy="0.835847 -0.096347 0.068283" xyz="0.075376 0.000576 0.530350"/>
    <axis xyz="-0.896488 -0.548942 -0.286931"/>
    <limit effort="1000.0" lower="-0.548" upper="0.548" velocity="0.5"/>
  </joint>
  <link name="branch_24">
    <visual>
      <geometry>
        <box size="0.1 0.1 0.2"/>
      </geometry>
      <origin rpy="0 0 0" xyz="0 0 0.1"/>
      <material name="white"/>
    </visual>
    <collision>
      <geometry>
        <box size="0.1 0.1 0.2"/>
      </geometry>
      <origin rpy="0 0 0" xyz="0 0 0.1"/>
    </collision>
    <inertial>
      <mass value="10"/>
      <inertia ixx="1.0" ixy="0.0" ixz="0.0" iyy="1.0" iyz="0.0" izz="1.0"/>
    </inertial>
  </link>
  <joint name="revolute_24" type="prismatic">
    <parent link="branch_23"/>
    <child link="branch_24"/>
    <origin rpy="0.130602 -0.503090 0.456760" xyz="0.000021 0.070164 0.479770"/>
    <axis xyz="0.457044 -0.765682 0.215026"/>
    <limit effort="1000.0" lower="-0.548" upper="0.548" velocity="0.5"/>
  </joint>
  <link name="branch_25">
    <visual>
      <geometry>
        <box size="0.1 0.1 0.2"/>
      </geometry>
      <origin rpy="0 0 0" xyz="0 0 0.1"/>
      <material name="white"/>
    </visual>
    <collision>
      <geometry>
        <box size="0.1 0.1 0.2"/>
      </geometry>
      <origin rpy="0 0 0" xyz="0 0 0.1"/>
    </collision>
    <inertial>
      <mass value="10"/>
      <inertia ixx="1.0" ixy="0.0" ixz="0.0" iyy="1.0" iyz="0.0" izz="1.0"/>
    </inertial>
  </link>
  <joint name="revolute_25" type="revolute">
    <parent link="branch_24"/>
    <child link="branch_25"/>
    <origin rpy="0.513403 0.495612 0.778033" xyz="0.024390 0.012015 0.577117"/>
    <axis xyz="0.928479 0.216073 -0.241030"/>
    <limit effort="1000.0" lower="-0.548" upper="0.548" velocity="0.5"/>
  </joint>
  <link name="branch_26">
    <visual>
      <geometry>
        <box size="0.1 0.1 0.2"/>
      </geometry>
      <origin rpy="0 0 0" xyz="0 0 0.1"/>
      <material name="white"/>
    </visual>
    <collision>
      <geometry>
        <box size="0.1 0.1 0.2"/>
      </geometry>
      <origin rpy="0 0 0" xyz="0 0 0.1"/>
    </collision>
    <inertial>
      <mass value="10"/>
      <inertia ixx="1.0" ixy="0.0" ixz="0.0" iyy="1.0" iyz="0.0" izz="1.0"/>
    </inertial>
  </link>
  <joint name="revolute_26" type="revolute">
    <parent link="branch_25"/>
    <child link="branch_26"/>
    <origin rpy="-0.861917 -0.003238 -0.337559" xyz="0.007480 0.015013 0.449829"/>
    <axis xyz="-0.399345 0.013336 -0.994195"/>
    <limit effort="1000.0" lower="-0.548" upper="0.548" velocity="0.5"/>
  </joint>
  <link name="branch_27">
    <visual>
      <geometry>
        <box size="0.1 0.1 0.2"/>
      </geometry>
      <origin rpy="0 0 0" xyz="0 0 0.1"/>
      <material name="white"/>
    </visual>
    <collision>
      <geometry>
        <box size="0.1 0.1 0.2"/>
      </geometry>
      <origin rpy="0 0 0" xyz="0 0 0.1"/>
    </collision>
    <inertial>
      <mass value="10"/>
      <inertia ixx="1.0" ixy="0.0" ixz="0.0" iyy="1.0" iyz="0.0" izz="1.0"/>
    </inertial>
  </link>
  <joint name="revolute_27" type="revolute">
    <parent link="branch_26"/>
    <child link="branch_27"/>
    <origin rpy="-0.393773 -0.942585 0.363172" xyz="0.000475 0.042756 0.449377"/>
    <axis xyz="-0.756175 -0.929863 -0.505808"/>
    <limit effort="1000.0" lower="-0.548" upper="0.548" velocity="0.5"/>
  </joint>
  <link name="branch_28">
    <visual>
      <geometry>
        <box size="0.1 0.1 0.2"/>
      </geometry>
      <origin rpy="0 0 0" xyz="0 0 0.1"/>
      <material name="white"/>
    </visual>
    <collision>
      <geometry>
        <box size="0.1 0.1 0.2"/>
      </geometry>
      <origin rpy="0 0 0" xyz="0 0 0.1"/>
    </collision>
    <inertial>
      <mass value="10"/>
      <inertia ixx="1.0" ixy="0.0" ixz="0.0" iyy="1.0" iyz="0.0" izz="1.0"/>
    </inertial>
  </link>
  <joint name="revolute_28" type="revolute">
    <parent link="branch_27"/>
    <child link="branch_28"/>
    <origin rpy="0.446848 -0.978141 -0.818824" xyz="0.084358 0.089651 0.569458"/>
    <axis xyz="-0.096771 -0.448003 -0.817614"/>
    <limit effort="1000.0" lower="-0.548" upper="0.548" velocity="0.5"/>
  </joint>
  <link name="branch_29">
    <visual>
      <geometry>
        <box size="0.1 0.1 0.2"/>
      </geometry>
      <origin rpy="0 0 0" xyz="0 0 0.1"/>
      <material name="white"/>
    </visual>
    <collision>
      <geometry>
        <box size="0.1 0.1 0.2"/>
      </geometry>
      <origin rpy="0 0 0" xyz="0 0 0.1"/>
    </collision>
    <inertial>
      <mass value="10"/>
      <inertia ixx="1.0" ixy="0.0" ixz="0.0" iyy="1.0" iyz="0.0" izz="1.0"/>
    </inertial>
  </link>
  <joint name="revolute_29" type="prismatic">
    <parent link="branch_28"/>
    <child link="branch_29"/>
    <origin rpy="0.107628 0.565670 0.786427" xyz="0.070395 0.003198 0.592451"/>
    <axis xyz="-0.578769 -0.930237 -0.925892"/>
    <limit effort="1000.0" lower="-0.548" upper="0.548" velocity="0.5"/>
  </joint>
  <link name="branch_30">
    <visual>
      <geometry>
        <box size="0.1 0.1 0.2"/>
      </geometry>
      <origin rpy="0 0 0" xyz="0 0 0.1"/>
      <material name="white"/>
    </visual>
    <collision>
      <geometry>
        <box size="0.1 0.1 0.2"/>
      </geometry>
      <origin rpy="0 0 0" xyz="0 0 0.1"/>
    </collision>
    <inertial>
      <mass value="10"/>
      <inertia ixx="1.0" ixy="0.0" ixz="0.0" iyy="1.0" iyz="0.0" izz="1.0"/>
    </inertial>
  </link>
  <joint name="revolute_30" type="revolute">
    <parent link="branch_29"/>
    <child link="branch_30"/>
    <origin rpy="-0.267822 0.784403 -0.820920" xyz="0.079364 0.013909 0.478531"/>
    <axis xyz="0.657426 -0.227631 -0.205185"/>
    <limit effort="1000.0" lower="-0.548" upper="0.548" velocity="0.5"/>
  </joint>
  <link name="branch_31">
    <visual>
      <geometry>
        <box size="0.1 0.1 0.2"/>
      </geometry>
      <origin rpy="0 0 0" xyz="0 0 0.1"/>
      <material name="white"/>
    </visual>
    <collision>
      <geometry>
        <box size="0.1 0.1 0.2"/>
      </geometry>
      <origin rpy="0 0 0" xyz="0 0 0.1"/>
    </collision>
    <inertial>
      <mass value="10"/>
      <inertia ixx="1.0" ixy="0.0" ixz="0.0" iyy="1.0" iyz="0.0" izz="1.0"/>
    </inertial>
  </link>
  <joint name="revolute_31" type="prismatic">
    <parent link="branch_30"/>
    <child link="branch_31"/>
    <origin rpy="0.060499 0.838602 -0.276396" xyz="0.042676 0.076659 0.417045"/>
    <axis xyz="0.405522 0.715567 0.857607"/>
    <limit effort="1000.0" lower="-0.548" upper="0.548" velocity="0.5"/>
  </joint>
  <link name="branch_32">
    <visual>
      <geometry>
        <box size="0.1 0.1 0.2"/>
      </geometry>
      <origin rpy="0 0 0" xyz="0 0 0.1"/>
      <material name="white"/>
    </visual>
    <collision>
      <geometry>
        <box size="0.1 0.1 0.2"/>
      </geometry>
      <origin rpy="0 0 0" xyz="0 0 0.1"/>
    </collision>
    <inertial>
      <mass value="10"/>
      <inertia ixx="1.0" ixy="0.0" ixz="0.0" iyy="1.0" iyz="0.0" izz="1.0"/>
    </inertial>
  </link>
  <joint name="revolute_32" type="revolute">
    <parent link="branch_31"/>
    <child link="branch_32"/>
    <origin rpy="-0.673494 0.191949 0.826432" xyz="0.019523 0.055823 0.493406"/>
    <axis xyz="-0.539773 0.190568 -0.658046"/>
    <limit effort="1000.0" lower="-0.548" upper="0.548" velocity="0.5"/>
  </joint>
  <link name="branch_33">
    <visual>
      <geometry>
        <box size="0.1 0.1 0.2"/>
      </geometry>
      <origin rpy="0 0 0" xyz="0 0 0.1"/>
      <material name="white"/>
    </visual>
    <collision>
      <geometry>
        <box size="0.1 0.1 0.2"/>
      </geometry>
      <origin rpy="0 0 0" xyz="0 0 0.1"/>
    </collision>
    <inertial>
      <mass value="10"/>
      <inertia ixx="1.0" ixy="0.0" ixz="0.0" iyy="1.0" iyz="0.0" izz="1.0"/>
    </inertial>
  </link>
  <joint name="revolute_33" type="revolute">
    <parent link="branch_32"/>
    <child link="branch_33"/>
    <origin rpy="-0.452412 -0.360693 0.865330" xyz="0.041288 0.071231 0.459751"/>
    <axis xyz="0.598133 -0.780570 -0.815203"/>
    <limit effort="1000.0" lower="-0.548" upper="0.548" velocity="0.5"/>
  </joint>
  <link name="branch_34">
    <visual>
      <geometry>
        <box size="0.1 0.1 0.2"/>
      </geometry>
      <origin rpy="0 0 0" xyz="0 0 0.1"/>
      <material name="white"/>
    </visual>
    <collision>
      <geometry>
        <box size="0.1 0.1 0.2"/>
      </geometry>
      <origin rpy="0 0 0" xyz="0 0 0.1"/>
    </collision>
    <inertial>
      <mass value="10"/>
      <inertia ixx="1.0" ixy="0.0" ixz="0.0" iyy="1.0" iyz="0.0" izz="1.0"/>
    </inertial>
  </link>
  <joint name="revolute_34" type="prismatic">
    <parent link="branch_33"/>
    <child link="branch_34"/>
    <origin rpy="0.680826 -0.678263 0.258071" xyz="0.060700 0.024609 0.431857"/>
    <axis xyz="-0.070427 -0.650204 0.172095"/>
    <limit effort="1000.0" lower="-0.548" upper="0.548" velocity="0.5"/>
  </joint>
  <link name="branch_35">
    <visual>
      <geometry>
        <box size="0.1 0.1 0.2"/>
      </geometry>
      <origin rpy="0 0 0" xyz="0 0 0.1"/>
      <material name="white"/>
    </visual>
    <collision>
      <geometry>
        <box size="0.1 0.1 0.2"/>
      </geometry>
      <origin rpy="0 0 0" xyz="0 0 0.1"/>
    </collision>
    <inertial>
      <mass value="10"/>
      <inertia ixx="1.0" ixy="0.0" ixz="0.0" iyy="1.0" iyz="0.0" izz="1.0"/>
    </inertial>
  </link>
  <joint name="revolute_35" type="prismatic">
    <parent link="branch_34"/>
    <child link="branch_35"/>
    <origin rpy="0.769567 -0.243995 0.110632" xyz="0.044301 0.084503 0.543714"/>
    <axis xyz="-0.923406 -0.967981 0.827601"/>
    <limit effort="1000.0" lower="-0.548" upper="0.548" velocity="0.5"/>
  </joint>
  <link name="branch_36">
    <visual>
      <geometry>
        <box size="0.1 0.1 0.2"/>
      </geometry>
      <origin rpy="0 0 0" xyz="0 0 0.1"/>
      <material name="white"/>
    </visual>
    <collision>
      <geometry>
        <box size="0.1 0.1 0.2"/>
      </geometry>
      <origin rpy="0 0 0" xyz="0 0 0.1"/>
    </collision>
    <inertial>
      <mass value="10"/>
      <inertia ixx="1.0" ixy="0.0" ixz="0.0" iyy="1.0" iyz="0.0" izz="1.0"/>
    </inertial>
  </link>
  <joint name="revolute_36" type="revolute">
    <parent link="branch_35"/>
    <child link="branch_36"/>
    <origin rpy="-0.072865 0.941924 -0.204796" xyz="0.017587 0.026972 0.534279"/>
    <axis xyz="-0.428820 -0.275771 -0.831444"/>
    <limit effort="1000.0" lower="-0.548" upper="0.548" velocity="0.5"/>
  </joint>
  <link name="branch_37">
    <visual>
      <geometry>
        <box size="0.1 0.1 0.2"/>
      </geometry>
      <origin rpy="0 0 0" xyz="0 0 0.1"/>
      <material name="white"/>
    </visual>
    <collision>
      <geometry>
        <box size="0.1 0.1 0.2"/>
      </geometry>
      <origin rpy="0 0 0" xyz="0 0 0.1"/>
    </collision>
    <inertial>
      <mass value="10"/>
      <inertia ixx="1.0" ixy="0.0" ixz="0.0" iyy="1.0" iyz="0.0" izz="1.0"/>
    </inertial>
  </link>
  <joint name="revolute_37" type="revolute">
    <parent link="branch_36"/>
    <child link="branch_37"/>
    <origin rpy="-0.911573 0.829250 -0.433547" xyz="0.029031 0.007391 0.424728"/>
    <axis xyz="-0.069587 0.319915 0.461285"/>
    <limit effort="1000.0" lower="-0.548" upper="0.548" velocity="0.5"/>
  </joint>
  <link name="branch_38">
    <visual>
      <geometry>
        <box size="0.1 0.1 0.2"/>
      </geometry>
      <origin rpy="0 0 0" xyz="0 0 0.1"/>
      <material name="white"/>
    </visual>
    <collision>
      <geometry>
        <box size="0.1 0.1 0.2"/>
      </geometry>
      <origin rpy="0 0 0" xyz="0 0 0.1"/>
    </collision>
    <inertial>
      <mass value="10"/>
      <inertia ixx="1.0" ixy="0.0" ixz="0.0" iyy="1.0" iyz="0.0" izz="1.0"/>
    </inertial>
  </link>
  <joint name="revolute_38" type="prismatic">
    <parent link="branch_37"/>
    <child link="branch_38"/>
    <origin rpy="0.146862 -0.958955 0.897532" xyz="0.041846 0.073909 0.566710"/>
    <axis xyz="-0.131055 0.305783 -0.446875"/>
    <limit effort="1000.0" lower="-0.548" upper="0.548" velocity="0.5"/>
  </joint>
  <link name="branch_39">
    <visual>
      <geometry>
        <box size="0.1 0.1 0.2"/>
      </geometry>
      <origin rpy="0 0 0" xyz="0 0 0.1"/>
      <material name="white"/>
    </visual>
    <collision>
      <geometry>
        <box size="0.1 0.1 0.2"/>
      </geometry>
      <origin rpy="0 0 0" xyz="0 0 0.1"/>
    </collision>
    <inertial>
      <mass value="10"/>
      <inertia ixx="1.0" ixy="0.0" ixz="0.0" iyy="1.0" iyz="0.0" izz="1.0"/>
    </inertial>
  </link>
  <joint name="revolute_39" type="revolute">
    <parent link="branch_38"/>
    <child link="branch_39"/>
    <origin rpy="-0.428356 0.664149 0.593611" xyz="0.055554 0.050347 0.452075"/>
    <axis xyz="0.835305 0.175497 -0.127504"/>
    <limit effort="1000.0" lower="-0.548" upper="0.548" velocity="0.5"/>
  </joint>
  <link name="branch_40">
    <visual>
      <geometry>
        <box size="0.1 0.1 0.2"/>
      </geometry>
      <origin rpy="0 0 0" xyz="0 0 0.1"/>
      <material name="white"/>
    </visual>
    <collision>
      <geometry>
        <box size="0.1 0.1 0.2"/>
      </geometry>
      <origin rpy="0 0 0" xyz="0 0 0.1"/>
    </collision>
    <inertial>
      <mass value="10"/>
      <inertia ixx="1.0" ixy="0.0" ixz="0.0" iyy="1.0" iyz="0.0" izz="1.0"/>
    </inertial>
  </link>
  <joint name="revolute_40" type="revolute">
    <parent link="branch_39"/>
    <child link="branch_40"/>
    <origin rpy="0.272926 -0.598242 -0.057813" xyz="0.071037 0.032452 0.503061"/>
    <axis xyz="-0.259339 -0.889679 0.611230"/>
    <limit effort="1000.0" lower="-0.548" upper="0.548" velocity="0.5"/>
  </joint>
  <link name="branch_41">
    <visual>
      <geometry>
        <box size="0.1 0.1 0.2"/>
      </geometry>
      <origin rpy="0 0 0" xyz="0 0 0.1"/>
      <material name="white"/>
    </visual>
    <collision>
      <geometry>
        <box size="0.1 0.1 0.2"/>
      </geometry>
      <origin rpy="0 0 0" xyz="0 0 0.1"/>
    </collision>
    <inertial>
      <mass value="10"/>
      <inertia ixx="1.0" ixy="0.0" ixz="0.0" iyy="1.0" iyz="0.0" izz="1.0"/>
    </inertial>
  </link>
  <joint name="revolute_41" type="prismatic">
    <parent link="branch_40"/>
    <child link="branch_41"/>
    <origin rpy="-0.417313 -0.361806 -0.498821" xyz="0.003043 0.015265 0.564804"/>
    <axis xyz="0.366652 -0.141582 -0.515033"/>
    <limit effort="1000.0" lower="-0.548" upper="0.548" velocity="0.5"/>
  </joint>
  <link name="branch_42">
    <visual>
      <geometry>
        <box size="0.1 0.1 0.2"/>
      </geometry>
      <origin rpy="0 0 0" xyz="0 0 0.1"/>
      <material name="white"/>
    </visual>
    <collision>
      <geometry>
        <box size="0.1 0.1 0.2"/>
      </geometry>
      <origin rpy="0 0 0" xyz="0 0 0.1"/>
    </collision>
    <inertial>
      <mass value="10"/>
      <inertia ixx="1.0" ixy="0.0" ixz="0.0" iyy="1.0" iyz="0.0" izz="1.0"/>
    </inertial>
  </link>
  <joint name="revolute_42" type="revolute">
    <parent link="branch_41"/>
    <child link="branch_42"/>
    <origin rpy="0.018061 -0.039737 0.488137" xyz="0.001250 0.074050 0.405978"/>
    <axis xyz="0.200499 -0.646496 0.170856"/>
    <limit effort="1000.0" lower="-0.548" upper="0.548" velocity="0.5"/>
  </joint>
  <link name="branch_43">
    <visual>
      <geometry>
        <box size="0.1 0.1 0.2"/>
      </geometry>
      <origin rpy="0 0 0" xyz="0 0 0.1"/>
      <material name="white"/>
    </visual>
    <collision>
      <geometry>
        <box size="0.1 0.1 0.2"/>
      </geometry>
      <origin rpy="0 0 0" xyz="0 0 0.1"/>
    </collision>
    <inertial>
      <mass value="10"/>
      <inertia ixx="1.0" ixy="0.0" ixz="0.0" iyy="1.0" iyz="0.0" izz="1.0"/>
    </inertial>
  </link>
  <joint name="revolute_43" type="revolute">
    <parent link="branch_42"/>
    <child link="branch_43"/>
    <origin rpy="0.407920 -0.857314 0.797180" xyz="0.002848 0.058665 0.507011"/>
    <axis xyz="-0.832722 -0.215471 -0.509148"/>
    <limit effort="1000.0" lower="-0.548" upper="0.548" velocity="0.5"/>
  </joint>
  <link name="branch_44">
    <visual>
      <geometry>
        <box size="0.1 0.1 0.2"/>
      </geometry>
      <origin rpy="0 0 0" xyz="0 0 0.1"/>
      <material name="white"/>
    </visual>
    <collision>
      <geometry>
        <box size="0.1 0.1 0.2"/>
      </geometry>
      <origin rpy="0 0 0" xyz="0 0 0.1"/>
    </collision>
    <inertial>
      <mass value="10"/>
      <inertia ixx="1.0" ixy="0.0" ixz="0.0" iyy="1.0" iyz="0.0" izz="1.0"/>
    </inertial>
  </link>
  <joint name="revolute_44" type="prismatic">
    <parent link="branch_43"/>
    <child link="branch_44"/>
    <origin rpy="0.869707 -0.331543 0.326171" xyz="0.008750 0.015825 0.590886"/>
    <axis xyz="0.033417 -0.198535 0.969727"/>
    <limit effort="1000.0" lower="-0.548" upper="0.548" velocity="0.5"/>
  </joint>
  <link name="branch_45">
    <visual>
      <geometry>
        <box size="0.1 0.1 0.2"/>
      </geometry>
      <origin rpy="0 0 0" xyz="0 0 0.1"/>
      <material name="white"/>
    </visual>
    <collision>
      <geometry>
        <box size="0.1 0.1 0.2"/>
      </geometry>
      <origin rpy="0 0 0" xyz="0 0 0.1"/>
    </collision>
    <inertial>
      <mass value="10"/>
      <inertia ixx="1.0" ixy="0.0" ixz="0.0" iyy="1.0" iyz="0.0" izz="1.0"/>
    </inertial>
  </link>
  <joint name="revolute_45" type="revolute">
    <parent link="branch_44"/>
    <child link="branch_45"/>
    <origin rpy="-0.703358 -0.478446 -0.844622" xyz="0.088883 0.029067 0.517344"/>
    <axis xyz="-0.868845 0.752190 0.198441"/>
    <limit effort="1000.0" lower="-0.548" upper="0.548" velocity="0.5"/>
  </joint>
  <link name="branch_46">
    <visual>
      <geometry>
        <box size="0.1 0.1 0.2"/>
      </geometry>
      <origin rpy="0 0 0" xyz="0 0 0.1"/>
      <material name="white"/>
    </visual>
    <collision>
      <geometry>
        <box size="0.1 0.1 0.2"/>
      </geometry>
      <origin rpy="0 0 0" xyz="0 0 0.1"/>
    </collision>
    <inertial>
      <mass value="10"/>
      <inertia ixx="1.0" ixy="0.0" ixz="0.0" iyy="1.0" iyz="0.0" izz="1.0"/>
    </inertial>
  </link>
  <joint name="revolute_46" type="prismatic">
    <parent link="branch_45"/>
    <child link="branch_46"/>
    <origin rpy="-0.458374 0.928335 -0.241648" xyz="0.085746 0.049922 0.416627"/>
    <axis xyz="-0.500546 0.489292 -0.776772"/>
    <limit effort="1000.0" lower="-0.548" upper="0.548" velocity="0.5"/>
  </joint>
  <link name="branch_47">
    <visual>
      <geometry>
        <box size="0.1 0.1 0.2"/>
      </geometry>
      <origin rpy="0 0 0" xyz="0 0 0.1"/>
      <material name="white"/>
    </visual>
    <collision>
      <geometry>
        <box size="0.1 0.1 0.2"/>
      </geometry>
      <origin rpy="0 0 0" xyz="0 0 0.1"/>
    </collision>
    <inertial>
      <mass value="10"/>
      <inertia ixx="1.0" ixy="0.0" ixz="0.0" iyy="1.0" iyz="0.0" izz="1.0"/>
    </inertial>
  </link>
  <joint name="revolute_47" type="revolute">
    <parent link="branch_46"/>
    <child link="branch_47"/>
    <origin rpy="0.058963 0.825625 -0.279195" xyz="0.068773 0.086724 0.459051"/>
    <axis xyz="-0.823074 0.704209 -0.234489"/>
    <limit effort="1000.0" lower="-0.548" upper="0.548" velocity="0.5"/>
  </joint>
  <link name="branch_48">
    <visual>
      <geometry>
        <box size="0.1 0.1 0.2"/>
      </geometry>
      <origin rpy="0 0 0" xyz="0 0 0.1"/>
      <material name="white"/>
    </visual>
    <collision>
      <geometry>
        <box size="0.1 0.1 0.2"/>
      </geometry>
      <origin rpy="0 0 0" xyz="0 0 0.1"/>
    </collision>
    <inertial>
      <mass value="10"/>
      <inertia ixx="1.0" ixy="0.0" ixz="0.0" iyy="1.0" iyz="0.0" izz="1.0"/>
    </inertial>
  </link>
  <joint name="revolute_48" type="revolute">
    <parent link="branch_47"/>
    <child link="branch_48"/>
    <origin rpy="-0.679519 -0.667696 0.040588" xyz="0.045091 0.075287 0.533723"/>
    <axis xyz="-0.345994 -0.295817 0.114880"/>
    <limit effort="1000.0" lower="-0.548" upper="0.548" velocity="0.5"/>
  </joint>
  <link name="branch_49">
    <visual>
      <geometry>
        <box size="0.1 0.1 0.2"/>
      </geometry>
      <origin rpy="0 0 0" xyz="0 0 0.1"/>
      <material name="white"/>
    </visual>
    <collision>
      <geometry>
        <box size="0.1 0.1 0.2"/>
      </geometry>
      <origin rpy="0 0 0" xyz="0 0 0.1"/>
    </collision>
    <inertial>
      <mass value="10"/>
      <inertia ixx="1.0" ixy="0.0" ixz="0.0" iyy="1.0" iyz="0.0" izz="1.0"/>
    </inertial>
  </link>
  <joint name="revolute_49" type="revolute">
    <parent link="branch_48"/>
    <child link="branch_49"/>
    <origin rpy="0.174370 0.412358 0.103123" xyz="0.008641 0.078931 0.564475"/>
    <axis xyz="0.662103 0.801858 0.359673"/>
    <limit effort="1000.0" lower="-0.548" upper="0.548" velocity="0.5"/>
  </joint>
  <link name="branch_50">
    <visual>
      <geometry>
        <box size="0.1 0.1 0.2"/>
      </geometry>
      <origin rpy="0 0 0" xyz="0 0 0.1"/>
      <material name="white"/>
    </visual>
    <collision>
      <geometry>
        <box size="0.1 0.1 0.2"/>
      </geometry>
      <origin rpy="0 0 0" xyz="0 0 0.1"/>
    </collision>
    <inertial>
      <mass value="10"/>
      <inertia ixx="1.0" ixy="0.0" ixz="0.0" iyy="1.0" iyz="0.0" izz="1.0"/>
    </inertial>
  </link>
  <joint name="revolute_50" type="revolute">
    <parent link="branch_49"/>
    <child link="branch_50"/>
    <origin rpy="0.684752 -0.617092 -0.807636" xyz="0.070962 0.048671 0.525133"/>
    <axis xyz="0.123444 0.738931 -0.373213"/>
    <limit effort="1000.0" lower="-0.548" upper="0.548" velocity="0.5"/>
  </joint>
  <link name="branch_51">
    <visual>
      <geometry>
        <box size="0.1 0.1 0.2"/>
      </geometry>
      <origin rpy="0 0 0" xyz="0 0 0.1"/>
      <material name="white"/>
    </visual>
    <collision>
      <geometry>
        <box size="0.1 0.1 0.2"/>
      </geometry>
      <origin rpy="0 0 0" xyz="0 0 0.1"/>
    </collision>
    <inertial>
      <mass value="10"/>
      <inertia ixx="1.0" ixy="0.0" ixz="0.0" iyy="1.0" iyz="0.0" izz="1.0"/>
    </inertial>
  </link>
  <joint name="revolute_51" type="revolute">
    <parent link="branch_50"/>
    <child link="branch_51"/>
    <origin rpy="0.136017 -0.835968 0.537858" xyz="0.032088 0.075063 0.585834"/>
    <axis xyz="0.345943 -0.383858 -0.239845"/>
    <limit effort="1000.0" lower="-0.548" upper="0.548" velocity="0.5"/>
  </joint>
  <link name="branch_52">
    <visual>
      <geometry>
        <box size="0.1 0.1 0.2"/>
      </geometry>
      <origin rpy="0 0 0" xyz="0 0 0.1"/>
      <material name="white"/>
    </visual>
    <collision>
      <geometry>
        <box size="0.1 0.1 0.2"/>
      </geometry>
      <origin rpy="0 0 0" xyz="0 0 0.1"/>
    </collision>
    <inertial>
      <mass value="10"/>
      <inertia ixx="1.0" ixy="0.0" ixz="0.0" iyy="1.0" iyz="0.0" izz="1.0"/>
    </inertial>
  </link>
  <joint name="revolute_52" type="revolute">
    <parent link="branch_51"/>
    <child link="branch_52"/>
    <origin rpy="-0.173482 -0.550934 0.862177" xyz="0.020257 0.004691 0.503655"/>
    <axis xyz="-0.792995 0.453488 0.209358"/>
    <limit effort="1000.0" lower="-0.548" upper="0.548" velocity="0.5"/>
  </joint>
  <link name="branch_53">
    <visual>
      <geometry>
        <box size="0.1 0.1 0.2"/>
      </geometry>
      <origin rpy="0 0 0" xyz="0 0 0.1"/>
      <material name="white"/>
    </visual>
    <collision>
      <geometry>
        <box size="0.1 0.1 0.2"/>
      </geometry>
      <origin rpy="0 0 0" xyz="0 0 0.1"/>
    </collision>
    <inertial>
      <mass value="10"/>
      <inertia ixx="1.0" ixy="0.0" ixz="0.0" iyy="1.0" iyz="0.0" izz="1.0"/>
    </inertial>
  </link>
  <joint name="revolute_53" type="revolute">
    <parent link="branch_52"/>
    <child link="branch_53"/>
    <origin rpy="0.254370 -0.600632 0.312615" xyz="0.011389 0.082535 0.499737"/>
    <axis xyz="0.966721 -0.722518 -0.583399"/>
    <limit effort="1000.0" lower="-0.548" upper="0.548" velocity="0.5"/>
  </joint>
  <link name="branch_54">
    <visual>
      <geometry>
        <box size="0.1 0.1 0.2"/>
      </geometry>
      <origin rpy="0 0 0" xyz="0 0 0.1"/>
      <material name="white"/>
    </visual>
    <collision>
      <geometry>
        <box size="0.1 0.1 0.2"/>
      </geometry>
      <origin rpy="0 0 0" xyz="0 0 0.1"/>
    </collision>
    <inertial>
      <mass value="10"/>
      <inertia ixx="1.0" ixy="0.0" ixz="0.0" iyy="1.0" iyz="0.0" izz="1.0"/>
    </inertial>
  </link>
  <joint name="revolute_54" type="revolute">
    <parent link="branch_53"/>
    <child link="branch_54"/>
    <origin rpy="0.704077 0.504579 0.081196" xyz="0.060267 0.068146 0.421721"/>
    <axis xyz="0.821481 -0.876927 -0.141028"/>
    <limit effort="1000.0" lower="-0.548" upper="0.548" velocity="0.5"/>
  </joint>
  <link name="branch_55">
    <visual>
      <geometry>
        <box size="0.1 0.1 0.2"/>
      </geometry>
      <origin rpy="0 0 0" xyz="0 0 0.1"/>
      <material name="white"/>
    </visual>
    <collision>
      <geometry>
        <box size="0.1 0.1 0.2"/>
      </geometry>
      <origin rpy="0 0 0" xyz="0 0 0.1"/>
    </collision>
    <inertial>
      <mass value="10"/>
      <inertia ixx="1.0" ixy="0.0" ixz="0.0" iyy="1.0" iyz="0.0" izz="1.0"/>
    </inertial>
  </link>
  <joint name="revolute_55" type="revolute">
    <parent link="branch_54"/>
    <child link="branch_55"/>
    <origin rpy="-0.346019 0.683658 0.537234" xyz="0.037390 0.036010 0.436375"/>
    <axis xyz="-0.798717 0.929564 -0.231102"/>
    <limit effort="1000.0" lower="-0.548" upper="0.548" velocity="0.5"/>
  </joint>
  <link name="branch_56">
    <visual>
      <geometry>
        <box size="0.1 0.1 0.2"/>
      </geometry>
      <origin rpy="0 0 0" xyz="0 0 0.1"/>
      <material name="white"/>
    </visual>
    <collision>
      <geometry>
        <box size="0.1 0.1 0.2"/>
      </geometry>
      <origin rpy="0 0 0" xyz="0 0 0.1"/>
    </collision>
    <inertial>
      <mass value="10"/>
      <inertia ixx="1.0" ixy="0.0" ixz="0.0" iyy="1.0" iyz="0.0" izz="1.0"/>
    </inertial>
  </link>
  <joint name="revolute_56" type="revolute">
    <parent link="branch_55"/>
    <child link="branch_56"/>
    <origin rpy="0.375271 0.513898 -0.198975" xyz="0.051298 0.025563 0.405539"/>
    <axis xyz="0.303449 -0.072134 -0.716815"/>
    <limit effort="1000.0" lower="-0.548" upper="0.548" velocity="0.5"/>
  </joint>
  <link name="branch_57">
    <visual>
      <geometry>
        <box size="0.1 0.1 0.2"/>
      </geometry>
      <origin rpy="0 0 0" xyz="0 0 0.1"/>
      <material name="white"/>
    </visual>
    <collision>
      <geometry>
        <box size="0.1 0.1 0.2"/>
      </geometry>
      <origin rpy="0 0 0" xyz="0 0 0.1"/>
    </collision>
    <inertial>
      <mass value="10"/>
      <inertia ixx="1.0" ixy="0.0" ixz="0.0" iyy="1.0" iyz="0.0" izz="1.0"/>
    </inertial>
  </link>
  <joint name="revolute_57" type="revolute">
    <parent link="branch_56"/>
    <child link="branch_57"/>
    <origin rpy="0.754485 -0.615355 -0.532089" xyz="0.055870 0.030093 0.417199"/>
    <axis xyz="0.240477 0.460830 0.377326"/>
    <limit effort="1000.0" lower="-0.548" upper="0.548" velocity="0.5"/>
  </joint>
  <link name="branch_58">
    <visual>
      <geometry>
        <box size="0.1 0.1 0.2"/>
      </geometry>
      <origin rpy="0 0 0" xyz="0 0 0.1"/>
      <material name="white"/>
    </visual>
    <collision>
      <geometry>
        <box size="0.1 0.1 0.2"/>
      </geometry>
      <origin rpy="0 0 0" xyz="0 0 0.1"/>
    </collision>
    <inertial>
      <mass value="10"/>
      <inertia ixx="1.0" ixy="0.0" ixz="0.0" iyy="1.0" iyz="0.0" izz="1.0"/>
    </inertial>
  </link>
  <joint name="revolute_58" type="prismatic">
    <parent link="branch_57"/>
    <child link="branch_58"/>
    <origin rpy="-0.117535 -0.222290 0.665745" xyz="0.080134 0.057073 0.431973"/>
    <axis xyz="0.532234 0.910360 0.067520"/>
    <limit effort="1000.0" lower="-0.548" upper="0.548" velocity="0.5"/>
  </joint>
  <link name="branch_59">
    <visual>
      <geometry>
        <box size="0.1 0.1 0.2"/>
      </geometry>
      <origin rpy="0 0 0" xyz="0 0 0.1"/>
      <material name="white"/>
    </visual>
    <collision>
      <geometry>
        <box size="0.1 0.1 0.2"/>
      </geometry>
      <origin rpy="0 0 0" xyz="0 0 0.1"/>
    </collision>
    <inertial>
      <mass value="10"/>
      <inertia ixx="1.0" ixy="0.0" ixz="0.0" iyy="1.0" iyz="0.0" izz="1.0"/>
    </inertial>
  </link>
  <joint name="revolute_59" type="prismatic">
    <parent link="branch_58"/>
    <child link="branch_59"/>
    <origin rpy="-0.217299 -0.666741 -0.113737" xyz="0.064698 0.019433 0.426153"/>
    <axis xyz="-0.778169 -0.328162 0.287501"/>
    <limit effort="1000.0" lower="-0.548" upper="0.548" velocity="0.5"/>
  </joint>
  <link name="branch_60">
    <visual>
      <geometry>
        <box size="0.1 0.1 0.2"/>
      </geometry>
      <origin rpy="0 0 0" xyz="0 0 0.1"/>
      <material name="white"/>
    </visual>
    <collision>
      <geometry>
        <box size="0.1 0.1 0.2"/>
      </geometry>
      <origin rpy="0 0 0" xyz="0 0 0.1"/>
    </collision>
    <inertial>
      <mass value="10"/>
      <inertia ixx="1.0" ixy="0.0" ixz="0.0" iyy="1.0" iyz="0.0" izz="1.0"/>
    </inertial>
  </link>
  <joint name="revolute_60" type="revolute">
    <parent link="branch_59"/>
    <child link="branch_60"/>
    <origin rpy="-0.024405 -0.310259 -0.078256" xyz="0.078873 0.043086 0.467623"/>
    <axis xyz="0.038282 -0.760945 0.793632"/>
    <limit effort="1000.0" lower="-0.548" upper="0.548" velocity="0.5"/>
  </joint>
  <link name="branch_61">
    <visual>
      <geometry>
        <box size="0.1 0.1 0.2"/>
      </geometry>
      <origin rpy="0 0 0" xyz="0 0 0.1"/>
      <material name="white"/>
    </visual>
    <collision>
      <geometry>
        <box size="0.1 0.1 0.2"/>
      </geometry>
      <origin rpy="0 0 0" xyz="0 0 0.1"/>
    </collision>
    <inertial>
      <mass value="10"/>
      <inertia ixx="1.0" ixy="0.0" ixz="0.0" iyy="1.0" iyz="0.0" izz="1.0"/>
    </inertial>
  </link>
  <joint name="revolute_61" type="revolute">
    <parent link="branch_60"/>
    <child link="branch_61"/>
    <origin rpy="0.811819 -0.295974 0.437862" xyz="0.047664 0.051188 0.432033"/>
    <axis xyz="-0.136359 -0.908728 0.922996"/>
    <limit effort="1000.0" lower="-0.548" upper="0.548" velocity="0.5"/>
  </joint>
  <link name="branch_62">
    <visual>
      <geometry>
        <box size="0.1 0.1 0.2"/>
      </geometry>
      <origin rpy="0 0 0" xyz="0 0 0.1"/>
      <material name="white"/>
    </visual>
    <collision>
      <geometry>
        <box size="0.1 0.1 0.2"/>
      </geometry>
      <origin rpy="0 0 0" xyz="0 0 0.1"/>
    </collision>
    <inertial>
      <mass value="10"/>
      <inertia ixx="1.0" ixy="0.0" ixz="0.0" iyy="1.0" iyz="0.0" izz="1.0"/>
    </inertial>
  </link>
  <joint name="revolute_62" type="revolute">
    <parent link="branch_61"/>
    <child link="branch_62"/>
    <origin rpy="0.788489 0.749904 0.360075" xyz="0.008857 0.000572 0.414278"/>
    <axis xyz="-0.151018 0.298940 0.436740"/>
    <limit effort="1000.0" lower="-0.548" upper="0.548" velocity="0.5"/>
  </joint>
  <link name="branch_63">
    <visual>
      <geometry>
        <box size="0.1 0.1 0.2"/>
      </geometry>
      <origin rpy="0 0 0" xyz="0 0 0.1"/>
      <material name="white"/>
    </visual>
    <collision>
      <geometry>
        <box size="0.1 0.1 0.2"/>
      </geometry>
      <origin rpy="0 0 0" xyz="0 0 0.1"/>
    </collision>
    <inertial>
      <mass value="10"/>
      <inertia ixx="1.0" ixy="0.0" ixz="0.0" iyy="1.0" iyz="0.0" izz="1.0"/>
    </inertial>
  </link>
  <joint name="revolute_63" type="revolute">
    <parent link="branch_62"/>
    <child link="branch_63"/>
    <origin rpy="-0.651688 0.770725 0.889890" xyz="0.060502 0.022348 0.486548"/>
    <axis xyz="0.449096 -0.759414 -0.557064"/>
    <limit effort="1000.0" lower="-0.548" upper="0.548" velocity="0.5"/>
  </joint>
  <link name="branch_64">
    <visual>
      <geometry>
        <box size="0.1 0.1 0.2"/>
      </geometry>
      <origin rpy="0 0 0" xyz="0 0 0.1"/>
      <material name="white"/>
    </visual>
    <collision>
      <geometry>
        <box size="0.1 0.1 0.2"/>
      </geometry>
      <origin rpy="0 0 0" xyz="0 0 0.1"/>
    </collision>
    <inertial>
      <mass value="10"/>
      <inertia ixx="1.0" ixy="0.0" ixz="0.0" iyy="1.0" iyz="0.0" izz="1.0"/>
    </inertial>
  </link>
  <joint name="revolute_64" type="prismatic">
    <parent link="branch_63"/>
    <child link="branch_64"/>
    <origin rpy="-0.814756 -0.113042 0.274694" xyz="0.060450 0.060364 0.508651"/>
    <axis xyz="0.300267 0.130281 -0.960206"/>
    <limit effort="1000.0" lower="-0.548" upper="0.548" velocity="0.5"/>
  </joint>
  <link name="branch_65">
    <visual>
      <geometry>
        <box size="0.1 0.1 0.2"/>
      </geometry>
      <origin rpy="0 0 0" xyz="0 0 0.1"/>
      <material name="white"/>
    </visual>
    <collision>
      <geometry>
        <box size="0.1 0.1 0.2"/>
      </geometry>
      <origin rpy="0 0 0" xyz="0 0 0.1"/>
    </collision>
    <inertial>
      <mass value="10"/>
      <inertia ixx="1.0" ixy="0.0" ixz="0.0" iyy="1.0" iyz="0.0" izz="1.0"/>
    </inertial>
  </link>
  <joint name="revolute_65" type="revolute">
    <parent link="branch_64"/>
    <child link="branch_65"/>
    <origin rpy="-0.346660 -0.339658 -0.414489" xyz="0.033239 0.040156 0.437400"/>
    <axis xyz="0.963718 -0.760143 -0.448856"/>
    <limit effort="1000.0" lower="-0.548" upper="0.548" velocity="0.5"/>
  </joint>
  <link name="branch_66">
    <visual>
      <geometry>
        <box size="0.1 0.1 0.2"/>
      </geometry>
      <origin rpy="0 0 0" xyz="0 0 0.1"/>
      <material name="white"/>
    </visual>
    <collision>
      <geometry>
        <box size="0.1 0.1 0.2"/>
      </geometry>
      <origin rpy="0 0 0" xyz="0 0 0.1"/>
    </collision>
    <inertial>
      <mass value="10"/>
      <inertia ixx="1.0" ixy="0.0" ixz="0.0" iyy="1.0" iyz="0.0" izz="1.0"/>
    </inertial>
  </link>
  <joint name="revolute_66" type="revolute">
    <parent link="branch_65"/>
    <child link="branch_66"/>
    <origin rpy="0.170851 0.853608 0.898428" xyz="0.080890 0.035955 0.424674"/>
    <axis xyz="0.858391 0.162028 0.456782"/>
    <limit effort="1000.0" lower="-0.548" upper="0.548" velocity="0.5"/>
  </joint>
  <link name="branch_67">
    <visual>
      <geometry>
        <box size="0.1 0.1 0.2"/>
      </geometry>
      <origin rpy="0 0 0" xyz="0 0 0.1"/>
      <material name="white"/>
    </visual>
    <collision>
      <geometry>
        <box size="0.1 0.1 0.2"/>
      </geometry>
      <origin rpy="0 0 0" xyz="0 0 0.1"/>
    </collision>
    <inertial>
      <mass value="10"/>
      <inertia ixx="1.0" ixy="0.0" ixz="0.0" iyy="1.0" iyz="0.0" izz="1.0"/>
    </inertial>
  </link>
  <joint name="revolute_67" type="revolute">
    <parent link="branch_66"/>
    <child link="branch_67"/>
    <origin rpy="0.792837 0.133085 -0.356754" xyz="0.050006 0.010980 0.482849"/>
    <axis xyz="-0.869598 -0.740607 -0.962514"/>
    <limit effort="1000.0" lower="-0.548" upper="0.548" velocity="0.5"/>
  </joint>
  <link name="branch_68">
    <visual>
      <geometry>
        <box size="0.1 0.1 0.2"/>
      </geometry>
      <origin rpy="0 0 0" xyz="0 0 0.1"/>
      <material name="white"/>
    </visual>
    <collision>
      <geometry>
        <box size="0.1 0.1 0.2"/>
      </geometry>
      <origin rpy="0 0 0" xyz="0 0 0.1"/>
    </collision>
    <inertial>
      <mass value="10"/>
      <inertia ixx="1.0" ixy="0.0" ixz="0.0" iyy="1.0" iyz="0.0" izz="1.0"/>
    </inertial>
  </link>
  <joint name="revolute_68" type="revolute">
    <parent link="branch_67"/>
    <child link="branch_68"/>
    <origin rpy="0.998095 -0.284087 0.162828" xyz="0.040061 0.054496 0.581617"/>
    <axis xyz="0.041069 0.641058 -0.519054"/>
    <limit effort="1000.0" lower="-0.548" upper="0.548" velocity="0.5"/>
  </joint>
  <link name="branch_69">
    <visual>
      <geometry>
        <box size="0.1 0.1 0.2"/>
      </geometry>
      <origin rpy="0 0 0" xyz="0 0 0.1"/>
      <material name="white"/>
    </visual>
    <collision>
      <geometry>
        <box size="0.1 0.1 0.2"/>
      </geometry>
      <origin rpy="0 0 0" xyz="0 0 0.1"/>
    </collision>
    <inertial>
      <mass value="10"/>
      <inertia ixx="1.0" ixy="0.0" ixz="0.0" iyy="1.0" iyz="0.0" izz="1.0"/>
    </inertial>
  </link>
  <joint name="revolute_69" type="revolute">
    <parent link="branch_68"/>
    <child link="branch_69"/>
    <origin rpy="-0.701728 -0.060503 0.041183" xyz="0.050868 0.059312 0.421203"/>
    <axis xyz="-0.820608 -0.356980 0.829840"/>
    <limit effort="1000.0" lower="-0.548" upper="0.548" velocity="0.5"/>
  </joint>
  <link name="branch_70">
    <visual>
      <geometry>
        <box size="0.1 0.1 0.2"/>
      </geometry>
      <origin rpy="0 0 0" xyz="0 0 0.1"/>
      <material name="white"/>
    </visual>
    <collision>
      <geometry>
        <box size="0.1 0.1 0.2"/>
      </geometry>
      <origin rpy="0 0 0" xyz="0 0 0.1"/>
    </collision>
    <inertial>
      <mass value="10"/>
      <inertia ixx="1.0" ixy="0.0" ixz="0.0" iyy="1.0" iyz="0.0" izz="1.0"/>
    </inertial>
  </link>
  <joint name="revolute_70" type="revolute">
    <parent link="branch_69"/>
    <child link="branch_70"/>
    <origin rpy="-0.178685 -0.177362 0.548898" xyz="0.052046 0.082556 0.534174"/>
    <axis xyz="0.300306 0.688614 -0.658144"/>
    <limit effort="1000.0" lower="-0.548" upper="0.548" velocity="0.5"/>
  </joint>
  <link name="branch_71">
    <visual>
      <geometry>
        <box size="0.1 0.1 0.2"/>
      </geometry>
      <origin rpy="0 0 0" xyz="0 0 0.1"/>
      <material name="white"/>
    </visual>
    <collision>
      <geometry>
        <box size="0.1 0.1 0.2"/>
      </geometry>
      <origin rpy="0 0 0" xyz="0 0 0.1"/>
    </collision>
    <inertial>
      <mass value="10"/>
      <inertia ixx="1.0" ixy="0.0" ixz="0.0" iyy="1.0" iyz="0.0" izz="1.0"/>
    </inertial>
  </link>
  <joint name="revolute_71" type="revolute">
    <parent link="branch_70"/>
    <child link="branch_71"/>
    <origin rpy="0.188171 -0.536866 0.026367" xyz="0.013904 0.013965 0.502446"/>
    <axis xyz="0.919143 -0.239752 0.825674"/>
    <limit effort="1000.0" lower="-0.548" upper="0.548" velocity="0.5"/>
  </joint>
  <link name="branch_72">
    <visual>
      <geometry>
        <box size="0.1 0.1 0.2"/>
      </geometry>
      <origin rpy="0 0 0" xyz="0 0 0.1"/>
      <material name="white"/>
    </visual>
    <collision>
      <geometry>
        <box size="0.1 0.1 0.2"/>
      </geometry>
      <origin rpy="0 0 0" xyz="0 0 0.1"/>
    </collision>
    <inertial>
      <mass value="10"/>
      <inertia ixx="1.0" ixy="0.0" ixz="0.0" iyy="1.0" iyz="0.0" izz="1.0"/>
    </inertial>
  </link>
  <joint name="revolute_72" type="revolute">
    <parent link="branch_71"/>
    <child link="branch_72"/>
    <origin rpy="0.806239 -0.039674 0.204913" xyz="0.049624 0.058618 0.550318"/>
    <axis xyz="0.635497 0.002200 -0.479451"/>
    <limit effort="1000.0" lower="-0.548" upper="0.548" velocity="0.5"/>
  </joint>
  <link name="branch_73">
    <visual>
      <geometry>
        <box size="0.1 0.1 0.2"/>
      </geometry>
      <origin rpy="0 0 0" xyz="0 0 0.1"/>
      <material name="white"/>
    </visual>
    <collision>
      <geometry>
        <box size="0.1 0.1 0.2"/>
      </geometry>
      <origin rpy="0 0 0" xyz="0 0 0.1"/>
    </collision>
    <inertial>
      <mass value="10"/>
      <inertia ixx="1.0" ixy="0.0" ixz="0.0" iyy="1.0" iyz="0.0" izz="1.0"/>
    </inertial>
  </link>
  <joint name="revolute_73" type="revolute">
    <parent link="branch_72"/>
    <child link="branch_73"/>
    <origin rpy="0.522579 0.184395 -0.309569" xyz="0.058685 0.026307 0.551175"/>
    <axis xyz="-0.137678 -0.132013 -0.447340"/>
    <limit effort="1000.0" lower="-0.548" upper="0.548" velocity="0.5"/>
  </joint>
  <link name="branch_74">
    <visual>
      <geometry>
        <box size="0.1 0.1 0.2"/>
      </geometry>
      <origin rpy="0 0 0" xyz="0 0 0.1"/>
      <material name="white"/>
    </visual>
    <collision>
      <geometry>
        <box size="0.1 0.1 0.2"/>
      </geometry>
      <origin rpy="0 0 0" xyz="0 0 0.1"/>
    </collision>
    <inertial>
      <mass value="10"/>
      <inertia ixx="1.0" ixy="0.0" ixz="0.0" iyy="1.0" iyz="0.0" izz="1.0"/>
    </inertial>
  </link>
  <joint name="revolute_74" type="prismatic">
    <parent link="branch_73"/>
    <child link="branch_74"/>
    <origin rpy="-0.683900 0.888690 0.340245" xyz="0.029770 0.045658 0.452842"/>
    <axis xyz="0.355651 -0.261174 -0.193499"/>
    <limit effort="1000.0" lower="-0.548" upper="0.548" velocity="0.5"/>
  </joint>
  <link name="branch_75">
    <visual>
      <geometry>
        <box size="0.1 0.1 0.2"/>
      </geometry>
      <origin rpy="0 0 0" xyz="0 0 0.1"/>
      <material name="white"/>
    </visual>
    <collision>
      <geometry>
        <box size="0.1 0.1 0.2"/>
      </geometry>
      <origin rpy="0 0 0" xyz="0 0 0.1"/>
    </collision>
    <inertial>
      <mass value="10"/>
      <inertia ixx="1.0" ixy="0.0" ixz="0.0" iyy="1.0" iyz="0.0" izz="1.0"/>
    </inertial>
  </link>
  <joint name="revolute_75" type="revolute">
    <parent link="branch_74"/>
    <child link="branch_75"/>
    <origin rpy="0.685969 -0.439437 0.605568" xyz="0.042917 0.003187 0.541181"/>
    <axis xyz="0.860531 -0.415703 -0.595715"/>
    <limit effort="1000.0" lower="-0.548" upper="0.548" velocity="0.5"/>
  </joint>
  <link name="branch_76">
    <visual>
      <geometry>
        <box size="0.1 0.1 0.2"/>
      </geometry>
      <origin rpy="0 0 0" xyz="0 0 0.1"/>
      <material name="white"/>
    </visual>
    <collision>
      <geometry>
        <box size="0.1 0.1 0.2"/>
      </geometry>
      <origin rpy="0 0 0" xyz="0 0 0.1"/>
    </collision>
    <inertial>
      <mass value="10"/>
      <inertia ixx="1.0" ixy="0.0" ixz="0.0" iyy="1.0" iyz="0.0" izz="1.0"/>
    </inertial>
  </link>
  <joint name="revolute_76" type="revolute">
    <parent link="branch_75"/>
    <child link="branch_76"/>
    <origin rpy="0.224177 -0.449038 0.284238" xyz="0.087515 0.003135 0.480682"/>
    <axis xyz="-0.381707 -0.384633 0.980525"/>
    <limit effort="1000.0" lower="-0.548" upper="0.548" velocity="0.5"/>
  </joint>
  <link name="branch_77">
    <visual>
      <geometry>
        <box size="0.1 0.1 0.2"/>
      </geometry>
      <origin rpy="0 0 0" xyz="0 0 0.1"/>
      <material name="white"/>
    </visual>
    <collision>
      <geometry>
        <box size="0.1 0.1 0.2"/>
      </geometry>
      <origin rpy="0 0 0" xyz="0 0 0.1"/>
    </collision>
    <inertial>
      <mass value="10"/>
      <inertia ixx="1.0" ixy="0.0" ixz="0.0" iyy="1.0" iyz="0.0" izz="1.0"/>
    </inertial>
  </link>
  <joint name="revolute_77" type="revolute">
    <parent link="branch_76"/>
    <child link="branch_77"/>
    <origin rpy="-0.268463 0.958538 -0.531667" xyz="0.082234 0.024348 0.478443"/>
    <axis xyz="-0.616485 0.293454 0.379836"/>
    <limit effort="1000.0" lower="-0.548" upper="0.548" velocity="0.5"/>
  </joint>
  <link name="branch_78">
    <visual>
      <geometry>
        <box size="0.1 0.1 0.2"/>
      </geometry>
      <origin rpy="0 0 0" xyz="0 0 0.1"/>
      <material name="white"/>
    </visual>
    <collision>
      <geometry>
        <box size="0.1 0.1 0.2"/>
      </geometry>
      <origin rpy="0 0 0" xyz="0 0 0.1"/>
    </collision>
    <inertial>
      <mass value="10"/>
      <inertia ixx="1.0" ixy="0.0" ixz="0.0" iyy="1.0" iyz="0.0" izz="1.0"/>
    </inertial>
  </link>
  <joint name="revolute_78" type="revolute">
    <parent link="branch_77"/>
    <child link="branch_78"/>
    <origin rpy="0.296050 0.989084 -0.980902" xyz="0.067990 0.070045 0.570507"/>
    <axis xyz="0.944095 0.805176 -0.436602"/>
    <limit effort="1000.0" lower="-0.548" upper="0.548" velocity="0.5"/>
  </joint>
  <link name="branch_79">
    <visual>
      <geometry>
        <box size="0.1 0.1 0.2"/>
      </geometry>
      <origin rpy="0 0 0" xyz="0 0 0.1"/>
      <material name="white"/>
    </visual>
    <collision>
      <geometry>
        <box size="0.1 0.1 0.2"/>
      </geometry>
      <origin rpy="0 0 0" xyz="0 0 0.1"/>
    </collision>
    <inertial>
      <mass value="10"/>
      <inertia ixx="1.0" ixy="0.0" ixz="0.0" iyy="1.0" iyz="0.0" izz="1.0"/>
    </inertial>
  </link>
  <joint name="revolute_79" type="revolute">
    <parent link="branch_78"/>
    <child link="branch_79"/>
    <origin rpy="-0.025110 0.228332 0.844958" xyz="0.051880 0.001757 0.506913"/>
    <axis xyz="0.652965 -0.984326 -0.180559"/>
    <limit effort="1000.0" lower="-0.548" upper="0.548" velocity="0.5"/>
  </joint>
  <link name="branch_80">
    <visual>
      <geometry>
        <box size="0.1 0.1 0.2"/>
      </geometry>
      <origin rpy="0 0 0" xyz="0 0 0.1"/>
      <material name="white"/>
    </visual>
    <collision>
      <geometry>
        <box size="0.1 0.1 0.2"/>
      </geometry>
      <origin rpy="0 0 0" xyz="0 0 0.1"/>
    </collision>
    <inertial>
      <mass value="10"/>
      <inertia ixx="1.0" ixy="0.0" ixz="0.0" iyy="1.0" iyz="0.0" izz="1.0"/>
    </inertial>
  </link>
  <joint name="revolute_80" type="revolute">
    <parent link="branch_79"/>
    <child link="branch_80"/>
    <origin rpy="0.396272 -0.878702 -0.141479" xyz="0.094161 0.045287 0.559006"/>
    <axis xyz="0.176680 -0.714433 0.234747"/>
    <limit effort="1000.0" lower="-0.548" upper="0.548" velocity="0.5"/>
  </joint>
  <link name="branch_81">
    <visual>
      <geometry>
        <box size="0.1 0.1 0.2"/>
      </geometry>
      <origin rpy="0 0 0" xyz="0 0 0.1"/>
      <material name="white"/>
    </visual>
    <collision>
      <geometry>
        <box size="0.1 0.1 0.2"/>
      </geometry>
      <origin rpy="0 0 0" xyz="0 0 0.1"/>
    </collision>
    <inertial>
      <mass value="10"/>
      <inertia ixx="1.0" ixy="0.0" ixz="0.0" iyy="1.0" iyz="0.0" izz="1.0"/>
    </inertial>
  </link>
  <joint name="revolute_81" type="revolute">
    <parent link="branch_80"/>
    <child link="branch_81"/>
    <origin rpy="0.607346 0.195778 0.021054" xyz="0.050412 0.045042 0.431710"/>
    <axis xyz="-0.186587 0.464243 0.676902"/>
    <limit effort="1000.0" lower="-0.548" upper="0.548" velocity="0.5"/>
  </joint>
  <link name="branch_82">
    <visual>
      <geometry>
        <box size="0.1 0.1 0.2"/>
      </geometry>
      <origin rpy="0 0 0" xyz="0 0 0.1"/>
      <material name="white"/>
    </visual>
    <collision>
      <geometry>
        <box size="0.1 0.1 0.2"/>
      </geometry>
      <origin rpy="0 0 0" xyz="0 0 0.1"/>
    </collision>
    <inertial>
      <mass value="10"/>
      <inertia ixx="1.0" ixy="0.0" ixz="0.0" iyy="1.0" iyz="0.0" izz="1.0"/>
    </inertial>
  </link>
  <joint name="revolute_82" type="revolute">
    <parent link="branch_81"/>
    <child link="branch_82"/>
    <origin rpy="-0.150672 -0.341629 0.888171" xyz="0.044224 0.086375 0.486306"/>
    <axis xyz="-0.099849 -0.453054 0.900659"/>
    <limit effort="1000.0" lower="-0.548" upper="0.548" velocity="0.5"/>
  </joint>
  <link name="branch_83">
    <visual>
      <geometry>
        <box size="0.1 0.1 0.2"/>
      </geometry>
      <origin rpy="0 0 0" xyz="0 0 0.1"/>
      <material name="white"/>
    </visual>
    <collision>
      <geometry>
        <box size="0.1 0.1 0.2"/>
      </geometry>
      <origin rpy="0 0 0" xyz="0 0 0.1"/>
    </collision>
    <inertial>
      <mass value="10"/>
      <inertia ixx="1.0" ixy="0.0" ixz="0.0" iyy="1.0" iyz="0.0" izz="1.0"/>
    </inertial>
  </link>
  <joint name="revolute_83" type="revolute">
    <parent link="branch_82"/>
    <child link="branch_83"/>
    <origin rpy="0.674922 0.758672 0.984680" xyz="0.029033 0.067436 0.538095"/>
    <axis xyz="-0.133780 -0.416524 0.264178"/>
    <limit effort="1000.0" lower="-0.548" upper="0.548" velocity="0.5"/>
  </joint>
  <link name="branch_84">
    <visual>
      <geometry>
        <box size="0.1 0.1 0.2"/>
      </geometry>
      <origin rpy="0 0 0" xyz="0 0 0.1"/>
      <material name="white"/>
    </visual>
    <collision>
      <geometry>
        <box size="0.1 0.1 0.2"/>
      </geometry>
      <origin rpy="0 0 0" xyz="0 0 0.1"/>
    </collision>
    <inertial>
      <mass value="10"/>
      <inertia ixx="1.0" ixy="0.0" ixz="0.0" iyy="1.0" iyz="0.0" izz="1.0"/>
    </inertial>
  </link>
  <joint name="revolute_84" type="revolute">
    <parent link="branch_83"/>
    <child link="branch_84"/>
    <origin rpy="0.636636 0.887273 -0.798261" xyz="0.026874 0.010219 0.580908"/>
    <axis xyz="-0.998276 0.881279 -0.182679"/>
    <limit effort="1000.0" lower="-0.548" upper="0.548" velocity="0.5"/>
  </joint>
  <link name="branch_85">
    <visual>
      <geometry>
        <box size="0.1 0.1 0.2"/>
      </geometry>
      <origin rpy="0 0 0" xyz="0 0 0.1"/>
      <material name="white"/>
    </visual>
    <collision>
      <geometry>
        <box size="0.1 0.1 0.2"/>
      </geometry>
      <origin rpy="0 0 0" xyz="0 0 0.1"/>
    </collision>
    <inertial>
      <mass value="10"/>
      <inertia ixx="1.0" ixy="0.0" ixz="0.0" iyy="1.0" iyz="0.0" izz="1.0"/>
    </inertial>
  </link>
  <joint name="revolute_85" type="revolute">
    <parent link="branch_84"/>
    <child link="branch_85"/>
    <origin rpy="-0.710895 0.889895 0.502275" xyz="0.000831 0.037648 0.435160"/>
    <axis xyz="-0.436444 -0.346385 0.236081"/>
    <limit effort="1000.0" lower="-0.548" upper="0.548" velocity="0.5"/>
  </joint>
  <link name="branch_86">
    <visual>
      <geometry>
        <box size="0.1 0.1 0.2"/>
      </geometry>
      <origin rpy="0 0 0" xyz="0 0 0.1"/>
      <material name="white"/>
    </visual>
    <collision>
      <geometry>
        <box size="0.1 0.1 0.2"/>
      </geometry>
      <origin rpy="0 0 0" xyz="0 0 0.1"/>
    </collision>
    <inertial>
      <mass value="10"/>
      <inertia ixx="1.0" ixy="0.0" ixz="0.0" iyy="1.0" iyz="0.0" izz="1.0"/>
    </inertial>
  </link>
  <joint name="revolute_86" type="prismatic">
    <parent link="branch_85"/>
    <child link="branch_86"/>
    <origin rpy="0.894903 -0.451764 -0.792761" xyz="0.062182 0.096459 0.588216"/>
    <axis xyz="0.827109 0.193366 -0.537187"/>
    <limit effort="1000.0" lower="-0.548" upper="0.548" velocity="0.5"/>
  </joint>
  <link name="branch_87">
    <visual>
      <geometry>
        <box size="0.1 0.1 0.2"/>
      </geometry>
      <origin rpy="0 0 0" xyz="0 0 0.1"/>
      <material name="white"/>
    </visual>
    <collision>
      <geometry>
        <box size="0.1 0.1 0.2"/>
      </geometry>
      <origin rpy="0 0 0" xyz="0 0 0.1"/>
    </collision>
    <inertial>
      <mass value="10"/>
      <inertia ixx="1.0" ixy="0.0" ixz="0.0" iyy="1.0" iyz="0.0" izz="1.0"/>
    </inertial>
  </link>
  <joint name="revolute_87" type="revolute">
    <parent link="branch_86"/>
    <child link="branch_87"/>
    <origin rpy="0.216306 -0.971152 0.634223" xyz="0.071034 0.091897 0.527086"/>
    <axis xyz="0.301961 -0.344747 0.808340"/>
    <limit effort="1000.0" lower="-0.548" upper="0.548" velocity="0.5"/>
  </joint>
  <link name="branch_88">
    <visual>
      <geometry>
        <box size="0.1 0.1 0.2"/>
      </geometry>
      <origin rpy="0 0 0" xyz="0 0 0.1"/>
      <material name="white"/>
    </visual>
    <collision>
      <geometry>
        <box size="0.1 0.1 0.2"/>
      </geometry>
      <origin rpy="0 0 0" xyz="0 0 0.1"/>
    </collision>
    <inertial>
      <mass value="10"/>
      <inertia ixx="1.0" ixy="0.0" ixz="0.0" iyy="1.0" iyz="0.0" izz="1.0"/>
    </inertial>
  </link>
  <joint name="revolute_88" type="revolute">
    <parent link="branch_87"/>
    <child link="branch_88"/>
    <origin rpy="0.699959 -0.195763 -0.714012" xyz="0.022646 0.057792 0.457509"/>
    <axis xyz="0.106531 -0.608079 -0.408297"/>
    <limit effort="1000.0" lower="-0.548" upper="0.548" velocity="0.5"/>
  </joint>
  <link name="branch_89">
    <visual>
      <geometry>
        <box size="0.1 0.1 0.2"/>
      </geometry>
      <origin rpy="0 0 0" xyz="0 0 0.1"/>
      <material name="white"/>
    </visual>
    <collision>
      <geometry>
        <box size="0.1 0.1 0.2"/>
      </geometry>
      <origin rpy="0 0 0" xyz="0 0 0.1"/>
    </collision>
    <inertial>
      <mass value="10"/>
      <inertia ixx="1.0" ixy="0.0" ixz="0.0" iyy="1.0" iyz="0.0" izz="1.0"/>
    </inertial>
  </link>
  <joint name="revolute_89" type="revolute">
    <parent link="branch_88"/>
    <child link="branch_89"/>
    <origin rpy="0.703495 0.313770 -0.471848" xyz="0.081634 0.059797 0.442306"/>
    <axis xyz="-0.173951 0.658744 0.666688"/>
    <limit effort="1000.0" lower="-0.548" upper="0.548" velocity="0.5"/>
  </joint>
  <link name="branch_90">
    <visual>
      <geometry>
        <box size="0.1 0.1 0.2"/>
      </geometry>
      <origin rpy="0 0 0" xyz="0 0 0.1"/>
      <material name="white"/>
    </visual>
    <collision>
      <geometry>
        <box size="0.1 0.1 0.2"/>
      </geometry>
      <origin rpy="0 0 0" xyz="0 0 0.1"/>
    </collision>
    <inertial>
      <mass value="10"/>
      <inertia ixx="1.0" ixy="0.0" ixz="0.0" iyy="1.0" iyz="0.0" izz="1.0"/>
    </inertial>
  </link>
  <joint name="revolute_90" type="revolute">
    <parent link="branch_89"/>
    <child link="branch_90"/>
    <origin rpy="0.522645 -0.539728 -0.012223" xyz="0.068029 0.086557 0.420408"/>
    <axis xyz="-0.984171 0.539472 0.624765"/>
    <limit effort="1000.0" lower="-0.548" upper="0.548" velocity="0.5"/>
  </joint>
  <link name="branch_91">
    <visual>
      <geometry>
        <box size="0.1 0.1 0.2"/>
      </geometry>
      <origin rpy="0 0 0" xyz="0 0 0.1"/>
      <material name="white"/>
    </visual>
    <collision>
      <geometry>
        <box size="0.1 0.1 0.2"/>
      </geometry>
      <origin rpy="0 0 0" xyz="0 0 0.1"/>
    </collision>
    <inertial>
      <mass value="10"/>
      <inertia ixx="1.0" ixy="0.0" ixz="0.0" iyy="1.0" iyz="0.0" izz="1.0"/>
    </inertial>
  </link>
  <joint name="revolute_91" type="revolute">
    <parent link="branch_90"/>
    <child link="branch_91"/>
    <origin rpy="0.730963 -0.698183 0.349536" xyz="0.044340 0.043845 0.504950"/>
    <axis xyz="0.278724 0.468613 0.502411"/>
    <limit effort="1000.0" lower="-0.548" upper="0.548" velocity="0.5"/>
  </joint>
  <link name="branch_92">
    <visual>
      <geometry>
        <box size="0.1 0.1 0.2"/>
      </geometry>
      <origin rpy="0 0 0" xyz="0 0 0.1"/>
      <material name="white"/>
    </visual>
    <collision>
      <geometry>
        <box size="0.1 0.1 0.2"/>
      </geometry>
      <origin rpy="0 0 0" xyz="0 0 0.1"/>
    </collision>
    <inertial>
      <mass value="10"/>
      <inertia ixx="1.0" ixy="0.0" ixz="0.0" iyy="1.0" iyz="0.0" izz="1.0"/>
    </inertial>
  </link>
  <joint name="revolute_92" type="revolute">
    <parent link="branch_91"/>
    <child link="branch_92"/>
    <origin rpy="0.922712 0.806877 -0.376128" xyz="0.055932 0.011497 0.432737"/>
    <axis xyz="-0.222613 0.896620 0.960051"/>
    <limit effort="1000.0" lower="-0.548" upper="0.548" velocity="0.5"/>
  </joint>
  <link name="branch_93">
    <visual>
      <geometry>
        <box size="0.1 0.1 0.2"/>
      </geometry>
      <origin rpy="0 0 0" xyz="0 0 0.1"/>
      <material name="white"/>
    </visual>
    <collision>
      <geometry>
        <box size="0.1 0.1 0.2"/>
      </geometry>
      <origin rpy="0 0 0" xyz="0 0 0.1"/>
    </collision>
    <inertial>
      <mass value="10"/>
      <inertia ixx="1.0" ixy="0.0" ixz="0.0" iyy="1.0" iyz="0.0" izz="1.0"/>
    </inertial>
  </link>
  <joint name="revolute_93" type="revolute">
    <parent link="branch_92"/>
    <child link="branch_93"/>
    <origin rpy="0.246373 0.765163 0.390417" xyz="0.048875 0.098462 0.491306"/>
    <axis xyz="-0.483024 0.594011 -0.726362"/>
    <limit effort="1000.0" lower="-0.548" upper="0.548" velocity="0.5"/>
  </joint>
  <link name="branch_94">
    <visual>
      <geometry>
        <box size="0.1 0.1 0.2"/>
      </geometry>
      <origin rpy="0 0 0" xyz="0 0 0.1"/>
      <material name="white"/>
    </visual>
    <collision>
      <geometry>
        <box size="0.1 0.1 0.2"/>
      </geometry>
      <origin rpy="0 0 0" xyz="0 0 0.1"/>
    </collision>
    <inertial>
      <mass value="10"/>
      <inertia ixx="1.0" ixy="0.0" ixz="0.0" iyy="1.0" iyz="0.0" izz="1.0"/>
    </inertial>
  </link>
  <joint name="revolute_94" type="revolute">
    <parent link="branch_93"/>
    <child link="branch_94"/>
    <origin rpy="-0.408716 0.866512 -0.479262" xyz="0.073410 0.045800 0.425170"/>
    <axis xyz="-0.063192 -0.581582 0.138505"/>
    <limit effort="1000.0" lower="-0.548" upper="0.548" velocity="0.5"/>
  </joint>
  <link name="branch_95">
    <visual>
      <geometry>
        <box size="0.1 0.1 0.2"/>
      </geometry>
      <origin rpy="0 0 0" xyz="0 0 0.1"/>
      <material name="white"/>
    </visual>
    <collision>
      <geometry>
        <box size="0.1 0.1 0.2"/>
      </geometry>
      <origin rpy="0 0 0" xyz="0 0 0.1"/>
    </collision>
    <inertial>
      <mass value="10"/>
      <inertia ixx="1.0" ixy="0.0" ixz="0.0" iyy="1.0" iyz="0.0" izz="1.0"/>
    </inertial>
  </link>
  <joint name="revolute_95" type="revolute">
    <parent link="branch_94"/>
    <child link="branch_95"/>
    <origin rpy="-0.775894 0.560680 0.027360" xyz="0.022702 0.094402 0.495007"/>
    <axis xyz="-0.649342 0.848099 -0.931286"/>
    <limit effort="1000.0" lower="-0.548" upper="0.548" velocity="0.5"/>
  </joint>
  <link name="branch_96">
    <visual>
      <geometry>
        <box size="0.1 0.1 0.2"/>
      </geometry>
      <origin rpy="0 0 0" xyz="0 0 0.1"/>
      <material name="white"/>
    </visual>
    <collision>
      <geometry>
        <box size="0.1 0.1 0.2"/>
      </geometry>
      <origin rpy="0 0 0" xyz="0 0 0.1"/>
    </collision>
    <inertial>
      <mass value="10"/>
      <inertia ixx="1.0" ixy="0.0" ixz="0.0" iyy="1.0" iyz="0.0" izz="1.0"/>
    </inertial>
  </link>
  <joint name="revolute_96" type="revolute">
    <parent link="branch_95"/>
    <child link="branch_96"/>
    <origin rpy="-0.388736 0.741075 -0.365801" xyz="0.029025 0.032707 0.588057"/>
    <axis xyz="-0.825479 -0.072226 -0.141924"/>
    <limit effort="1000.0" lower="-0.548" upper="0.548" velocity="0.5"/>
  </joint>
  <link name="branch_97">
    <visual>
      <geometry>
        <box size="0.1 0.1 0.2"/>
      </geometry>
      <origin rpy="0 0 0" xyz="0 0 0.1"/>
      <material name="white"/>
    </visual>
    <collision>
      <geometry>
        <box size="0.1 0.1 0.2"/>
      </geometry>
      <origin rpy="0 0 0" xyz="0 0 0.1"/>
    </collision>
    <inertial>
      <mass value="10"/>
      <inertia ixx="1.0" ixy="0.0" ixz="0.0" iyy="1.0" iyz="0.0" izz="1.0"/>
    </inertial>
  </link>
  <joint name="revolute_97" type="revolute">
    <parent link="branch_96"/>
    <child link="branch_97"/>
    <origin rpy="0.241565 -0.304741 0.217242" xyz="0.007879 0.047348 0.580853"/>
    <axis xyz="-0.424010 -0.914534 0.276721"/>
    <limit effort="1000.0" lower="-0.548" upper="0.548" velocity="0.5"/>
  </joint>
  <link name="branch_98">
    <visual>
      <geometry>
        <box size="0.1 0.1 0.2"/>
      </geometry>
      <origin rpy="0 0 0" xyz="0 0 0.1"/>
      <material name="white"/>
    </visual>
    <collision>
      <geometry>
        <box size="0.1 0.1 0.2"/>
      </geometry>
      <origin rpy="0 0 0" xyz="0 0 0.1"/>
    </collision>
    <inertial>
      <mass value="10"/>
      <inertia ixx="1.0" ixy="0.0" ixz="0.0" iyy="1.0" iyz="0.0" izz="1.0"/>
    </inertial>
  </link>
  <joint name="revolute_98" type="revolute">
    <parent link="branch_97"/>
    <child link="branch_98"/>
    <origin rpy="0.774208 0.603350 -0.497305" xyz="0.083113 0.027671 0.472680"/>
    <axis xyz="0.510355 -0.377865 0.180838"/>
    <limit effort="1000.0" lower="-0.548" upper="0.548" velocity="0.5"/>
  </joint>
  <link name="branch_99">
    <visual>
      <geometry>
        <box size="0.1 0.1 0.2"/>
      </geometry>
      <origin rpy="0 0 0" xyz="0 0 0.1"/>
      <material name="white"/>
    </visual>
    <collision>
      <geometry>
        <box size="0.1 0.1 0.2"/>
      </geometry>
      <origin rpy="0 0 0" xyz="0 0 0.1"/>
    </collision>
    <inertial>
      <mass value="10"/>
      <inertia ixx="1.0" ixy="0.0" ixz="0.0" iyy="1.0" iyz="0.0" izz="1.0"/>
    </inertial>
  </link>
  <joint name="revolute_99" type="revolute">
    <parent link="branch_98"/>
    <child link="branch_99"/>
    <origin rpy="0.272571 -0.855446 0.468236" xyz="0.096335 0.001256 0.407950"/>
    <axis xyz="-0.145518 -0.116799 -0.339990"/>
    <limit effort="1000.0" lower="-0.548" upper="0.548" velocity="0.5"/>
  </joint>
  <link name="branch_100">
    <visual>
      <geometry>
        <box size="0.1 0.1 0.2"/>
      </geometry>
      <origin rpy="0 0 0" xyz="0 0 0.1"/>
      <material name="white"/>
    </visual>
    <collision>
      <geometry>
        <box size="0.1 0.1 0.2"/>
      </geometry>
      <origin rpy="0 0 0" xyz="0 0 0.1"/>
    </collision>
    <inertial>
      <mass value="10"/>
      <inertia ixx="1.0" ixy="0.0" ixz="0.0" iyy="1.0" iyz="0.0" izz="1.0"/>
    </inertial>
  </link>
  <joint name="revolute_100" type="revolute">
    <parent link="branch_99"/>
    <child link="branch_100"/>
    <origin rpy="0.529790 -0.928276 -0.741747" xyz="0.023838 0.094012 0.549982"/>
    <axis xyz="-0.437783 0.156971 0.657390"/>
    <limit effort="1000.0" lower="-0.548" upper="0.548" velocity="0.5"/>
  </joint>
  <link name="head">
    <visual>
      <geometry>
        <sphere radius="0.1"/>
      </geometry>
      <material name="black"/>
    </visual>
    <collision>
      <geometry>
        <sphere radius="0.1"/>
      </geometry>
    </collision>
    <inertial>
      <mass value="2"/>
      <inertia ixx="1.0" ixy="0.0" ixz="0.0" iyy="1.0" iyz="0.0" izz="1.0"/>
    </inertial>
  </link>
  <joint name="head_swivel" type="continuous">
    <parent link="branch_100"/>
    <child link="head"/>
    <origin xyz="0 0 0.2"/>
    <axis xyz="0 0 1"/>
  </joint>
</robot>

