<?xml version="1.0" ?>
<!-- =================================================================================== -->
<!-- |    This document was autogenerated by xacro from ../urdf/d_0100_0.urdf.xacro    | -->
<!-- |    EDITING THIS FILE BY HAND IS NOT RECOMMENDED                                 | -->
<!-- =================================================================================== -->
<robot name="multi_degree" xmlns:xacro="http://ros.org/wiki/xacro">
  <material name="blue">
    <color rgba="0 0 0.8 1"/>
  </material>
  <material name="black">
    <color rgba="0 0 0 1"/>
  </material>
  <material name="white">
    <color rgba="1 1 1 1"/>
  </material>
  <link name="branch_0">
    <visual>
      <geometry>
        <cylinder length="0.4" radius="0.1"/>
      </geometry>
      <material name="blue"/>
    </visual>
    <collision>
      <geometry>
        <cylinder length="0.4" radius="0.1"/>
      </geometry>
    </collision>
    <inertial>
      <mass value="10"/>
      <inertia ixx="1.0" ixy="0.0" ixz="0.0" iyy="1.0" iyz="0.0" izz="1.0"/>
    </inertial>
  </link>
  <link name="branch_1">
    <visual>
      <geometry>
        <box size="0.1 0.1 0.2"/>
      </geometry>
      <origin rpy="0 0 0" xyz="0 0 0.1"/>
      <material name="white"/>
    </visual>
    <collision>
      <geometry>
        <box size="0.1 0.1 0.2"/>
      </geometry>
      <origin rpy="0 0 0" xyz="0 0 0.1"/>
    </collision>
    <inertial>
      <mass value="10"/>
      <inertia ixx="1.0" ixy="0.0" ixz="0.0" iyy="1.0" iyz="0.0" izz="1.0"/>
    </inertial>
  </link>
  <joint name="revolute_1" type="revolute">
    <parent link="branch_0"/>
    <child link="branch_1"/>
    <origin rpy="0.880939 0.925130 -0.899589" xyz="0 0 0.2"/>
    <axis xyz="0 0 1"/>
    <limit effort="1000.0" lower="-0.548" upper="0.548" velocity="0.5"/>
  </joint>
  <link name="branch_2">
    <visual>
      <geometry>
        <box size="0.1 0.1 0.2"/>
      </geometry>
      <origin rpy="0 0 0" xyz="0 0 0.1"/>
      <material name="white"/>
    </visual>
    <collision>
      <geometry>
        <box size="0.1 0.1 0.2"/>
      </geometry>
      <origin rpy="0 0 0" xyz="0 0 0.1"/>
    </collision>
    <inertial>
      <mass value="10"/>
      <inertia ixx="1.0" ixy="0.0" ixz="0.0" iyy="1.0" iyz="0.0" izz="1.0"/>
    </inertial>
  </link>
  <joint name="revolute_2" type="revolute">
    <parent link="branch_1"/>
    <child link="branch_2"/>
    <origin rpy="-0.873213 -0.234889 -0.005690" xyz="0 0 0.2"/>
    <axis xyz="1 0 0"/>
    <limit effort="1000.0" lower="-0.548" upper="0.548" velocity="0.5"/>
  </joint>
  <link name="branch_3">
    <visual>
      <geometry>
        <box size="0.1 0.1 0.2"/>
      </geometry>
      <origin rpy="0 0 0" xyz="0 0 0.1"/>
      <material name="white"/>
    </visual>
    <collision>
      <geometry>
        <box size="0.1 0.1 0.2"/>
      </geometry>
      <origin rpy="0 0 0" xyz="0 0 0.1"/>
    </collision>
    <inertial>
      <mass value="10"/>
      <inertia ixx="1.0" ixy="0.0" ixz="0.0" iyy="1.0" iyz="0.0" izz="1.0"/>
    </inertial>
  </link>
  <joint name="revolute_3" type="revolute">
    <parent link="branch_2"/>
    <child link="branch_3"/>
    <origin rpy="0.678664 0.681439 0.793484" xyz="0 0 0.2"/>
    <axis xyz="0 1 0"/>
    <limit effort="1000.0" lower="-0.548" upper="0.548" velocity="0.5"/>
  </joint>
  <link name="branch_4">
    <visual>
      <geometry>
        <box size="0.1 0.1 0.2"/>
      </geometry>
      <origin rpy="0 0 0" xyz="0 0 0.1"/>
      <material name="white"/>
    </visual>
    <collision>
      <geometry>
        <box size="0.1 0.1 0.2"/>
      </geometry>
      <origin rpy="0 0 0" xyz="0 0 0.1"/>
    </collision>
    <inertial>
      <mass value="10"/>
      <inertia ixx="1.0" ixy="0.0" ixz="0.0" iyy="1.0" iyz="0.0" izz="1.0"/>
    </inertial>
  </link>
  <joint name="revolute_4" type="revolute">
    <parent link="branch_3"/>
    <child link="branch_4"/>
    <origin rpy="-0.206444 -0.244771 -0.447685" xyz="0 0 0.2"/>
    <axis xyz="0 0 1"/>
    <limit effort="1000.0" lower="-0.548" upper="0.548" velocity="0.5"/>
  </joint>
  <link name="branch_5">
    <visual>
      <geometry>
        <box size="0.1 0.1 0.2"/>
      </geometry>
      <origin rpy="0 0 0" xyz="0 0 0.1"/>
      <material name="white"/>
    </visual>
    <collision>
      <geometry>
        <box size="0.1 0.1 0.2"/>
      </geometry>
      <origin rpy="0 0 0" xyz="0 0 0.1"/>
    </collision>
    <inertial>
      <mass value="10"/>
      <inertia ixx="1.0" ixy="0.0" ixz="0.0" iyy="1.0" iyz="0.0" izz="1.0"/>
    </inertial>
  </link>
  <joint name="revolute_5" type="revolute">
    <parent link="branch_4"/>
    <child link="branch_5"/>
    <origin rpy="0.799155 -0.237650 0.455385" xyz="0 0 0.2"/>
    <axis xyz="1 0 0"/>
    <limit effort="1000.0" lower="-0.548" upper="0.548" velocity="0.5"/>
  </joint>
  <link name="branch_6">
    <visual>
      <geometry>
        <box size="0.1 0.1 0.2"/>
      </geometry>
      <origin rpy="0 0 0" xyz="0 0 0.1"/>
      <material name="white"/>
    </visual>
    <collision>
      <geometry>
        <box size="0.1 0.1 0.2"/>
      </geometry>
      <origin rpy="0 0 0" xyz="0 0 0.1"/>
    </collision>
    <inertial>
      <mass value="10"/>
      <inertia ixx="1.0" ixy="0.0" ixz="0.0" iyy="1.0" iyz="0.0" izz="1.0"/>
    </inertial>
  </link>
  <joint name="revolute_6" type="revolute">
    <parent link="branch_5"/>
    <child link="branch_6"/>
    <origin rpy="-0.291238 0.300774 0.289823" xyz="0 0 0.2"/>
    <axis xyz="0 1 0"/>
    <limit effort="1000.0" lower="-0.548" upper="0.548" velocity="0.5"/>
  </joint>
  <link name="branch_7">
    <visual>
      <geometry>
        <box size="0.1 0.1 0.2"/>
      </geometry>
      <origin rpy="0 0 0" xyz="0 0 0.1"/>
      <material name="white"/>
    </visual>
    <collision>
      <geometry>
        <box size="0.1 0.1 0.2"/>
      </geometry>
      <origin rpy="0 0 0" xyz="0 0 0.1"/>
    </collision>
    <inertial>
      <mass value="10"/>
      <inertia ixx="1.0" ixy="0.0" ixz="0.0" iyy="1.0" iyz="0.0" izz="1.0"/>
    </inertial>
  </link>
  <joint name="revolute_7" type="revolute">
    <parent link="branch_6"/>
    <child link="branch_7"/>
    <origin rpy="0.786577 -0.923928 -0.939867" xyz="0 0 0.2"/>
    <axis xyz="0 0 1"/>
    <limit effort="1000.0" lower="-0.548" upper="0.548" velocity="0.5"/>
  </joint>
  <link name="branch_8">
    <visual>
      <geometry>
        <box size="0.1 0.1 0.2"/>
      </geometry>
      <origin rpy="0 0 0" xyz="0 0 0.1"/>
      <material name="white"/>
    </visual>
    <collision>
      <geometry>
        <box size="0.1 0.1 0.2"/>
      </geometry>
      <origin rpy="0 0 0" xyz="0 0 0.1"/>
    </collision>
    <inertial>
      <mass value="10"/>
      <inertia ixx="1.0" ixy="0.0" ixz="0.0" iyy="1.0" iyz="0.0" izz="1.0"/>
    </inertial>
  </link>
  <joint name="revolute_8" type="revolute">
    <parent link="branch_7"/>
    <child link="branch_8"/>
    <origin rpy="-0.991979 -0.414691 -0.767531" xyz="0 0 0.2"/>
    <axis xyz="1 0 0"/>
    <limit effort="1000.0" lower="-0.548" upper="0.548" velocity="0.5"/>
  </joint>
  <link name="branch_9">
    <visual>
      <geometry>
        <box size="0.1 0.1 0.2"/>
      </geometry>
      <origin rpy="0 0 0" xyz="0 0 0.1"/>
      <material name="white"/>
    </visual>
    <collision>
      <geometry>
        <box size="0.1 0.1 0.2"/>
      </geometry>
      <origin rpy="0 0 0" xyz="0 0 0.1"/>
    </collision>
    <inertial>
      <mass value="10"/>
      <inertia ixx="1.0" ixy="0.0" ixz="0.0" iyy="1.0" iyz="0.0" izz="1.0"/>
    </inertial>
  </link>
  <joint name="revolute_9" type="revolute">
    <parent link="branch_8"/>
    <child link="branch_9"/>
    <origin rpy="0.975257 0.974660 -0.020132" xyz="0 0 0.2"/>
    <axis xyz="0 1 0"/>
    <limit effort="1000.0" lower="-0.548" upper="0.548" velocity="0.5"/>
  </joint>
  <link name="branch_10">
    <visual>
      <geometry>
        <box size="0.1 0.1 0.2"/>
      </geometry>
      <origin rpy="0 0 0" xyz="0 0 0.1"/>
      <material name="white"/>
    </visual>
    <collision>
      <geometry>
        <box size="0.1 0.1 0.2"/>
      </geometry>
      <origin rpy="0 0 0" xyz="0 0 0.1"/>
    </collision>
    <inertial>
      <mass value="10"/>
      <inertia ixx="1.0" ixy="0.0" ixz="0.0" iyy="1.0" iyz="0.0" izz="1.0"/>
    </inertial>
  </link>
  <joint name="revolute_10" type="revolute">
    <parent link="branch_9"/>
    <child link="branch_10"/>
    <origin rpy="0.618776 0.243435 0.009311" xyz="0 0 0.2"/>
    <axis xyz="0 0 1"/>
    <limit effort="1000.0" lower="-0.548" upper="0.548" velocity="0.5"/>
  </joint>
  <link name="branch_11">
    <visual>
      <geometry>
        <box size="0.1 0.1 0.2"/>
      </geometry>
      <origin rpy="0 0 0" xyz="0 0 0.1"/>
      <material name="white"/>
    </visual>
    <collision>
      <geometry>
        <box size="0.1 0.1 0.2"/>
      </geometry>
      <origin rpy="0 0 0" xyz="0 0 0.1"/>
    </collision>
    <inertial>
      <mass value="10"/>
      <inertia ixx="1.0" ixy="0.0" ixz="0.0" iyy="1.0" iyz="0.0" izz="1.0"/>
    </inertial>
  </link>
  <joint name="revolute_11" type="revolute">
    <parent link="branch_10"/>
    <child link="branch_11"/>
    <origin rpy="0.543905 0.343846 -0.296014" xyz="0 0 0.2"/>
    <axis xyz="1 0 0"/>
    <limit effort="1000.0" lower="-0.548" upper="0.548" velocity="0.5"/>
  </joint>
  <link name="branch_12">
    <visual>
      <geometry>
        <box size="0.1 0.1 0.2"/>
      </geometry>
      <origin rpy="0 0 0" xyz="0 0 0.1"/>
      <material name="white"/>
    </visual>
    <collision>
      <geometry>
        <box size="0.1 0.1 0.2"/>
      </geometry>
      <origin rpy="0 0 0" xyz="0 0 0.1"/>
    </collision>
    <inertial>
      <mass value="10"/>
      <inertia ixx="1.0" ixy="0.0" ixz="0.0" iyy="1.0" iyz="0.0" izz="1.0"/>
    </inertial>
  </link>
  <joint name="revolute_12" type="revolute">
    <parent link="branch_11"/>
    <child link="branch_12"/>
    <origin rpy="-0.690983 -0.661844 -0.415076" xyz="0 0 0.2"/>
    <axis xyz="0 1 0"/>
    <limit effort="1000.0" lower="-0.548" upper="0.548" velocity="0.5"/>
  </joint>
  <link name="branch_13">
    <visual>
      <geometry>
        <box size="0.1 0.1 0.2"/>
      </geometry>
      <origin rpy="0 0 0" xyz="0 0 0.1"/>
      <material name="white"/>
    </visual>
    <collision>
      <geometry>
        <box size="0.1 0.1 0.2"/>
      </geometry>
      <origin rpy="0 0 0" xyz="0 0 0.1"/>
    </collision>
    <inertial>
      <mass value="10"/>
      <inertia ixx="1.0" ixy="0.0" ixz="0.0" iyy="1.0" iyz="0.0" izz="1.0"/>
    </inertial>
  </link>
  <joint name="revolute_13" type="revolute">
    <parent link="branch_12"/>
    <child link="branch_13"/>
    <origin rpy="0.990456 -0.868361 -0.288289" xyz="0 0 0.2"/>
    <axis xyz="0 0 1"/>
    <limit effort="1000.0" lower="-0.548" upper="0.548" velocity="0.5"/>
  </joint>
  <link name="branch_14">
    <visual>
      <geometry>
        <box size="0.1 0.1 0.2"/>
      </geometry>
      <origin rpy="0 0 0" xyz="0 0 0.1"/>
      <material name="white"/>
    </visual>
    <collision>
      <geometry>
        <box size="0.1 0.1 0.2"/>
      </geometry>
      <origin rpy="0 0 0" xyz="0 0 0.1"/>
    </collision>
    <inertial>
      <mass value="10"/>
      <inertia ixx="1.0" ixy="0.0" ixz="0.0" iyy="1.0" iyz="0.0" izz="1.0"/>
    </inertial>
  </link>
  <joint name="revolute_14" type="revolute">
    <parent link="branch_13"/>
    <child link="branch_14"/>
    <origin rpy="-0.254315 -0.316045 -0.609626" xyz="0 0 0.2"/>
    <axis xyz="1 0 0"/>
    <limit effort="1000.0" lower="-0.548" upper="0.548" velocity="0.5"/>
  </joint>
  <link name="branch_15">
    <visual>
      <geometry>
        <box size="0.1 0.1 0.2"/>
      </geometry>
      <origin rpy="0 0 0" xyz="0 0 0.1"/>
      <material name="white"/>
    </visual>
    <collision>
      <geometry>
        <box size="0.1 0.1 0.2"/>
      </geometry>
      <origin rpy="0 0 0" xyz="0 0 0.1"/>
    </collision>
    <inertial>
      <mass value="10"/>
      <inertia ixx="1.0" ixy="0.0" ixz="0.0" iyy="1.0" iyz="0.0" izz="1.0"/>
    </inertial>
  </link>
  <joint name="revolute_15" type="revolute">
    <parent link="branch_14"/>
    <child link="branch_15"/>
    <origin rpy="0.508035 -0.860661 0.183931" xyz="0 0 0.2"/>
    <axis xyz="0 1 0"/>
    <limit effort="1000.0" lower="-0.548" upper="0.548" velocity="0.5"/>
  </joint>
  <link name="branch_16">
    <visual>
      <geometry>
        <box size="0.1 0.1 0.2"/>
      </geometry>
      <origin rpy="0 0 0" xyz="0 0 0.1"/>
      <material name="white"/>
    </visual>
    <collision>
      <geometry>
        <box size="0.1 0.1 0.2"/>
      </geometry>
      <origin rpy="0 0 0" xyz="0 0 0.1"/>
    </collision>
    <inertial>
      <mass value="10"/>
      <inertia ixx="1.0" ixy="0.0" ixz="0.0" iyy="1.0" iyz="0.0" izz="1.0"/>
    </inertial>
  </link>
  <joint name="revolute_16" type="revolute">
    <parent link="branch_15"/>
    <child link="branch_16"/>
    <origin rpy="-0.191191 0.429163 -0.016914" xyz="0 0 0.2"/>
    <axis xyz="0 0 1"/>
    <limit effort="1000.0" lower="-0.548" upper="0.548" velocity="0.5"/>
  </joint>
  <link name="branch_17">
    <visual>
      <geometry>
        <box size="0.1 0.1 0.2"/>
      </geometry>
      <origin rpy="0 0 0" xyz="0 0 0.1"/>
      <material name="white"/>
    </visual>
    <collision>
      <geometry>
        <box size="0.1 0.1 0.2"/>
      </geometry>
      <origin rpy="0 0 0" xyz="0 0 0.1"/>
    </collision>
    <inertial>
      <mass value="10"/>
      <inertia ixx="1.0" ixy="0.0" ixz="0.0" iyy="1.0" iyz="0.0" izz="1.0"/>
    </inertial>
  </link>
  <joint name="revolute_17" type="revolute">
    <parent link="branch_16"/>
    <child link="branch_17"/>
    <origin rpy="-0.115119 0.489296 0.691847" xyz="0 0 0.2"/>
    <axis xyz="1 0 0"/>
    <limit effort="1000.0" lower="-0.548" upper="0.548" velocity="0.5"/>
  </joint>
  <link name="branch_18">
    <visual>
      <geometry>
        <box size="0.1 0.1 0.2"/>
      </geometry>
      <origin rpy="0 0 0" xyz="0 0 0.1"/>
      <material name="white"/>
    </visual>
    <collision>
      <geometry>
        <box size="0.1 0.1 0.2"/>
      </geometry>
      <origin rpy="0 0 0" xyz="0 0 0.1"/>
    </collision>
    <inertial>
      <mass value="10"/>
      <inertia ixx="1.0" ixy="0.0" ixz="0.0" iyy="1.0" iyz="0.0" izz="1.0"/>
    </inertial>
  </link>
  <joint name="revolute_18" type="revolute">
    <parent link="branch_17"/>
    <child link="branch_18"/>
    <origin rpy="0.470189 0.721764 0.478424" xyz="0 0 0.2"/>
    <axis xyz="0 1 0"/>
    <limit effort="1000.0" lower="-0.548" upper="0.548" velocity="0.5"/>
  </joint>
  <link name="branch_19">
    <visual>
      <geometry>
        <box size="0.1 0.1 0.2"/>
      </geometry>
      <origin rpy="0 0 0" xyz="0 0 0.1"/>
      <material name="white"/>
    </visual>
    <collision>
      <geometry>
        <box size="0.1 0.1 0.2"/>
      </geometry>
      <origin rpy="0 0 0" xyz="0 0 0.1"/>
    </collision>
    <inertial>
      <mass value="10"/>
      <inertia ixx="1.0" ixy="0.0" ixz="0.0" iyy="1.0" iyz="0.0" izz="1.0"/>
    </inertial>
  </link>
  <joint name="revolute_19" type="revolute">
    <parent link="branch_18"/>
    <child link="branch_19"/>
    <origin rpy="0.444849 -0.298368 0.486445" xyz="0 0 0.2"/>
    <axis xyz="0 0 1"/>
    <limit effort="1000.0" lower="-0.548" upper="0.548" velocity="0.5"/>
  </joint>
  <link name="branch_20">
    <visual>
      <geometry>
        <box size="0.1 0.1 0.2"/>
      </geometry>
      <origin rpy="0 0 0" xyz="0 0 0.1"/>
      <material name="white"/>
    </visual>
    <collision>
      <geometry>
        <box size="0.1 0.1 0.2"/>
      </geometry>
      <origin rpy="0 0 0" xyz="0 0 0.1"/>
    </collision>
    <inertial>
      <mass value="10"/>
      <inertia ixx="1.0" ixy="0.0" ixz="0.0" iyy="1.0" iyz="0.0" izz="1.0"/>
    </inertial>
  </link>
  <joint name="revolute_20" type="revolute">
    <parent link="branch_19"/>
    <child link="branch_20"/>
    <origin rpy="-0.311716 0.710943 0.461702" xyz="0 0 0.2"/>
    <axis xyz="1 0 0"/>
    <limit effort="1000.0" lower="-0.548" upper="0.548" velocity="0.5"/>
  </joint>
  <link name="branch_21">
    <visual>
      <geometry>
        <box size="0.1 0.1 0.2"/>
      </geometry>
      <origin rpy="0 0 0" xyz="0 0 0.1"/>
      <material name="white"/>
    </visual>
    <collision>
      <geometry>
        <box size="0.1 0.1 0.2"/>
      </geometry>
      <origin rpy="0 0 0" xyz="0 0 0.1"/>
    </collision>
    <inertial>
      <mass value="10"/>
      <inertia ixx="1.0" ixy="0.0" ixz="0.0" iyy="1.0" iyz="0.0" izz="1.0"/>
    </inertial>
  </link>
  <joint name="revolute_21" type="revolute">
    <parent link="branch_20"/>
    <child link="branch_21"/>
    <origin rpy="-0.967871 -0.585071 0.080478" xyz="0 0 0.2"/>
    <axis xyz="0 1 0"/>
    <limit effort="1000.0" lower="-0.548" upper="0.548" velocity="0.5"/>
  </joint>
  <link name="branch_22">
    <visual>
      <geometry>
        <box size="0.1 0.1 0.2"/>
      </geometry>
      <origin rpy="0 0 0" xyz="0 0 0.1"/>
      <material name="white"/>
    </visual>
    <collision>
      <geometry>
        <box size="0.1 0.1 0.2"/>
      </geometry>
      <origin rpy="0 0 0" xyz="0 0 0.1"/>
    </collision>
    <inertial>
      <mass value="10"/>
      <inertia ixx="1.0" ixy="0.0" ixz="0.0" iyy="1.0" iyz="0.0" izz="1.0"/>
    </inertial>
  </link>
  <joint name="revolute_22" type="revolute">
    <parent link="branch_21"/>
    <child link="branch_22"/>
    <origin rpy="-0.629715 -0.000147 -0.375617" xyz="0 0 0.2"/>
    <axis xyz="0 0 1"/>
    <limit effort="1000.0" lower="-0.548" upper="0.548" velocity="0.5"/>
  </joint>
  <link name="branch_23">
    <visual>
      <geometry>
        <box size="0.1 0.1 0.2"/>
      </geometry>
      <origin rpy="0 0 0" xyz="0 0 0.1"/>
      <material name="white"/>
    </visual>
    <collision>
      <geometry>
        <box size="0.1 0.1 0.2"/>
      </geometry>
      <origin rpy="0 0 0" xyz="0 0 0.1"/>
    </collision>
    <inertial>
      <mass value="10"/>
      <inertia ixx="1.0" ixy="0.0" ixz="0.0" iyy="1.0" iyz="0.0" izz="1.0"/>
    </inertial>
  </link>
  <joint name="revolute_23" type="revolute">
    <parent link="branch_22"/>
    <child link="branch_23"/>
    <origin rpy="-0.498075 0.711564 -0.066600" xyz="0 0 0.2"/>
    <axis xyz="1 0 0"/>
    <limit effort="1000.0" lower="-0.548" upper="0.548" velocity="0.5"/>
  </joint>
  <link name="branch_24">
    <visual>
      <geometry>
        <box size="0.1 0.1 0.2"/>
      </geometry>
      <origin rpy="0 0 0" xyz="0 0 0.1"/>
      <material name="white"/>
    </visual>
    <collision>
      <geometry>
        <box size="0.1 0.1 0.2"/>
      </geometry>
      <origin rpy="0 0 0" xyz="0 0 0.1"/>
    </collision>
    <inertial>
      <mass value="10"/>
      <inertia ixx="1.0" ixy="0.0" ixz="0.0" iyy="1.0" iyz="0.0" izz="1.0"/>
    </inertial>
  </link>
  <joint name="revolute_24" type="revolute">
    <parent link="branch_23"/>
    <child link="branch_24"/>
    <origin rpy="0.185879 -0.898062 -0.076144" xyz="0 0 0.2"/>
    <axis xyz="0 1 0"/>
    <limit effort="1000.0" lower="-0.548" upper="0.548" velocity="0.5"/>
  </joint>
  <link name="branch_25">
    <visual>
      <geometry>
        <box size="0.1 0.1 0.2"/>
      </geometry>
      <origin rpy="0 0 0" xyz="0 0 0.1"/>
      <material name="white"/>
    </visual>
    <collision>
      <geometry>
        <box size="0.1 0.1 0.2"/>
      </geometry>
      <origin rpy="0 0 0" xyz="0 0 0.1"/>
    </collision>
    <inertial>
      <mass value="10"/>
      <inertia ixx="1.0" ixy="0.0" ixz="0.0" iyy="1.0" iyz="0.0" izz="1.0"/>
    </inertial>
  </link>
  <joint name="revolute_25" type="revolute">
    <parent link="branch_24"/>
    <child link="branch_25"/>
    <origin rpy="0.325219 0.285869 0.669540" xyz="0 0 0.2"/>
    <axis xyz="0 0 1"/>
    <limit effort="1000.0" lower="-0.548" upper="0.548" velocity="0.5"/>
  </joint>
  <link name="branch_26">
    <visual>
      <geometry>
        <box size="0.1 0.1 0.2"/>
      </geometry>
      <origin rpy="0 0 0" xyz="0 0 0.1"/>
      <material name="white"/>
    </visual>
    <collision>
      <geometry>
        <box size="0.1 0.1 0.2"/>
      </geometry>
      <origin rpy="0 0 0" xyz="0 0 0.1"/>
    </collision>
    <inertial>
      <mass value="10"/>
      <inertia ixx="1.0" ixy="0.0" ixz="0.0" iyy="1.0" iyz="0.0" izz="1.0"/>
    </inertial>
  </link>
  <joint name="revolute_26" type="revolute">
    <parent link="branch_25"/>
    <child link="branch_26"/>
    <origin rpy="-0.245619 -0.731046 0.177576" xyz="0 0 0.2"/>
    <axis xyz="1 0 0"/>
    <limit effort="1000.0" lower="-0.548" upper="0.548" velocity="0.5"/>
  </joint>
  <link name="branch_27">
    <visual>
      <geometry>
        <box size="0.1 0.1 0.2"/>
      </geometry>
      <origin rpy="0 0 0" xyz="0 0 0.1"/>
      <material name="white"/>
    </visual>
    <collision>
      <geometry>
        <box size="0.1 0.1 0.2"/>
      </geometry>
      <origin rpy="0 0 0" xyz="0 0 0.1"/>
    </collision>
    <inertial>
      <mass value="10"/>
      <inertia ixx="1.0" ixy="0.0" ixz="0.0" iyy="1.0" iyz="0.0" izz="1.0"/>
    </inertial>
  </link>
  <joint name="revolute_27" type="revolute">
    <parent link="branch_26"/>
    <child link="branch_27"/>
    <origin rpy="-0.756323 0.960802 0.986385" xyz="0 0 0.2"/>
    <axis xyz="0 1 0"/>
    <limit effort="1000.0" lower="-0.548" upper="0.548" velocity="0.5"/>
  </joint>
  <link name="branch_28">
    <visual>
      <geometry>
        <box size="0.1 0.1 0.2"/>
      </geometry>
      <origin rpy="0 0 0" xyz="0 0 0.1"/>
      <material name="white"/>
    </visual>
    <collision>
      <geometry>
        <box size="0.1 0.1 0.2"/>
      </geometry>
      <origin rpy="0 0 0" xyz="0 0 0.1"/>
    </collision>
    <inertial>
      <mass value="10"/>
      <inertia ixx="1.0" ixy="0.0" ixz="0.0" iyy="1.0" iyz="0.0" izz="1.0"/>
    </inertial>
  </link>
  <joint name="revolute_28" type="revolute">
    <parent link="branch_27"/>
    <child link="branch_28"/>
    <origin rpy="0.965441 0.439226 -0.128735" xyz="0 0 0.2"/>
    <axis xyz="0 0 1"/>
    <limit effort="1000.0" lower="-0.548" upper="0.548" velocity="0.5"/>
  </joint>
  <link name="branch_29">
    <visual>
      <geometry>
        <box size="0.1 0.1 0.2"/>
      </geometry>
      <origin rpy="0 0 0" xyz="0 0 0.1"/>
      <material name="white"/>
    </visual>
    <collision>
      <geometry>
        <box size="0.1 0.1 0.2"/>
      </geometry>
      <origin rpy="0 0 0" xyz="0 0 0.1"/>
    </collision>
    <inertial>
      <mass value="10"/>
      <inertia ixx="1.0" ixy="0.0" ixz="0.0" iyy="1.0" iyz="0.0" izz="1.0"/>
    </inertial>
  </link>
  <joint name="revolute_29" type="revolute">
    <parent link="branch_28"/>
    <child link="branch_29"/>
    <origin rpy="-0.332927 -0.074329 -0.658546" xyz="0 0 0.2"/>
    <axis xyz="1 0 0"/>
    <limit effort="1000.0" lower="-0.548" upper="0.548" velocity="0.5"/>
  </joint>
  <link name="branch_30">
    <visual>
      <geometry>
        <box size="0.1 0.1 0.2"/>
      </geometry>
      <origin rpy="0 0 0" xyz="0 0 0.1"/>
      <material name="white"/>
    </visual>
    <collision>
      <geometry>
        <box size="0.1 0.1 0.2"/>
      </geometry>
      <origin rpy="0 0 0" xyz="0 0 0.1"/>
    </collision>
    <inertial>
      <mass value="10"/>
      <inertia ixx="1.0" ixy="0.0" ixz="0.0" iyy="1.0" iyz="0.0" izz="1.0"/>
    </inertial>
  </link>
  <joint name="revolute_30" type="revolute">
    <parent link="branch_29"/>
    <child link="branch_30"/>
    <origin rpy="-0.621984 -0.612627 0.786303" xyz="0 0 0.2"/>
    <axis xyz="0 1 0"/>
    <limit effort="1000.0" lower="-0.548" upper="0.548" velocity="0.5"/>
  </joint>
  <link name="branch_31">
    <visual>
      <geometry>
        <box size="0.1 0.1 0.2"/>
      </geometry>
      <origin rpy="0 0 0" xyz="0 0 0.1"/>
      <material name="white"/>
    </visual>
    <collision>
      <geometry>
        <box size="0.1 0.1 0.2"/>
      </geometry>
      <origin rpy="0 0 0" xyz="0 0 0.1"/>
    </collision>
    <inertial>
      <mass value="10"/>
      <inertia ixx="1.0" ixy="0.0" ixz="0.0" iyy="1.0" iyz="0.0" izz="1.0"/>
    </inertial>
  </link>
  <joint name="revolute_31" type="revolute">
    <parent link="branch_30"/>
    <child link="branch_31"/>
    <origin rpy="-0.207056 0.467851 -0.525414" xyz="0 0 0.2"/>
    <axis xyz="0 0 1"/>
    <limit effort="1000.0" lower="-0.548" upper="0.548" velocity="0.5"/>
  </joint>
  <link name="branch_32">
    <visual>
      <geometry>
        <box size="0.1 0.1 0.2"/>
      </geometry>
      <origin rpy="0 0 0" xyz="0 0 0.1"/>
      <material name="white"/>
    </visual>
    <collision>
      <geometry>
        <box size="0.1 0.1 0.2"/>
      </geometry>
      <origin rpy="0 0 0" xyz="0 0 0.1"/>
    </collision>
    <inertial>
      <mass value="10"/>
      <inertia ixx="1.0" ixy="0.0" ixz="0.0" iyy="1.0" iyz="0.0" izz="1.0"/>
    </inertial>
  </link>
  <joint name="revolute_32" type="revolute">
    <parent link="branch_31"/>
    <child link="branch_32"/>
    <origin rpy="0.792797 -0.907765 -0.493284" xyz="0 0 0.2"/>
    <axis xyz="1 0 0"/>
    <limit effort="1000.0" lower="-0.548" upper="0.548" velocity="0.5"/>
  </joint>
  <link name="branch_33">
    <visual>
      <geometry>
        <box size="0.1 0.1 0.2"/>
      </geometry>
      <origin rpy="0 0 0" xyz="0 0 0.1"/>
      <material name="white"/>
    </visual>
    <collision>
      <geometry>
        <box size="0.1 0.1 0.2"/>
      </geometry>
      <origin rpy="0 0 0" xyz="0 0 0.1"/>
    </collision>
    <inertial>
      <mass value="10"/>
      <inertia ixx="1.0" ixy="0.0" ixz="0.0" iyy="1.0" iyz="0.0" izz="1.0"/>
    </inertial>
  </link>
  <joint name="revolute_33" type="revolute">
    <parent link="branch_32"/>
    <child link="branch_33"/>
    <origin rpy="0.504361 0.025635 -0.122999" xyz="0 0 0.2"/>
    <axis xyz="0 1 0"/>
    <limit effort="1000.0" lower="-0.548" upper="0.548" velocity="0.5"/>
  </joint>
  <link name="branch_34">
    <visual>
      <geometry>
        <box size="0.1 0.1 0.2"/>
      </geometry>
      <origin rpy="0 0 0" xyz="0 0 0.1"/>
      <material name="white"/>
    </visual>
    <collision>
      <geometry>
        <box size="0.1 0.1 0.2"/>
      </geometry>
      <origin rpy="0 0 0" xyz="0 0 0.1"/>
    </collision>
    <inertial>
      <mass value="10"/>
      <inertia ixx="1.0" ixy="0.0" ixz="0.0" iyy="1.0" iyz="0.0" izz="1.0"/>
    </inertial>
  </link>
  <joint name="revolute_34" type="revolute">
    <parent link="branch_33"/>
    <child link="branch_34"/>
    <origin rpy="0.606299 0.949490 0.378926" xyz="0 0 0.2"/>
    <axis xyz="0 0 1"/>
    <limit effort="1000.0" lower="-0.548" upper="0.548" velocity="0.5"/>
  </joint>
  <link name="branch_35">
    <visual>
      <geometry>
        <box size="0.1 0.1 0.2"/>
      </geometry>
      <origin rpy="0 0 0" xyz="0 0 0.1"/>
      <material name="white"/>
    </visual>
    <collision>
      <geometry>
        <box size="0.1 0.1 0.2"/>
      </geometry>
      <origin rpy="0 0 0" xyz="0 0 0.1"/>
    </collision>
    <inertial>
      <mass value="10"/>
      <inertia ixx="1.0" ixy="0.0" ixz="0.0" iyy="1.0" iyz="0.0" izz="1.0"/>
    </inertial>
  </link>
  <joint name="revolute_35" type="revolute">
    <parent link="branch_34"/>
    <child link="branch_35"/>
    <origin rpy="-0.107832 0.619031 -0.435195" xyz="0 0 0.2"/>
    <axis xyz="1 0 0"/>
    <limit effort="1000.0" lower="-0.548" upper="0.548" velocity="0.5"/>
  </joint>
  <link name="branch_36">
    <visual>
      <geometry>
        <box size="0.1 0.1 0.2"/>
      </geometry>
      <origin rpy="0 0 0" xyz="0 0 0.1"/>
      <material name="white"/>
    </visual>
    <collision>
      <geometry>
        <box size="0.1 0.1 0.2"/>
      </geometry>
      <origin rpy="0 0 0" xyz="0 0 0.1"/>
    </collision>
    <inertial>
      <mass value="10"/>
      <inertia ixx="1.0" ixy="0.0" ixz="0.0" iyy="1.0" iyz="0.0" izz="1.0"/>
    </inertial>
  </link>
  <joint name="revolute_36" type="revolute">
    <parent link="branch_35"/>
    <child link="branch_36"/>
    <origin rpy="0.161122 -0.203394 0.890023" xyz="0 0 0.2"/>
    <axis xyz="0 1 0"/>
    <limit effort="1000.0" lower="-0.548" upper="0.548" velocity="0.5"/>
  </joint>
  <link name="branch_37">
    <visual>
      <geometry>
        <box size="0.1 0.1 0.2"/>
      </geometry>
      <origin rpy="0 0 0" xyz="0 0 0.1"/>
      <material name="white"/>
    </visual>
    <collision>
      <geometry>
        <box size="0.1 0.1 0.2"/>
      </geometry>
      <origin rpy="0 0 0" xyz="0 0 0.1"/>
    </collision>
    <inertial>
      <mass value="10"/>
      <inertia ixx="1.0" ixy="0.0" ixz="0.0" iyy="1.0" iyz="0.0" izz="1.0"/>
    </inertial>
  </link>
  <joint name="revolute_37" type="revolute">
    <parent link="branch_36"/>
    <child link="branch_37"/>
    <origin rpy="0.121924 -0.217009 -0.355595" xyz="0 0 0.2"/>
    <axis xyz="0 0 1"/>
    <limit effort="1000.0" lower="-0.548" upper="0.548" velocity="0.5"/>
  </joint>
  <link name="branch_38">
    <visual>
      <geometry>
        <box size="0.1 0.1 0.2"/>
      </geometry>
      <origin rpy="0 0 0" xyz="0 0 0.1"/>
      <material name="white"/>
    </visual>
    <collision>
      <geometry>
        <box size="0.1 0.1 0.2"/>
      </geometry>
      <origin rpy="0 0 0" xyz="0 0 0.1"/>
    </collision>
    <inertial>
      <mass value="10"/>
      <inertia ixx="1.0" ixy="0.0" ixz="0.0" iyy="1.0" iyz="0.0" izz="1.0"/>
    </inertial>
  </link>
  <joint name="revolute_38" type="revolute">
    <parent link="branch_37"/>
    <child link="branch_38"/>
    <origin rpy="-0.438851 0.654256 -0.111919" xyz="0 0 0.2"/>
    <axis xyz="1 0 0"/>
    <limit effort="1000.0" lower="-0.548" upper="0.548" velocity="0.5"/>
  </joint>
  <link name="branch_39">
    <visual>
      <geometry>
        <box size="0.1 0.1 0.2"/>
      </geometry>
      <origin rpy="0 0 0" xyz="0 0 0.1"/>
      <material name="white"/>
    </visual>
    <collision>
      <geometry>
        <box size="0.1 0.1 0.2"/>
      </geometry>
      <origin rpy="0 0 0" xyz="0 0 0.1"/>
    </collision>
    <inertial>
      <mass value="10"/>
      <inertia ixx="1.0" ixy="0.0" ixz="0.0" iyy="1.0" iyz="0.0" izz="1.0"/>
    </inertial>
  </link>
  <joint name="revolute_39" type="revolute">
    <parent link="branch_38"/>
    <child link="branch_39"/>
    <origin rpy="0.486820 0.995710 -0.146478" xyz="0 0 0.2"/>
    <axis xyz="0 1 0"/>
    <limit effort="1000.0" lower="-0.548" upper="0.548" velocity="0.5"/>
  </joint>
  <link name="branch_40">
    <visual>
      <geometry>
        <box size="0.1 0.1 0.2"/>
      </geometry>
      <origin rpy="0 0 0" xyz="0 0 0.1"/>
      <material name="white"/>
    </visual>
    <collision>
      <geometry>
        <box size="0.1 0.1 0.2"/>
      </geometry>
      <origin rpy="0 0 0" xyz="0 0 0.1"/>
    </collision>
    <inertial>
      <mass value="10"/>
      <inertia ixx="1.0" ixy="0.0" ixz="0.0" iyy="1.0" iyz="0.0" izz="1.0"/>
    </inertial>
  </link>
  <joint name="revolute_40" type="revolute">
    <parent link="branch_39"/>
    <child link="branch_40"/>
    <origin rpy="0.874194 0.782013 0.520595" xyz="0 0 0.2"/>
    <axis xyz="0 0 1"/>
    <limit effort="1000.0" lower="-0.548" upper="0.548" velocity="0.5"/>
  </joint>
  <link name="branch_41">
    <visual>
      <geometry>
        <box size="0.1 0.1 0.2"/>
      </geometry>
      <origin rpy="0 0 0" xyz="0 0 0.1"/>
      <material name="white"/>
    </visual>
    <collision>
      <geometry>
        <box size="0.1 0.1 0.2"/>
      </geometry>
      <origin rpy="0 0 0" xyz="0 0 0.1"/>
    </collision>
    <inertial>
      <mass value="10"/>
      <inertia ixx="1.0" ixy="0.0" ixz="0.0" iyy="1.0" iyz="0.0" izz="1.0"/>
    </inertial>
  </link>
  <joint name="revolute_41" type="revolute">
    <parent link="branch_40"/>
    <child link="branch_41"/>
    <origin rpy="0.342045 -0.743400 0.898611" xyz="0 0 0.2"/>
    <axis xyz="1 0 0"/>
    <limit effort="1000.0" lower="-0.548" upper="0.548" velocity="0.5"/>
  </joint>
  <link name="branch_42">
    <visual>
      <geometry>
        <box size="0.1 0.1 0.2"/>
      </geometry>
      <origin rpy="0 0 0" xyz="0 0 0.1"/>
      <material name="white"/>
    </visual>
    <collision>
      <geometry>
        <box size="0.1 0.1 0.2"/>
      </geometry>
      <origin rpy="0 0 0" xyz="0 0 0.1"/>
    </collision>
    <inertial>
      <mass value="10"/>
      <inertia ixx="1.0" ixy="0.0" ixz="0.0" iyy="1.0" iyz="0.0" izz="1.0"/>
    </inertial>
  </link>
  <joint name="revolute_42" type="revolute">
    <parent link="branch_41"/>
    <child link="branch_42"/>
    <origin rpy="0.434280 -0.236685 -0.308445" xyz="0 0 0.2"/>
    <axis xyz="0 1 0"/>
    <limit effort="1000.0" lower="-0.548" upper="0.548" velocity="0.5"/>
  </joint>
  <link name="branch_43">
    <visual>
      <geometry>
        <box size="0.1 0.1 0.2"/>
      </geometry>
      <origin rpy="0 0 0" xyz="0 0 0.1"/>
      <material name="white"/>
    </visual>
    <collision>
      <geometry>
        <box size="0.1 0.1 0.2"/>
      </geometry>
      <origin rpy="0 0 0" xyz="0 0 0.1"/>
    </collision>
    <inertial>
      <mass value="10"/>
      <inertia ixx="1.0" ixy="0.0" ixz="0.0" iyy="1.0" iyz="0.0" izz="1.0"/>
    </inertial>
  </link>
  <joint name="revolute_43" type="revolute">
    <parent link="branch_42"/>
    <child link="branch_43"/>
    <origin rpy="-0.540086 0.640316 -0.515648" xyz="0 0 0.2"/>
    <axis xyz="0 0 1"/>
    <limit effort="1000.0" lower="-0.548" upper="0.548" velocity="0.5"/>
  </joint>
  <link name="branch_44">
    <visual>
      <geometry>
        <box size="0.1 0.1 0.2"/>
      </geometry>
      <origin rpy="0 0 0" xyz="0 0 0.1"/>
      <material name="white"/>
    </visual>
    <collision>
      <geometry>
        <box size="0.1 0.1 0.2"/>
      </geometry>
      <origin rpy="0 0 0" xyz="0 0 0.1"/>
    </collision>
    <inertial>
      <mass value="10"/>
      <inertia ixx="1.0" ixy="0.0" ixz="0.0" iyy="1.0" iyz="0.0" izz="1.0"/>
    </inertial>
  </link>
  <joint name="revolute_44" type="revolute">
    <parent link="branch_43"/>
    <child link="branch_44"/>
    <origin rpy="-0.590595 0.019242 0.988713" xyz="0 0 0.2"/>
    <axis xyz="1 0 0"/>
    <limit effort="1000.0" lower="-0.548" upper="0.548" velocity="0.5"/>
  </joint>
  <link name="branch_45">
    <visual>
      <geometry>
        <box size="0.1 0.1 0.2"/>
      </geometry>
      <origin rpy="0 0 0" xyz="0 0 0.1"/>
      <material name="white"/>
    </visual>
    <collision>
      <geometry>
        <box size="0.1 0.1 0.2"/>
      </geometry>
      <origin rpy="0 0 0" xyz="0 0 0.1"/>
    </collision>
    <inertial>
      <mass value="10"/>
      <inertia ixx="1.0" ixy="0.0" ixz="0.0" iyy="1.0" iyz="0.0" izz="1.0"/>
    </inertial>
  </link>
  <joint name="revolute_45" type="revolute">
    <parent link="branch_44"/>
    <child link="branch_45"/>
    <origin rpy="-0.971565 0.584047 0.595012" xyz="0 0 0.2"/>
    <axis xyz="0 1 0"/>
    <limit effort="1000.0" lower="-0.548" upper="0.548" velocity="0.5"/>
  </joint>
  <link name="branch_46">
    <visual>
      <geometry>
        <box size="0.1 0.1 0.2"/>
      </geometry>
      <origin rpy="0 0 0" xyz="0 0 0.1"/>
      <material name="white"/>
    </visual>
    <collision>
      <geometry>
        <box size="0.1 0.1 0.2"/>
      </geometry>
      <origin rpy="0 0 0" xyz="0 0 0.1"/>
    </collision>
    <inertial>
      <mass value="10"/>
      <inertia ixx="1.0" ixy="0.0" ixz="0.0" iyy="1.0" iyz="0.0" izz="1.0"/>
    </inertial>
  </link>
  <joint name="revolute_46" type="revolute">
    <parent link="branch_45"/>
    <child link="branch_46"/>
    <origin rpy="-0.174958 0.474071 -0.512820" xyz="0 0 0.2"/>
    <axis xyz="0 0 1"/>
    <limit effort="1000.0" lower="-0.548" upper="0.548" velocity="0.5"/>
  </joint>
  <link name="branch_47">
    <visual>
      <geometry>
        <box size="0.1 0.1 0.2"/>
      </geometry>
      <origin rpy="0 0 0" xyz="0 0 0.1"/>
      <material name="white"/>
    </visual>
    <collision>
      <geometry>
        <box size="0.1 0.1 0.2"/>
      </geometry>
      <origin rpy="0 0 0" xyz="0 0 0.1"/>
    </collision>
    <inertial>
      <mass value="10"/>
      <inertia ixx="1.0" ixy="0.0" ixz="0.0" iyy="1.0" iyz="0.0" izz="1.0"/>
    </inertial>
  </link>
  <joint name="revolute_47" type="revolute">
    <parent link="branch_46"/>
    <child link="branch_47"/>
    <origin rpy="0.608033 -0.881525 0.648302" xyz="0 0 0.2"/>
    <axis xyz="1 0 0"/>
    <limit effort="1000.0" lower="-0.548" upper="0.548" velocity="0.5"/>
  </joint>
  <link name="branch_48">
    <visual>
      <geometry>
        <box size="0.1 0.1 0.2"/>
      </geometry>
      <origin rpy="0 0 0" xyz="0 0 0.1"/>
      <material name="white"/>
    </visual>
    <collision>
      <geometry>
        <box size="0.1 0.1 0.2"/>
      </geometry>
      <origin rpy="0 0 0" xyz="0 0 0.1"/>
    </collision>
    <inertial>
      <mass value="10"/>
      <inertia ixx="1.0" ixy="0.0" ixz="0.0" iyy="1.0" iyz="0.0" izz="1.0"/>
    </inertial>
  </link>
  <joint name="revolute_48" type="revolute">
    <parent link="branch_47"/>
    <child link="branch_48"/>
    <origin rpy="0.262289 0.006557 -0.229775" xyz="0 0 0.2"/>
    <axis xyz="0 1 0"/>
    <limit effort="1000.0" lower="-0.548" upper="0.548" velocity="0.5"/>
  </joint>
  <link name="branch_49">
    <visual>
      <geometry>
        <box size="0.1 0.1 0.2"/>
      </geometry>
      <origin rpy="0 0 0" xyz="0 0 0.1"/>
      <material name="white"/>
    </visual>
    <collision>
      <geometry>
        <box size="0.1 0.1 0.2"/>
      </geometry>
      <origin rpy="0 0 0" xyz="0 0 0.1"/>
    </collision>
    <inertial>
      <mass value="10"/>
      <inertia ixx="1.0" ixy="0.0" ixz="0.0" iyy="1.0" iyz="0.0" izz="1.0"/>
    </inertial>
  </link>
  <joint name="revolute_49" type="revolute">
    <parent link="branch_48"/>
    <child link="branch_49"/>
    <origin rpy="0.257999 0.860079 0.331375" xyz="0 0 0.2"/>
    <axis xyz="0 0 1"/>
    <limit effort="1000.0" lower="-0.548" upper="0.548" velocity="0.5"/>
  </joint>
  <link name="branch_50">
    <visual>
      <geometry>
        <box size="0.1 0.1 0.2"/>
      </geometry>
      <origin rpy="0 0 0" xyz="0 0 0.1"/>
      <material name="white"/>
    </visual>
    <collision>
      <geometry>
        <box size="0.1 0.1 0.2"/>
      </geometry>
      <origin rpy="0 0 0" xyz="0 0 0.1"/>
    </collision>
    <inertial>
      <mass value="10"/>
      <inertia ixx="1.0" ixy="0.0" ixz="0.0" iyy="1.0" iyz="0.0" izz="1.0"/>
    </inertial>
  </link>
  <joint name="revolute_50" type="revolute">
    <parent link="branch_49"/>
    <child link="branch_50"/>
    <origin rpy="0.040012 0.380674 -0.181805" xyz="0 0 0.2"/>
    <axis xyz="1 0 0"/>
    <limit effort="1000.0" lower="-0.548" upper="0.548" velocity="0.5"/>
  </joint>
  <link name="branch_51">
    <visual>
      <geometry>
        <box size="0.1 0.1 0.2"/>
      </geometry>
      <origin rpy="0 0 0" xyz="0 0 0.1"/>
      <material name="white"/>
    </visual>
    <collision>
      <geometry>
        <box size="0.1 0.1 0.2"/>
      </geometry>
      <origin rpy="0 0 0" xyz="0 0 0.1"/>
    </collision>
    <inertial>
      <mass value="10"/>
      <inertia ixx="1.0" ixy="0.0" ixz="0.0" iyy="1.0" iyz="0.0" izz="1.0"/>
    </inertial>
  </link>
  <joint name="revolute_51" type="revolute">
    <parent link="branch_50"/>
    <child link="branch_51"/>
    <origin rpy="0.296612 0.279285 -0.307611" xyz="0 0 0.2"/>
    <axis xyz="0 1 0"/>
    <limit effort="1000.0" lower="-0.548" upper="0.548" velocity="0.5"/>
  </joint>
  <link name="branch_52">
    <visual>
      <geometry>
        <box size="0.1 0.1 0.2"/>
      </geometry>
      <origin rpy="0 0 0" xyz="0 0 0.1"/>
      <material name="white"/>
    </visual>
    <collision>
      <geometry>
        <box size="0.1 0.1 0.2"/>
      </geometry>
      <origin rpy="0 0 0" xyz="0 0 0.1"/>
    </collision>
    <inertial>
      <mass value="10"/>
      <inertia ixx="1.0" ixy="0.0" ixz="0.0" iyy="1.0" iyz="0.0" izz="1.0"/>
    </inertial>
  </link>
  <joint name="revolute_52" type="revolute">
    <parent link="branch_51"/>
    <child link="branch_52"/>
    <origin rpy="-0.940073 0.970840 -0.965566" xyz="0 0 0.2"/>
    <axis xyz="0 0 1"/>
    <limit effort="1000.0" lower="-0.548" upper="0.548" velocity="0.5"/>
  </joint>
  <link name="branch_53">
    <visual>
      <geometry>
        <box size="0.1 0.1 0.2"/>
      </geometry>
      <origin rpy="0 0 0" xyz="0 0 0.1"/>
      <material name="white"/>
    </visual>
    <collision>
      <geometry>
        <box size="0.1 0.1 0.2"/>
      </geometry>
      <origin rpy="0 0 0" xyz="0 0 0.1"/>
    </collision>
    <inertial>
      <mass value="10"/>
      <inertia ixx="1.0" ixy="0.0" ixz="0.0" iyy="1.0" iyz="0.0" izz="1.0"/>
    </inertial>
  </link>
  <joint name="revolute_53" type="revolute">
    <parent link="branch_52"/>
    <child link="branch_53"/>
    <origin rpy="0.700244 -0.544807 0.468713" xyz="0 0 0.2"/>
    <axis xyz="1 0 0"/>
    <limit effort="1000.0" lower="-0.548" upper="0.548" velocity="0.5"/>
  </joint>
  <link name="branch_54">
    <visual>
      <geometry>
        <box size="0.1 0.1 0.2"/>
      </geometry>
      <origin rpy="0 0 0" xyz="0 0 0.1"/>
      <material name="white"/>
    </visual>
    <collision>
      <geometry>
        <box size="0.1 0.1 0.2"/>
      </geometry>
      <origin rpy="0 0 0" xyz="0 0 0.1"/>
    </collision>
    <inertial>
      <mass value="10"/>
      <inertia ixx="1.0" ixy="0.0" ixz="0.0" iyy="1.0" iyz="0.0" izz="1.0"/>
    </inertial>
  </link>
  <joint name="revolute_54" type="revolute">
    <parent link="branch_53"/>
    <child link="branch_54"/>
    <origin rpy="-0.280514 -0.556094 0.928627" xyz="0 0 0.2"/>
    <axis xyz="0 1 0"/>
    <limit effort="1000.0" lower="-0.548" upper="0.548" velocity="0.5"/>
  </joint>
  <link name="branch_55">
    <visual>
      <geometry>
        <box size="0.1 0.1 0.2"/>
      </geometry>
      <origin rpy="0 0 0" xyz="0 0 0.1"/>
      <material name="white"/>
    </visual>
    <collision>
      <geometry>
        <box size="0.1 0.1 0.2"/>
      </geometry>
      <origin rpy="0 0 0" xyz="0 0 0.1"/>
    </collision>
    <inertial>
      <mass value="10"/>
      <inertia ixx="1.0" ixy="0.0" ixz="0.0" iyy="1.0" iyz="0.0" izz="1.0"/>
    </inertial>
  </link>
  <joint name="revolute_55" type="revolute">
    <parent link="branch_54"/>
    <child link="branch_55"/>
    <origin rpy="-0.696467 -0.961082 -0.661968" xyz="0 0 0.2"/>
    <axis xyz="0 0 1"/>
    <limit effort="1000.0" lower="-0.548" upper="0.548" velocity="0.5"/>
  </joint>
  <link name="branch_56">
    <visual>
      <geometry>
        <box size="0.1 0.1 0.2"/>
      </geometry>
      <origin rpy="0 0 0" xyz="0 0 0.1"/>
      <material name="white"/>
    </visual>
    <collision>
      <geometry>
        <box size="0.1 0.1 0.2"/>
      </geometry>
      <origin rpy="0 0 0" xyz="0 0 0.1"/>
    </collision>
    <inertial>
      <mass value="10"/>
      <inertia ixx="1.0" ixy="0.0" ixz="0.0" iyy="1.0" iyz="0.0" izz="1.0"/>
    </inertial>
  </link>
  <joint name="revolute_56" type="revolute">
    <parent link="branch_55"/>
    <child link="branch_56"/>
    <origin rpy="0.777603 -0.473902 -0.633532" xyz="0 0 0.2"/>
    <axis xyz="1 0 0"/>
    <limit effort="1000.0" lower="-0.548" upper="0.548" velocity="0.5"/>
  </joint>
  <link name="branch_57">
    <visual>
      <geometry>
        <box size="0.1 0.1 0.2"/>
      </geometry>
      <origin rpy="0 0 0" xyz="0 0 0.1"/>
      <material name="white"/>
    </visual>
    <collision>
      <geometry>
        <box size="0.1 0.1 0.2"/>
      </geometry>
      <origin rpy="0 0 0" xyz="0 0 0.1"/>
    </collision>
    <inertial>
      <mass value="10"/>
      <inertia ixx="1.0" ixy="0.0" ixz="0.0" iyy="1.0" iyz="0.0" izz="1.0"/>
    </inertial>
  </link>
  <joint name="revolute_57" type="revolute">
    <parent link="branch_56"/>
    <child link="branch_57"/>
    <origin rpy="0.896079 -0.825601 0.191509" xyz="0 0 0.2"/>
    <axis xyz="0 1 0"/>
    <limit effort="1000.0" lower="-0.548" upper="0.548" velocity="0.5"/>
  </joint>
  <link name="branch_58">
    <visual>
      <geometry>
        <box size="0.1 0.1 0.2"/>
      </geometry>
      <origin rpy="0 0 0" xyz="0 0 0.1"/>
      <material name="white"/>
    </visual>
    <collision>
      <geometry>
        <box size="0.1 0.1 0.2"/>
      </geometry>
      <origin rpy="0 0 0" xyz="0 0 0.1"/>
    </collision>
    <inertial>
      <mass value="10"/>
      <inertia ixx="1.0" ixy="0.0" ixz="0.0" iyy="1.0" iyz="0.0" izz="1.0"/>
    </inertial>
  </link>
  <joint name="revolute_58" type="revolute">
    <parent link="branch_57"/>
    <child link="branch_58"/>
    <origin rpy="-0.097365 -0.055375 -0.200458" xyz="0 0 0.2"/>
    <axis xyz="0 0 1"/>
    <limit effort="1000.0" lower="-0.548" upper="0.548" velocity="0.5"/>
  </joint>
  <link name="branch_59">
    <visual>
      <geometry>
        <box size="0.1 0.1 0.2"/>
      </geometry>
      <origin rpy="0 0 0" xyz="0 0 0.1"/>
      <material name="white"/>
    </visual>
    <collision>
      <geometry>
        <box size="0.1 0.1 0.2"/>
      </geometry>
      <origin rpy="0 0 0" xyz="0 0 0.1"/>
    </collision>
    <inertial>
      <mass value="10"/>
      <inertia ixx="1.0" ixy="0.0" ixz="0.0" iyy="1.0" iyz="0.0" izz="1.0"/>
    </inertial>
  </link>
  <joint name="revolute_59" type="revolute">
    <parent link="branch_58"/>
    <child link="branch_59"/>
    <origin rpy="-0.237286 -0.724001 -0.938169" xyz="0 0 0.2"/>
    <axis xyz="1 0 0"/>
    <limit effort="1000.0" lower="-0.548" upper="0.548" velocity="0.5"/>
  </joint>
  <link name="branch_60">
    <visual>
      <geometry>
        <box size="0.1 0.1 0.2"/>
      </geometry>
      <origin rpy="0 0 0" xyz="0 0 0.1"/>
      <material name="white"/>
    </visual>
    <collision>
      <geometry>
        <box size="0.1 0.1 0.2"/>
      </geometry>
      <origin rpy="0 0 0" xyz="0 0 0.1"/>
    </collision>
    <inertial>
      <mass value="10"/>
      <inertia ixx="1.0" ixy="0.0" ixz="0.0" iyy="1.0" iyz="0.0" izz="1.0"/>
    </inertial>
  </link>
  <joint name="revolute_60" type="revolute">
    <parent link="branch_59"/>
    <child link="branch_60"/>
    <origin rpy="-0.856611 0.094194 0.319830" xyz="0 0 0.2"/>
    <axis xyz="0 1 0"/>
    <limit effort="1000.0" lower="-0.548" upper="0.548" velocity="0.5"/>
  </joint>
  <link name="branch_61">
    <visual>
      <geometry>
        <box size="0.1 0.1 0.2"/>
      </geometry>
      <origin rpy="0 0 0" xyz="0 0 0.1"/>
      <material name="white"/>
    </visual>
    <collision>
      <geometry>
        <box size="0.1 0.1 0.2"/>
      </geometry>
      <origin rpy="0 0 0" xyz="0 0 0.1"/>
    </collision>
    <inertial>
      <mass value="10"/>
      <inertia ixx="1.0" ixy="0.0" ixz="0.0" iyy="1.0" iyz="0.0" izz="1.0"/>
    </inertial>
  </link>
  <joint name="revolute_61" type="revolute">
    <parent link="branch_60"/>
    <child link="branch_61"/>
    <origin rpy="0.422674 0.786583 -0.640158" xyz="0 0 0.2"/>
    <axis xyz="0 0 1"/>
    <limit effort="1000.0" lower="-0.548" upper="0.548" velocity="0.5"/>
  </joint>
  <link name="branch_62">
    <visual>
      <geometry>
        <box size="0.1 0.1 0.2"/>
      </geometry>
      <origin rpy="0 0 0" xyz="0 0 0.1"/>
      <material name="white"/>
    </visual>
    <collision>
      <geometry>
        <box size="0.1 0.1 0.2"/>
      </geometry>
      <origin rpy="0 0 0" xyz="0 0 0.1"/>
    </collision>
    <inertial>
      <mass value="10"/>
      <inertia ixx="1.0" ixy="0.0" ixz="0.0" iyy="1.0" iyz="0.0" izz="1.0"/>
    </inertial>
  </link>
  <joint name="revolute_62" type="revolute">
    <parent link="branch_61"/>
    <child link="branch_62"/>
    <origin rpy="0.393514 0.821017 0.656454" xyz="0 0 0.2"/>
    <axis xyz="1 0 0"/>
    <limit effort="1000.0" lower="-0.548" upper="0.548" velocity="0.5"/>
  </joint>
  <link name="branch_63">
    <visual>
      <geometry>
        <box size="0.1 0.1 0.2"/>
      </geometry>
      <origin rpy="0 0 0" xyz="0 0 0.1"/>
      <material name="white"/>
    </visual>
    <collision>
      <geometry>
        <box size="0.1 0.1 0.2"/>
      </geometry>
      <origin rpy="0 0 0" xyz="0 0 0.1"/>
    </collision>
    <inertial>
      <mass value="10"/>
      <inertia ixx="1.0" ixy="0.0" ixz="0.0" iyy="1.0" iyz="0.0" izz="1.0"/>
    </inertial>
  </link>
  <joint name="revolute_63" type="revolute">
    <parent link="branch_62"/>
    <child link="branch_63"/>
    <origin rpy="0.848707 0.289730 0.716381" xyz="0 0 0.2"/>
    <axis xyz="0 1 0"/>
    <limit effort="1000.0" lower="-0.548" upper="0.548" velocity="0.5"/>
  </joint>
  <link name="branch_64">
    <visual>
      <geometry>
        <box size="0.1 0.1 0.2"/>
      </geometry>
      <origin rpy="0 0 0" xyz="0 0 0.1"/>
      <material name="white"/>
    </visual>
    <collision>
      <geometry>
        <box size="0.1 0.1 0.2"/>
      </geometry>
      <origin rpy="0 0 0" xyz="0 0 0.1"/>
    </collision>
    <inertial>
      <mass value="10"/>
      <inertia ixx="1.0" ixy="0.0" ixz="0.0" iyy="1.0" iyz="0.0" izz="1.0"/>
    </inertial>
  </link>
  <joint name="revolute_64" type="revolute">
    <parent link="branch_63"/>
    <child link="branch_64"/>
    <origin rpy="-0.707387 0.218358 0.416625" xyz="0 0 0.2"/>
    <axis xyz="0 0 1"/>
    <limit effort="1000.0" lower="-0.548" upper="0.548" velocity="0.5"/>
  </joint>
  <link name="branch_65">
    <visual>
      <geometry>
        <box size="0.1 0.1 0.2"/>
      </geometry>
      <origin rpy="0 0 0" xyz="0 0 0.1"/>
      <material name="white"/>
    </visual>
    <collision>
      <geometry>
        <box size="0.1 0.1 0.2"/>
      </geometry>
      <origin rpy="0 0 0" xyz="0 0 0.1"/>
    </collision>
    <inertial>
      <mass value="10"/>
      <inertia ixx="1.0" ixy="0.0" ixz="0.0" iyy="1.0" iyz="0.0" izz="1.0"/>
    </inertial>
  </link>
  <joint name="revolute_65" type="revolute">
    <parent link="branch_64"/>
    <child link="branch_65"/>
    <origin rpy="-0.668469 0.556390 -0.863890" xyz="0 0 0.2"/>
    <axis xyz="1 0 0"/>
    <limit effort="1000.0" lower="-0.548" upper="0.548" velocity="0.5"/>
  </joint>
  <link name="branch_66">
    <visual>
      <geometry>
        <box size="0.1 0.1 0.2"/>
      </geometry>
      <origin rpy="0 0 0" xyz="0 0 0.1"/>
      <material name="white"/>
    </visual>
    <collision>
      <geometry>
        <box size="0.1 0.1 0.2"/>
      </geometry>
      <origin rpy="0 0 0" xyz="0 0 0.1"/>
    </collision>
    <inertial>
      <mass value="10"/>
      <inertia ixx="1.0" ixy="0.0" ixz="0.0" iyy="1.0" iyz="0.0" izz="1.0"/>
    </inertial>
  </link>
  <joint name="revolute_66" type="revolute">
    <parent link="branch_65"/>
    <child link="branch_66"/>
    <origin rpy="-0.142371 0.922858 -0.560357" xyz="0 0 0.2"/>
    <axis xyz="0 1 0"/>
    <limit effort="1000.0" lower="-0.548" upper="0.548" velocity="0.5"/>
  </joint>
  <link name="branch_67">
    <visual>
      <geometry>
        <box size="0.1 0.1 0.2"/>
      </geometry>
      <origin rpy="0 0 0" xyz="0 0 0.1"/>
      <material name="white"/>
    </visual>
    <collision>
      <geometry>
        <box size="0.1 0.1 0.2"/>
      </geometry>
      <origin rpy="0 0 0" xyz="0 0 0.1"/>
    </collision>
    <inertial>
      <mass value="10"/>
      <inertia ixx="1.0" ixy="0.0" ixz="0.0" iyy="1.0" iyz="0.0" izz="1.0"/>
    </inertial>
  </link>
  <joint name="revolute_67" type="revolute">
    <parent link="branch_66"/>
    <child link="branch_67"/>
    <origin rpy="0.032029 0.114367 -0.782754" xyz="0 0 0.2"/>
    <axis xyz="0 0 1"/>
    <limit effort="1000.0" lower="-0.548" upper="0.548" velocity="0.5"/>
  </joint>
  <link name="branch_68">
    <visual>
      <geometry>
        <box size="0.1 0.1 0.2"/>
      </geometry>
      <origin rpy="0 0 0" xyz="0 0 0.1"/>
      <material name="white"/>
    </visual>
    <collision>
      <geometry>
        <box size="0.1 0.1 0.2"/>
      </geometry>
      <origin rpy="0 0 0" xyz="0 0 0.1"/>
    </collision>
    <inertial>
      <mass value="10"/>
      <inertia ixx="1.0" ixy="0.0" ixz="0.0" iyy="1.0" iyz="0.0" izz="1.0"/>
    </inertial>
  </link>
  <joint name="revolute_68" type="revolute">
    <parent link="branch_67"/>
    <child link="branch_68"/>
    <origin rpy="0.976653 0.913909 -0.886675" xyz="0 0 0.2"/>
    <axis xyz="1 0 0"/>
    <limit effort="1000.0" lower="-0.548" upper="0.548" velocity="0.5"/>
  </joint>
  <link name="branch_69">
    <visual>
      <geometry>
        <box size="0.1 0.1 0.2"/>
      </geometry>
      <origin rpy="0 0 0" xyz="0 0 0.1"/>
      <material name="white"/>
    </visual>
    <collision>
      <geometry>
        <box size="0.1 0.1 0.2"/>
      </geometry>
      <origin rpy="0 0 0" xyz="0 0 0.1"/>
    </collision>
    <inertial>
      <mass value="10"/>
      <inertia ixx="1.0" ixy="0.0" ixz="0.0" iyy="1.0" iyz="0.0" izz="1.0"/>
    </inertial>
  </link>
  <joint name="revolute_69" type="revolute">
    <parent link="branch_68"/>
    <child link="branch_69"/>
    <origin rpy="-0.747347 0.975740 0.015960" xyz="0 0 0.2"/>
    <axis xyz="0 1 0"/>
    <limit effort="1000.0" lower="-0.548" upper="0.548" velocity="0.5"/>
  </joint>
  <link name="branch_70">
    <visual>
      <geometry>
        <box size="0.1 0.1 0.2"/>
      </geometry>
      <origin rpy="0 0 0" xyz="0 0 0.1"/>
      <material name="white"/>
    </visual>
    <collision>
      <geometry>
        <box size="0.1 0.1 0.2"/>
      </geometry>
      <origin rpy="0 0 0" xyz="0 0 0.1"/>
    </collision>
    <inertial>
      <mass value="10"/>
      <inertia ixx="1.0" ixy="0.0" ixz="0.0" iyy="1.0" iyz="0.0" izz="1.0"/>
    </inertial>
  </link>
  <joint name="revolute_70" type="revolute">
    <parent link="branch_69"/>
    <child link="branch_70"/>
    <origin rpy="0.346847 0.295570 0.778674" xyz="0 0 0.2"/>
    <axis xyz="0 0 1"/>
    <limit effort="1000.0" lower="-0.548" upper="0.548" velocity="0.5"/>
  </joint>
  <link name="branch_71">
    <visual>
      <geometry>
        <box size="0.1 0.1 0.2"/>
      </geometry>
      <origin rpy="0 0 0" xyz="0 0 0.1"/>
      <material name="white"/>
    </visual>
    <collision>
      <geometry>
        <box size="0.1 0.1 0.2"/>
      </geometry>
      <origin rpy="0 0 0" xyz="0 0 0.1"/>
    </collision>
    <inertial>
      <mass value="10"/>
      <inertia ixx="1.0" ixy="0.0" ixz="0.0" iyy="1.0" iyz="0.0" izz="1.0"/>
    </inertial>
  </link>
  <joint name="revolute_71" type="revolute">
    <parent link="branch_70"/>
    <child link="branch_71"/>
    <origin rpy="0.133430 0.655413 0.922063" xyz="0 0 0.2"/>
    <axis xyz="1 0 0"/>
    <limit effort="1000.0" lower="-0.548" upper="0.548" velocity="0.5"/>
  </joint>
  <link name="branch_72">
    <visual>
      <geometry>
        <box size="0.1 0.1 0.2"/>
      </geometry>
      <origin rpy="0 0 0" xyz="0 0 0.1"/>
      <material name="white"/>
    </visual>
    <collision>
      <geometry>
        <box size="0.1 0.1 0.2"/>
      </geometry>
      <origin rpy="0 0 0" xyz="0 0 0.1"/>
    </collision>
    <inertial>
      <mass value="10"/>
      <inertia ixx="1.0" ixy="0.0" ixz="0.0" iyy="1.0" iyz="0.0" izz="1.0"/>
    </inertial>
  </link>
  <joint name="revolute_72" type="revolute">
    <parent link="branch_71"/>
    <child link="branch_72"/>
    <origin rpy="-0.045553 0.311866 0.344737" xyz="0 0 0.2"/>
    <axis xyz="0 1 0"/>
    <limit effort="1000.0" lower="-0.548" upper="0.548" velocity="0.5"/>
  </joint>
  <link name="branch_73">
    <visual>
      <geometry>
        <box size="0.1 0.1 0.2"/>
      </geometry>
      <origin rpy="0 0 0" xyz="0 0 0.1"/>
      <material name="white"/>
    </visual>
    <collision>
      <geometry>
        <box size="0.1 0.1 0.2"/>
      </geometry>
      <origin rpy="0 0 0" xyz="0 0 0.1"/>
    </collision>
    <inertial>
      <mass value="10"/>
      <inertia ixx="1.0" ixy="0.0" ixz="0.0" iyy="1.0" iyz="0.0" izz="1.0"/>
    </inertial>
  </link>
  <joint name="revolute_73" type="revolute">
    <parent link="branch_72"/>
    <child link="branch_73"/>
    <origin rpy="-0.755822 0.028247 -0.261749" xyz="0 0 0.2"/>
    <axis xyz="0 0 1"/>
    <limit effort="1000.0" lower="-0.548" upper="0.548" velocity="0.5"/>
  </joint>
  <link name="branch_74">
    <visual>
      <geometry>
        <box size="0.1 0.1 0.2"/>
      </geometry>
      <origin rpy="0 0 0" xyz="0 0 0.1"/>
      <material name="white"/>
    </visual>
    <collision>
      <geometry>
        <box size="0.1 0.1 0.2"/>
      </geometry>
      <origin rpy="0 0 0" xyz="0 0 0.1"/>
    </collision>
    <inertial>
      <mass value="10"/>
      <inertia ixx="1.0" ixy="0.0" ixz="0.0" iyy="1.0" iyz="0.0" izz="1.0"/>
    </inertial>
  </link>
  <joint name="revolute_74" type="revolute">
    <parent link="branch_73"/>
    <child link="branch_74"/>
    <origin rpy="0.462535 -0.555128 -0.413043" xyz="0 0 0.2"/>
    <axis xyz="1 0 0"/>
    <limit effort="1000.0" lower="-0.548" upper="0.548" velocity="0.5"/>
  </joint>
  <link name="branch_75">
    <visual>
      <geometry>
        <box size="0.1 0.1 0.2"/>
      </geometry>
      <origin rpy="0 0 0" xyz="0 0 0.1"/>
      <material name="white"/>
    </visual>
    <collision>
      <geometry>
        <box size="0.1 0.1 0.2"/>
      </geometry>
      <origin rpy="0 0 0" xyz="0 0 0.1"/>
    </collision>
    <inertial>
      <mass value="10"/>
      <inertia ixx="1.0" ixy="0.0" ixz="0.0" iyy="1.0" iyz="0.0" izz="1.0"/>
    </inertial>
  </link>
  <joint name="revolute_75" type="revolute">
    <parent link="branch_74"/>
    <child link="branch_75"/>
    <origin rpy="0.018925 -0.419018 -0.120430" xyz="0 0 0.2"/>
    <axis xyz="0 1 0"/>
    <limit effort="1000.0" lower="-0.548" upper="0.548" velocity="0.5"/>
  </joint>
  <link name="branch_76">
    <visual>
      <geometry>
        <box size="0.1 0.1 0.2"/>
      </geometry>
      <origin rpy="0 0 0" xyz="0 0 0.1"/>
      <material name="white"/>
    </visual>
    <collision>
      <geometry>
        <box size="0.1 0.1 0.2"/>
      </geometry>
      <origin rpy="0 0 0" xyz="0 0 0.1"/>
    </collision>
    <inertial>
      <mass value="10"/>
      <inertia ixx="1.0" ixy="0.0" ixz="0.0" iyy="1.0" iyz="0.0" izz="1.0"/>
    </inertial>
  </link>
  <joint name="revolute_76" type="revolute">
    <parent link="branch_75"/>
    <child link="branch_76"/>
    <origin rpy="-0.058217 0.020625 0.211101" xyz="0 0 0.2"/>
    <axis xyz="0 0 1"/>
    <limit effort="1000.0" lower="-0.548" upper="0.548" velocity="0.5"/>
  </joint>
  <link name="branch_77">
    <visual>
      <geometry>
        <box size="0.1 0.1 0.2"/>
      </geometry>
      <origin rpy="0 0 0" xyz="0 0 0.1"/>
      <material name="white"/>
    </visual>
    <collision>
      <geometry>
        <box size="0.1 0.1 0.2"/>
      </geometry>
      <origin rpy="0 0 0" xyz="0 0 0.1"/>
    </collision>
    <inertial>
      <mass value="10"/>
      <inertia ixx="1.0" ixy="0.0" ixz="0.0" iyy="1.0" iyz="0.0" izz="1.0"/>
    </inertial>
  </link>
  <joint name="revolute_77" type="revolute">
    <parent link="branch_76"/>
    <child link="branch_77"/>
    <origin rpy="-0.943850 0.237871 -0.931270" xyz="0 0 0.2"/>
    <axis xyz="1 0 0"/>
    <limit effort="1000.0" lower="-0.548" upper="0.548" velocity="0.5"/>
  </joint>
  <link name="branch_78">
    <visual>
      <geometry>
        <box size="0.1 0.1 0.2"/>
      </geometry>
      <origin rpy="0 0 0" xyz="0 0 0.1"/>
      <material name="white"/>
    </visual>
    <collision>
      <geometry>
        <box size="0.1 0.1 0.2"/>
      </geometry>
      <origin rpy="0 0 0" xyz="0 0 0.1"/>
    </collision>
    <inertial>
      <mass value="10"/>
      <inertia ixx="1.0" ixy="0.0" ixz="0.0" iyy="1.0" iyz="0.0" izz="1.0"/>
    </inertial>
  </link>
  <joint name="revolute_78" type="revolute">
    <parent link="branch_77"/>
    <child link="branch_78"/>
    <origin rpy="0.970059 0.351196 0.100759" xyz="0 0 0.2"/>
    <axis xyz="0 1 0"/>
    <limit effort="1000.0" lower="-0.548" upper="0.548" velocity="0.5"/>
  </joint>
  <link name="branch_79">
    <visual>
      <geometry>
        <box size="0.1 0.1 0.2"/>
      </geometry>
      <origin rpy="0 0 0" xyz="0 0 0.1"/>
      <material name="white"/>
    </visual>
    <collision>
      <geometry>
        <box size="0.1 0.1 0.2"/>
      </geometry>
      <origin rpy="0 0 0" xyz="0 0 0.1"/>
    </collision>
    <inertial>
      <mass value="10"/>
      <inertia ixx="1.0" ixy="0.0" ixz="0.0" iyy="1.0" iyz="0.0" izz="1.0"/>
    </inertial>
  </link>
  <joint name="revolute_79" type="revolute">
    <parent link="branch_78"/>
    <child link="branch_79"/>
    <origin rpy="0.945799 -0.632844 0.077412" xyz="0 0 0.2"/>
    <axis xyz="0 0 1"/>
    <limit effort="1000.0" lower="-0.548" upper="0.548" velocity="0.5"/>
  </joint>
  <link name="branch_80">
    <visual>
      <geometry>
        <box size="0.1 0.1 0.2"/>
      </geometry>
      <origin rpy="0 0 0" xyz="0 0 0.1"/>
      <material name="white"/>
    </visual>
    <collision>
      <geometry>
        <box size="0.1 0.1 0.2"/>
      </geometry>
      <origin rpy="0 0 0" xyz="0 0 0.1"/>
    </collision>
    <inertial>
      <mass value="10"/>
      <inertia ixx="1.0" ixy="0.0" ixz="0.0" iyy="1.0" iyz="0.0" izz="1.0"/>
    </inertial>
  </link>
  <joint name="revolute_80" type="revolute">
    <parent link="branch_79"/>
    <child link="branch_80"/>
    <origin rpy="0.241369 -0.854169 0.330065" xyz="0 0 0.2"/>
    <axis xyz="1 0 0"/>
    <limit effort="1000.0" lower="-0.548" upper="0.548" velocity="0.5"/>
  </joint>
  <link name="branch_81">
    <visual>
      <geometry>
        <box size="0.1 0.1 0.2"/>
      </geometry>
      <origin rpy="0 0 0" xyz="0 0 0.1"/>
      <material name="white"/>
    </visual>
    <collision>
      <geometry>
        <box size="0.1 0.1 0.2"/>
      </geometry>
      <origin rpy="0 0 0" xyz="0 0 0.1"/>
    </collision>
    <inertial>
      <mass value="10"/>
      <inertia ixx="1.0" ixy="0.0" ixz="0.0" iyy="1.0" iyz="0.0" izz="1.0"/>
    </inertial>
  </link>
  <joint name="revolute_81" type="revolute">
    <parent link="branch_80"/>
    <child link="branch_81"/>
    <origin rpy="-0.103218 -0.932106 -0.323088" xyz="0 0 0.2"/>
    <axis xyz="0 1 0"/>
    <limit effort="1000.0" lower="-0.548" upper="0.548" velocity="0.5"/>
  </joint>
  <link name="branch_82">
    <visual>
      <geometry>
        <box size="0.1 0.1 0.2"/>
      </geometry>
      <origin rpy="0 0 0" xyz="0 0 0.1"/>
      <material name="white"/>
    </visual>
    <collision>
      <geometry>
        <box size="0.1 0.1 0.2"/>
      </geometry>
      <origin rpy="0 0 0" xyz="0 0 0.1"/>
    </collision>
    <inertial>
      <mass value="10"/>
      <inertia ixx="1.0" ixy="0.0" ixz="0.0" iyy="1.0" iyz="0.0" izz="1.0"/>
    </inertial>
  </link>
  <joint name="revolute_82" type="revolute">
    <parent link="branch_81"/>
    <child link="branch_82"/>
    <origin rpy="-0.791351 0.412631 0.810342" xyz="0 0 0.2"/>
    <axis xyz="0 0 1"/>
    <limit effort="1000.0" lower="-0.548" upper="0.548" velocity="0.5"/>
  </joint>
  <link name="branch_83">
    <visual>
      <geometry>
        <box size="0.1 0.1 0.2"/>
      </geometry>
      <origin rpy="0 0 0" xyz="0 0 0.1"/>
      <material name="white"/>
    </visual>
    <collision>
      <geometry>
        <box size="0.1 0.1 0.2"/>
      </geometry>
      <origin rpy="0 0 0" xyz="0 0 0.1"/>
    </collision>
    <inertial>
      <mass value="10"/>
      <inertia ixx="1.0" ixy="0.0" ixz="0.0" iyy="1.0" iyz="0.0" izz="1.0"/>
    </inertial>
  </link>
  <joint name="revolute_83" type="revolute">
    <parent link="branch_82"/>
    <child link="branch_83"/>
    <origin rpy="0.236896 -0.849119 -0.235211" xyz="0 0 0.2"/>
    <axis xyz="1 0 0"/>
    <limit effort="1000.0" lower="-0.548" upper="0.548" velocity="0.5"/>
  </joint>
  <link name="branch_84">
    <visual>
      <geometry>
        <box size="0.1 0.1 0.2"/>
      </geometry>
      <origin rpy="0 0 0" xyz="0 0 0.1"/>
      <material name="white"/>
    </visual>
    <collision>
      <geometry>
        <box size="0.1 0.1 0.2"/>
      </geometry>
      <origin rpy="0 0 0" xyz="0 0 0.1"/>
    </collision>
    <inertial>
      <mass value="10"/>
      <inertia ixx="1.0" ixy="0.0" ixz="0.0" iyy="1.0" iyz="0.0" izz="1.0"/>
    </inertial>
  </link>
  <joint name="revolute_84" type="revolute">
    <parent link="branch_83"/>
    <child link="branch_84"/>
    <origin rpy="0.681768 -0.262161 0.008967" xyz="0 0 0.2"/>
    <axis xyz="0 1 0"/>
    <limit effort="1000.0" lower="-0.548" upper="0.548" velocity="0.5"/>
  </joint>
  <link name="branch_85">
    <visual>
      <geometry>
        <box size="0.1 0.1 0.2"/>
      </geometry>
      <origin rpy="0 0 0" xyz="0 0 0.1"/>
      <material name="white"/>
    </visual>
    <collision>
      <geometry>
        <box size="0.1 0.1 0.2"/>
      </geometry>
      <origin rpy="0 0 0" xyz="0 0 0.1"/>
    </collision>
    <inertial>
      <mass value="10"/>
      <inertia ixx="1.0" ixy="0.0" ixz="0.0" iyy="1.0" iyz="0.0" izz="1.0"/>
    </inertial>
  </link>
  <joint name="revolute_85" type="revolute">
    <parent link="branch_84"/>
    <child link="branch_85"/>
    <origin rpy="-0.737250 0.617409 -0.528498" xyz="0 0 0.2"/>
    <axis xyz="0 0 1"/>
    <limit effort="1000.0" lower="-0.548" upper="0.548" velocity="0.5"/>
  </joint>
  <link name="branch_86">
    <visual>
      <geometry>
        <box size="0.1 0.1 0.2"/>
      </geometry>
      <origin rpy="0 0 0" xyz="0 0 0.1"/>
      <material name="white"/>
    </visual>
    <collision>
      <geometry>
        <box size="0.1 0.1 0.2"/>
      </geometry>
      <origin rpy="0 0 0" xyz="0 0 0.1"/>
    </collision>
    <inertial>
      <mass value="10"/>
      <inertia ixx="1.0" ixy="0.0" ixz="0.0" iyy="1.0" iyz="0.0" izz="1.0"/>
    </inertial>
  </link>
  <joint name="revolute_86" type="revolute">
    <parent link="branch_85"/>
    <child link="branch_86"/>
    <origin rpy="0.283375 -0.171490 0.490427" xyz="0 0 0.2"/>
    <axis xyz="1 0 0"/>
    <limit effort="1000.0" lower="-0.548" upper="0.548" velocity="0.5"/>
  </joint>
  <link name="branch_87">
    <visual>
      <geometry>
        <box size="0.1 0.1 0.2"/>
      </geometry>
      <origin rpy="0 0 0" xyz="0 0 0.1"/>
      <material name="white"/>
    </visual>
    <collision>
      <geometry>
        <box size="0.1 0.1 0.2"/>
      </geometry>
      <origin rpy="0 0 0" xyz="0 0 0.1"/>
    </collision>
    <inertial>
      <mass value="10"/>
      <inertia ixx="1.0" ixy="0.0" ixz="0.0" iyy="1.0" iyz="0.0" izz="1.0"/>
    </inertial>
  </link>
  <joint name="revolute_87" type="revolute">
    <parent link="branch_86"/>
    <child link="branch_87"/>
    <origin rpy="-0.478753 -0.102759 -0.567790" xyz="0 0 0.2"/>
    <axis xyz="0 1 0"/>
    <limit effort="1000.0" lower="-0.548" upper="0.548" velocity="0.5"/>
  </joint>
  <link name="branch_88">
    <visual>
      <geometry>
        <box size="0.1 0.1 0.2"/>
      </geometry>
      <origin rpy="0 0 0" xyz="0 0 0.1"/>
      <material name="white"/>
    </visual>
    <collision>
      <geometry>
        <box size="0.1 0.1 0.2"/>
      </geometry>
      <origin rpy="0 0 0" xyz="0 0 0.1"/>
    </collision>
    <inertial>
      <mass value="10"/>
      <inertia ixx="1.0" ixy="0.0" ixz="0.0" iyy="1.0" iyz="0.0" izz="1.0"/>
    </inertial>
  </link>
  <joint name="revolute_88" type="revolute">
    <parent link="branch_87"/>
    <child link="branch_88"/>
    <origin rpy="0.872443 0.998000 -0.511640" xyz="0 0 0.2"/>
    <axis xyz="0 0 1"/>
    <limit effort="1000.0" lower="-0.548" upper="0.548" velocity="0.5"/>
  </joint>
  <link name="branch_89">
    <visual>
      <geometry>
        <box size="0.1 0.1 0.2"/>
      </geometry>
      <origin rpy="0 0 0" xyz="0 0 0.1"/>
      <material name="white"/>
    </visual>
    <collision>
      <geometry>
        <box size="0.1 0.1 0.2"/>
      </geometry>
      <origin rpy="0 0 0" xyz="0 0 0.1"/>
    </collision>
    <inertial>
      <mass value="10"/>
      <inertia ixx="1.0" ixy="0.0" ixz="0.0" iyy="1.0" iyz="0.0" izz="1.0"/>
    </inertial>
  </link>
  <joint name="revolute_89" type="revolute">
    <parent link="branch_88"/>
    <child link="branch_89"/>
    <origin rpy="-0.760401 0.075412 -0.541581" xyz="0 0 0.2"/>
    <axis xyz="1 0 0"/>
    <limit effort="1000.0" lower="-0.548" upper="0.548" velocity="0.5"/>
  </joint>
  <link name="branch_90">
    <visual>
      <geometry>
        <box size="0.1 0.1 0.2"/>
      </geometry>
      <origin rpy="0 0 0" xyz="0 0 0.1"/>
      <material name="white"/>
    </visual>
    <collision>
      <geometry>
        <box size="0.1 0.1 0.2"/>
      </geometry>
      <origin rpy="0 0 0" xyz="0 0 0.1"/>
    </collision>
    <inertial>
      <mass value="10"/>
      <inertia ixx="1.0" ixy="0.0" ixz="0.0" iyy="1.0" iyz="0.0" izz="1.0"/>
    </inertial>
  </link>
  <joint name="revolute_90" type="revolute">
    <parent link="branch_89"/>
    <child link="branch_90"/>
    <origin rpy="-0.614570 -0.594523 -0.595782" xyz="0 0 0.2"/>
    <axis xyz="0 1 0"/>
    <limit effort="1000.0" lower="-0.548" upper="0.548" velocity="0.5"/>
  </joint>
  <link name="branch_91">
    <visual>
      <geometry>
        <box size="0.1 0.1 0.2"/>
      </geometry>
      <origin rpy="0 0 0" xyz="0 0 0.1"/>
      <material name="white"/>
    </visual>
    <collision>
      <geometry>
        <box size="0.1 0.1 0.2"/>
      </geometry>
      <origin rpy="0 0 0" xyz="0 0 0.1"/>
    </collision>
    <inertial>
      <mass value="10"/>
      <inertia ixx="1.0" ixy="0.0" ixz="0.0" iyy="1.0" iyz="0.0" izz="1.0"/>
    </inertial>
  </link>
  <joint name="revolute_91" type="revolute">
    <parent link="branch_90"/>
    <child link="branch_91"/>
    <origin rpy="-0.546676 0.082389 0.645587" xyz="0 0 0.2"/>
    <axis xyz="0 0 1"/>
    <limit effort="1000.0" lower="-0.548" upper="0.548" velocity="0.5"/>
  </joint>
  <link name="branch_92">
    <visual>
      <geometry>
        <box size="0.1 0.1 0.2"/>
      </geometry>
      <origin rpy="0 0 0" xyz="0 0 0.1"/>
      <material name="white"/>
    </visual>
    <collision>
      <geometry>
        <box size="0.1 0.1 0.2"/>
      </geometry>
      <origin rpy="0 0 0" xyz="0 0 0.1"/>
    </collision>
    <inertial>
      <mass value="10"/>
      <inertia ixx="1.0" ixy="0.0" ixz="0.0" iyy="1.0" iyz="0.0" izz="1.0"/>
    </inertial>
  </link>
  <joint name="revolute_92" type="revolute">
    <parent link="branch_91"/>
    <child link="branch_92"/>
    <origin rpy="0.865955 -0.107270 -0.457631" xyz="0 0 0.2"/>
    <axis xyz="1 0 0"/>
    <limit effort="1000.0" lower="-0.548" upper="0.548" velocity="0.5"/>
  </joint>
  <link name="branch_93">
    <visual>
      <geometry>
        <box size="0.1 0.1 0.2"/>
      </geometry>
      <origin rpy="0 0 0" xyz="0 0 0.1"/>
      <material name="white"/>
    </visual>
    <collision>
      <geometry>
        <box size="0.1 0.1 0.2"/>
      </geometry>
      <origin rpy="0 0 0" xyz="0 0 0.1"/>
    </collision>
    <inertial>
      <mass value="10"/>
      <inertia ixx="1.0" ixy="0.0" ixz="0.0" iyy="1.0" iyz="0.0" izz="1.0"/>
    </inertial>
  </link>
  <joint name="revolute_93" type="revolute">
    <parent link="branch_92"/>
    <child link="branch_93"/>
    <origin rpy="-0.983164 0.657519 -0.248982" xyz="0 0 0.2"/>
    <axis xyz="0 1 0"/>
    <limit effort="1000.0" lower="-0.548" upper="0.548" velocity="0.5"/>
  </joint>
  <link name="branch_94">
    <visual>
      <geometry>
        <box size="0.1 0.1 0.2"/>
      </geometry>
      <origin rpy="0 0 0" xyz="0 0 0.1"/>
      <material name="white"/>
    </visual>
    <collision>
      <geometry>
        <box size="0.1 0.1 0.2"/>
      </geometry>
      <origin rpy="0 0 0" xyz="0 0 0.1"/>
    </collision>
    <inertial>
      <mass value="10"/>
      <inertia ixx="1.0" ixy="0.0" ixz="0.0" iyy="1.0" iyz="0.0" izz="1.0"/>
    </inertial>
  </link>
  <joint name="revolute_94" type="revolute">
    <parent link="branch_93"/>
    <child link="branch_94"/>
    <origin rpy="-0.245326 -0.333514 0.987914" xyz="0 0 0.2"/>
    <axis xyz="0 0 1"/>
    <limit effort="1000.0" lower="-0.548" upper="0.548" velocity="0.5"/>
  </joint>
  <link name="branch_95">
    <visual>
      <geometry>
        <box size="0.1 0.1 0.2"/>
      </geometry>
      <origin rpy="0 0 0" xyz="0 0 0.1"/>
      <material name="white"/>
    </visual>
    <collision>
      <geometry>
        <box size="0.1 0.1 0.2"/>
      </geometry>
      <origin rpy="0 0 0" xyz="0 0 0.1"/>
    </collision>
    <inertial>
      <mass value="10"/>
      <inertia ixx="1.0" ixy="0.0" ixz="0.0" iyy="1.0" iyz="0.0" izz="1.0"/>
    </inertial>
  </link>
  <joint name="revolute_95" type="revolute">
    <parent link="branch_94"/>
    <child link="branch_95"/>
    <origin rpy="-0.627917 0.137988 0.669682" xyz="0 0 0.2"/>
    <axis xyz="1 0 0"/>
    <limit effort="1000.0" lower="-0.548" upper="0.548" velocity="0.5"/>
  </joint>
  <link name="branch_96">
    <visual>
      <geometry>
        <box size="0.1 0.1 0.2"/>
      </geometry>
      <origin rpy="0 0 0" xyz="0 0 0.1"/>
      <material name="white"/>
    </visual>
    <collision>
      <geometry>
        <box size="0.1 0.1 0.2"/>
      </geometry>
      <origin rpy="0 0 0" xyz="0 0 0.1"/>
    </collision>
    <inertial>
      <mass value="10"/>
      <inertia ixx="1.0" ixy="0.0" ixz="0.0" iyy="1.0" iyz="0.0" izz="1.0"/>
    </inertial>
  </link>
  <joint name="revolute_96" type="revolute">
    <parent link="branch_95"/>
    <child link="branch_96"/>
    <origin rpy="0.200593 -0.371585 0.932432" xyz="0 0 0.2"/>
    <axis xyz="0 1 0"/>
    <limit effort="1000.0" lower="-0.548" upper="0.548" velocity="0.5"/>
  </joint>
  <link name="branch_97">
    <visual>
      <geometry>
        <box size="0.1 0.1 0.2"/>
      </geometry>
      <origin rpy="0 0 0" xyz="0 0 0.1"/>
      <material name="white"/>
    </visual>
    <collision>
      <geometry>
        <box size="0.1 0.1 0.2"/>
      </geometry>
      <origin rpy="0 0 0" xyz="0 0 0.1"/>
    </collision>
    <inertial>
      <mass value="10"/>
      <inertia ixx="1.0" ixy="0.0" ixz="0.0" iyy="1.0" iyz="0.0" izz="1.0"/>
    </inertial>
  </link>
  <joint name="revolute_97" type="revolute">
    <parent link="branch_96"/>
    <child link="branch_97"/>
    <origin rpy="-0.902166 0.060625 0.215807" xyz="0 0 0.2"/>
    <axis xyz="0 0 1"/>
    <limit effort="1000.0" lower="-0.548" upper="0.548" velocity="0.5"/>
  </joint>
  <link name="branch_98">
    <visual>
      <geometry>
        <box size="0.1 0.1 0.2"/>
      </geometry>
      <origin rpy="0 0 0" xyz="0 0 0.1"/>
      <material name="white"/>
    </visual>
    <collision>
      <geometry>
        <box size="0.1 0.1 0.2"/>
      </geometry>
      <origin rpy="0 0 0" xyz="0 0 0.1"/>
    </collision>
    <inertial>
      <mass value="10"/>
      <inertia ixx="1.0" ixy="0.0" ixz="0.0" iyy="1.0" iyz="0.0" izz="1.0"/>
    </inertial>
  </link>
  <joint name="revolute_98" type="revolute">
    <parent link="branch_97"/>
    <child link="branch_98"/>
    <origin rpy="-0.904166 0.548985 0.737054" xyz="0 0 0.2"/>
    <axis xyz="1 0 0"/>
    <limit effort="1000.0" lower="-0.548" upper="0.548" velocity="0.5"/>
  </joint>
  <link name="branch_99">
    <visual>
      <geometry>
        <box size="0.1 0.1 0.2"/>
      </geometry>
      <origin rpy="0 0 0" xyz="0 0 0.1"/>
      <material name="white"/>
    </visual>
    <collision>
      <geometry>
        <box size="0.1 0.1 0.2"/>
      </geometry>
      <origin rpy="0 0 0" xyz="0 0 0.1"/>
    </collision>
    <inertial>
      <mass value="10"/>
      <inertia ixx="1.0" ixy="0.0" ixz="0.0" iyy="1.0" iyz="0.0" izz="1.0"/>
    </inertial>
  </link>
  <joint name="revolute_99" type="revolute">
    <parent link="branch_98"/>
    <child link="branch_99"/>
    <origin rpy="0.171246 -0.992597 0.609496" xyz="0 0 0.2"/>
    <axis xyz="0 1 0"/>
    <limit effort="1000.0" lower="-0.548" upper="0.548" velocity="0.5"/>
  </joint>
  <link name="branch_100">
    <visual>
      <geometry>
        <box size="0.1 0.1 0.2"/>
      </geometry>
      <origin rpy="0 0 0" xyz="0 0 0.1"/>
      <material name="white"/>
    </visual>
    <collision>
      <geometry>
        <box size="0.1 0.1 0.2"/>
      </geometry>
      <origin rpy="0 0 0" xyz="0 0 0.1"/>
    </collision>
    <inertial>
      <mass value="10"/>
      <inertia ixx="1.0" ixy="0.0" ixz="0.0" iyy="1.0" iyz="0.0" izz="1.0"/>
    </inertial>
  </link>
  <joint name="revolute_100" type="revolute">
    <parent link="branch_99"/>
    <child link="branch_100"/>
    <origin rpy="0.576723 -0.588379 0.849096" xyz="0 0 0.2"/>
    <axis xyz="0 0 1"/>
    <limit effort="1000.0" lower="-0.548" upper="0.548" velocity="0.5"/>
  </joint>
  <link name="head">
    <visual>
      <geometry>
        <sphere radius="0.1"/>
      </geometry>
      <material name="black"/>
    </visual>
    <collision>
      <geometry>
        <sphere radius="0.1"/>
      </geometry>
    </collision>
    <inertial>
      <mass value="2"/>
      <inertia ixx="1.0" ixy="0.0" ixz="0.0" iyy="1.0" iyz="0.0" izz="1.0"/>
    </inertial>
  </link>
  <joint name="head_swivel" type="continuous">
    <parent link="branch_100"/>
    <child link="head"/>
    <origin xyz="0 0 0.2"/>
    <axis xyz="0 0 1"/>
  </joint>
</robot>

